Workbook

Sheet LOC_COPY
A1: STT | B1: Số 2D | C1: Tổng | D1: Trùng Tổng Chọn (C2) | E1: Trùng G7 | F1: Nguồn G7 | G1: Trùng Chạm Chọn (G2) | H1: Điểm 2D Matrix | I1: Dàn Nguồn Top 20 | J1: Dàn Nổi Bật Top 10
A2: ĐIỀU KHIỂN: | B2: LỌC TỔNG (C2): | C2: 0123456789 | D2: (Nhập các Tổng, VD: 1267) | E2: LỌC CHẠM (G2): | F2: (Nhập các Chạm, VD: 2358) | G2: 0123456789 | H2: COPY DÀN NỔI BẬT: | I2: =TEXTJOIN(" ", TRUE, I3:I102) | J2: =TEXTJOIN(" ", TRUE, J3:J102)
A3: 1 | B3: 00 | C3: =MOD(VALUE(LEFT(B3,1))+VALUE(RIGHT(B3,1)), 10) | D3: =IF(ISNUMBER(SEARCH(TEXT(C3,"0"),$C$2)), "ĐÚNG TỔNG", "KHÔNG") | E3: =IF(ISNUMBER(SEARCH(TEXT(C3,"0"), Du_Lieu_2026!$F$2 & Du_Lieu_2026!$I$2 & Du_Lieu_2026!$L$2 & Du_Lieu_2026!$O$2)), "CÓ G7", "---") | F3: =IF(E3="CÓ G7", "CÓ NGUỒN", "---") | G3: =IF(OR(ISNUMBER(SEARCH(LEFT(B3,1),$G$2)), ISNUMBER(SEARCH(RIGHT(B3,1),$G$2))), "ĐÚNG CHẠM", "KHÔNG") | H3: =IF(D3="ĐÚNG TỔNG", 15, 0) + IF(G3="ĐÚNG CHẠM", 15, 0) + IF(E3="CÓ G7", 10, 0) + (100-ROW())/1000 | I3: =IF(RANK(H3,$H$3:$H$102)<=20, B3, "") | J3: =IF(AND(D3="ĐÚNG TỔNG", G3="ĐÚNG CHẠM", RANK(H3,$H$3:$H$102)<=10), B3, "")
A4: 2 | B4: 01 | C4: =MOD(VALUE(LEFT(B4,1))+VALUE(RIGHT(B4,1)), 10) | D4: =IF(ISNUMBER(SEARCH(TEXT(C4,"0"),$C$2)), "ĐÚNG TỔNG", "KHÔNG") | E4: =IF(ISNUMBER(SEARCH(TEXT(C4,"0"), Du_Lieu_2026!$F$2 & Du_Lieu_2026!$I$2 & Du_Lieu_2026!$L$2 & Du_Lieu_2026!$O$2)), "CÓ G7", "---") | F4: =IF(E4="CÓ G7", "CÓ NGUỒN", "---") | G4: =IF(OR(ISNUMBER(SEARCH(LEFT(B4,1),$G$2)), ISNUMBER(SEARCH(RIGHT(B4,1),$G$2))), "ĐÚNG CHẠM", "KHÔNG") | H4: =IF(D4="ĐÚNG TỔNG", 15, 0) + IF(G4="ĐÚNG CHẠM", 15, 0) + IF(E4="CÓ G7", 10, 0) + (100-ROW())/1000 | I4: =IF(RANK(H4,$H$3:$H$102)<=20, B4, "") | J4: =IF(AND(D4="ĐÚNG TỔNG", G4="ĐÚNG CHẠM", RANK(H4,$H$3:$H$102)<=10), B4, "")
A5: 3 | B5: 02 | C5: =MOD(VALUE(LEFT(B5,1))+VALUE(RIGHT(B5,1)), 10) | D5: =IF(ISNUMBER(SEARCH(TEXT(C5,"0"),$C$2)), "ĐÚNG TỔNG", "KHÔNG") | E5: =IF(ISNUMBER(SEARCH(TEXT(C5,"0"), Du_Lieu_2026!$F$2 & Du_Lieu_2026!$I$2 & Du_Lieu_2026!$L$2 & Du_Lieu_2026!$O$2)), "CÓ G7", "---") | F5: =IF(E5="CÓ G7", "CÓ NGUỒN", "---") | G5: =IF(OR(ISNUMBER(SEARCH(LEFT(B5,1),$G$2)), ISNUMBER(SEARCH(RIGHT(B5,1),$G$2))), "ĐÚNG CHẠM", "KHÔNG") | H5: =IF(D5="ĐÚNG TỔNG", 15, 0) + IF(G5="ĐÚNG CHẠM", 15, 0) + IF(E5="CÓ G7", 10, 0) + (100-ROW())/1000 | I5: =IF(RANK(H5,$H$3:$H$102)<=20, B5, "") | J5: =IF(AND(D5="ĐÚNG TỔNG", G5="ĐÚNG CHẠM", RANK(H5,$H$3:$H$102)<=10), B5, "")
A6: 4 | B6: 03 | C6: =MOD(VALUE(LEFT(B6,1))+VALUE(RIGHT(B6,1)), 10) | D6: =IF(ISNUMBER(SEARCH(TEXT(C6,"0"),$C$2)), "ĐÚNG TỔNG", "KHÔNG") | E6: =IF(ISNUMBER(SEARCH(TEXT(C6,"0"), Du_Lieu_2026!$F$2 & Du_Lieu_2026!$I$2 & Du_Lieu_2026!$L$2 & Du_Lieu_2026!$O$2)), "CÓ G7", "---") | F6: =IF(E6="CÓ G7", "CÓ NGUỒN", "---") | G6: =IF(OR(ISNUMBER(SEARCH(LEFT(B6,1),$G$2)), ISNUMBER(SEARCH(RIGHT(B6,1),$G$2))), "ĐÚNG CHẠM", "KHÔNG") | H6: =IF(D6="ĐÚNG TỔNG", 15, 0) + IF(G6="ĐÚNG CHẠM", 15, 0) + IF(E6="CÓ G7", 10, 0) + (100-ROW())/1000 | I6: =IF(RANK(H6,$H$3:$H$102)<=20, B6, "") | J6: =IF(AND(D6="ĐÚNG TỔNG", G6="ĐÚNG CHẠM", RANK(H6,$H$3:$H$102)<=10), B6, "")
A7: 5 | B7: 04 | C7: =MOD(VALUE(LEFT(B7,1))+VALUE(RIGHT(B7,1)), 10) | D7: =IF(ISNUMBER(SEARCH(TEXT(C7,"0"),$C$2)), "ĐÚNG TỔNG", "KHÔNG") | E7: =IF(ISNUMBER(SEARCH(TEXT(C7,"0"), Du_Lieu_2026!$F$2 & Du_Lieu_2026!$I$2 & Du_Lieu_2026!$L$2 & Du_Lieu_2026!$O$2)), "CÓ G7", "---") | F7: =IF(E7="CÓ G7", "CÓ NGUỒN", "---") | G7: =IF(OR(ISNUMBER(SEARCH(LEFT(B7,1),$G$2)), ISNUMBER(SEARCH(RIGHT(B7,1),$G$2))), "ĐÚNG CHẠM", "KHÔNG") | H7: =IF(D7="ĐÚNG TỔNG", 15, 0) + IF(G7="ĐÚNG CHẠM", 15, 0) + IF(E7="CÓ G7", 10, 0) + (100-ROW())/1000 | I7: =IF(RANK(H7,$H$3:$H$102)<=20, B7, "") | J7: =IF(AND(D7="ĐÚNG TỔNG", G7="ĐÚNG CHẠM", RANK(H7,$H$3:$H$102)<=10), B7, "")
A8: 6 | B8: 05 | C8: =MOD(VALUE(LEFT(B8,1))+VALUE(RIGHT(B8,1)), 10) | D8: =IF(ISNUMBER(SEARCH(TEXT(C8,"0"),$C$2)), "ĐÚNG TỔNG", "KHÔNG") | E8: =IF(ISNUMBER(SEARCH(TEXT(C8,"0"), Du_Lieu_2026!$F$2 & Du_Lieu_2026!$I$2 & Du_Lieu_2026!$L$2 & Du_Lieu_2026!$O$2)), "CÓ G7", "---") | F8: =IF(E8="CÓ G7", "CÓ NGUỒN", "---") | G8: =IF(OR(ISNUMBER(SEARCH(LEFT(B8,1),$G$2)), ISNUMBER(SEARCH(RIGHT(B8,1),$G$2))), "ĐÚNG CHẠM", "KHÔNG") | H8: =IF(D8="ĐÚNG TỔNG", 15, 0) + IF(G8="ĐÚNG CHẠM", 15, 0) + IF(E8="CÓ G7", 10, 0) + (100-ROW())/1000 | I8: =IF(RANK(H8,$H$3:$H$102)<=20, B8, "") | J8: =IF(AND(D8="ĐÚNG TỔNG", G8="ĐÚNG CHẠM", RANK(H8,$H$3:$H$102)<=10), B8, "")
A9: 7 | B9: 06 | C9: =MOD(VALUE(LEFT(B9,1))+VALUE(RIGHT(B9,1)), 10) | D9: =IF(ISNUMBER(SEARCH(TEXT(C9,"0"),$C$2)), "ĐÚNG TỔNG", "KHÔNG") | E9: =IF(ISNUMBER(SEARCH(TEXT(C9,"0"), Du_Lieu_2026!$F$2 & Du_Lieu_2026!$I$2 & Du_Lieu_2026!$L$2 & Du_Lieu_2026!$O$2)), "CÓ G7", "---") | F9: =IF(E9="CÓ G7", "CÓ NGUỒN", "---") | G9: =IF(OR(ISNUMBER(SEARCH(LEFT(B9,1),$G$2)), ISNUMBER(SEARCH(RIGHT(B9,1),$G$2))), "ĐÚNG CHẠM", "KHÔNG") | H9: =IF(D9="ĐÚNG TỔNG", 15, 0) + IF(G9="ĐÚNG CHẠM", 15, 0) + IF(E9="CÓ G7", 10, 0) + (100-ROW())/1000 | I9: =IF(RANK(H9,$H$3:$H$102)<=20, B9, "") | J9: =IF(AND(D9="ĐÚNG TỔNG", G9="ĐÚNG CHẠM", RANK(H9,$H$3:$H$102)<=10), B9, "")
A10: 8 | B10: 07 | C10: =MOD(VALUE(LEFT(B10,1))+VALUE(RIGHT(B10,1)), 10) | D10: =IF(ISNUMBER(SEARCH(TEXT(C10,"0"),$C$2)), "ĐÚNG TỔNG", "KHÔNG") | E10: =IF(ISNUMBER(SEARCH(TEXT(C10,"0"), Du_Lieu_2026!$F$2 & Du_Lieu_2026!$I$2 & Du_Lieu_2026!$L$2 & Du_Lieu_2026!$O$2)), "CÓ G7", "---") | F10: =IF(E10="CÓ G7", "CÓ NGUỒN", "---") | G10: =IF(OR(ISNUMBER(SEARCH(LEFT(B10,1),$G$2)), ISNUMBER(SEARCH(RIGHT(B10,1),$G$2))), "ĐÚNG CHẠM", "KHÔNG") | H10: =IF(D10="ĐÚNG TỔNG", 15, 0) + IF(G10="ĐÚNG CHẠM", 15, 0) + IF(E10="CÓ G7", 10, 0) + (100-ROW())/1000 | I10: =IF(RANK(H10,$H$3:$H$102)<=20, B10, "") | J10: =IF(AND(D10="ĐÚNG TỔNG", G10="ĐÚNG CHẠM", RANK(H10,$H$3:$H$102)<=10), B10, "")
A11: 9 | B11: 08 | C11: =MOD(VALUE(LEFT(B11,1))+VALUE(RIGHT(B11,1)), 10) | D11: =IF(ISNUMBER(SEARCH(TEXT(C11,"0"),$C$2)), "ĐÚNG TỔNG", "KHÔNG") | E11: =IF(ISNUMBER(SEARCH(TEXT(C11,"0"), Du_Lieu_2026!$F$2 & Du_Lieu_2026!$I$2 & Du_Lieu_2026!$L$2 & Du_Lieu_2026!$O$2)), "CÓ G7", "---") | F11: =IF(E11="CÓ G7", "CÓ NGUỒN", "---") | G11: =IF(OR(ISNUMBER(SEARCH(LEFT(B11,1),$G$2)), ISNUMBER(SEARCH(RIGHT(B11,1),$G$2))), "ĐÚNG CHẠM", "KHÔNG") | H11: =IF(D11="ĐÚNG TỔNG", 15, 0) + IF(G11="ĐÚNG CHẠM", 15, 0) + IF(E11="CÓ G7", 10, 0) + (100-ROW())/1000 | I11: =IF(RANK(H11,$H$3:$H$102)<=20, B11, "") | J11: =IF(AND(D11="ĐÚNG TỔNG", G11="ĐÚNG CHẠM", RANK(H11,$H$3:$H$102)<=10), B11, "")
A12: 10 | B12: 09 | C12: =MOD(VALUE(LEFT(B12,1))+VALUE(RIGHT(B12,1)), 10) | D12: =IF(ISNUMBER(SEARCH(TEXT(C12,"0"),$C$2)), "ĐÚNG TỔNG", "KHÔNG") | E12: =IF(ISNUMBER(SEARCH(TEXT(C12,"0"), Du_Lieu_2026!$F$2 & Du_Lieu_2026!$I$2 & Du_Lieu_2026!$L$2 & Du_Lieu_2026!$O$2)), "CÓ G7", "---") | F12: =IF(E12="CÓ G7", "CÓ NGUỒN", "---") | G12: =IF(OR(ISNUMBER(SEARCH(LEFT(B12,1),$G$2)), ISNUMBER(SEARCH(RIGHT(B12,1),$G$2))), "ĐÚNG CHẠM", "KHÔNG") | H12: =IF(D12="ĐÚNG TỔNG", 15, 0) + IF(G12="ĐÚNG CHẠM", 15, 0) + IF(E12="CÓ G7", 10, 0) + (100-ROW())/1000 | I12: =IF(RANK(H12,$H$3:$H$102)<=20, B12, "") | J12: =IF(AND(D12="ĐÚNG TỔNG", G12="ĐÚNG CHẠM", RANK(H12,$H$3:$H$102)<=10), B12, "")
A13: 11 | B13: 10 | C13: =MOD(VALUE(LEFT(B13,1))+VALUE(RIGHT(B13,1)), 10) | D13: =IF(ISNUMBER(SEARCH(TEXT(C13,"0"),$C$2)), "ĐÚNG TỔNG", "KHÔNG") | E13: =IF(ISNUMBER(SEARCH(TEXT(C13,"0"), Du_Lieu_2026!$F$2 & Du_Lieu_2026!$I$2 & Du_Lieu_2026!$L$2 & Du_Lieu_2026!$O$2)), "CÓ G7", "---") | F13: =IF(E13="CÓ G7", "CÓ NGUỒN", "---") | G13: =IF(OR(ISNUMBER(SEARCH(LEFT(B13,1),$G$2)), ISNUMBER(SEARCH(RIGHT(B13,1),$G$2))), "ĐÚNG CHẠM", "KHÔNG") | H13: =IF(D13="ĐÚNG TỔNG", 15, 0) + IF(G13="ĐÚNG CHẠM", 15, 0) + IF(E13="CÓ G7", 10, 0) + (100-ROW())/1000 | I13: =IF(RANK(H13,$H$3:$H$102)<=20, B13, "") | J13: =IF(AND(D13="ĐÚNG TỔNG", G13="ĐÚNG CHẠM", RANK(H13,$H$3:$H$102)<=10), B13, "")
A14: 12 | B14: 11 | C14: =MOD(VALUE(LEFT(B14,1))+VALUE(RIGHT(B14,1)), 10) | D14: =IF(ISNUMBER(SEARCH(TEXT(C14,"0"),$C$2)), "ĐÚNG TỔNG", "KHÔNG") | E14: =IF(ISNUMBER(SEARCH(TEXT(C14,"0"), Du_Lieu_2026!$F$2 & Du_Lieu_2026!$I$2 & Du_Lieu_2026!$L$2 & Du_Lieu_2026!$O$2)), "CÓ G7", "---") | F14: =IF(E14="CÓ G7", "CÓ NGUỒN", "---") | G14: =IF(OR(ISNUMBER(SEARCH(LEFT(B14,1),$G$2)), ISNUMBER(SEARCH(RIGHT(B14,1),$G$2))), "ĐÚNG CHẠM", "KHÔNG") | H14: =IF(D14="ĐÚNG TỔNG", 15, 0) + IF(G14="ĐÚNG CHẠM", 15, 0) + IF(E14="CÓ G7", 10, 0) + (100-ROW())/1000 | I14: =IF(RANK(H14,$H$3:$H$102)<=20, B14, "") | J14: =IF(AND(D14="ĐÚNG TỔNG", G14="ĐÚNG CHẠM", RANK(H14,$H$3:$H$102)<=10), B14, "")
... A102: 100 | B102: 99 | C102: =MOD(VALUE(LEFT(B102,1))+VALUE(RIGHT(B102,1)), 10) | D102: =IF(ISNUMBER(SEARCH(TEXT(C102,"0"),$C$2)), "ĐÚNG TỔNG", "KHÔNG") | E102: =IF(ISNUMBER(SEARCH(TEXT(C102,"0"), Du_Lieu_2026!$F$2 & Du_Lieu_2026!$I$2 & Du_Lieu_2026!$L$2 & Du_Lieu_2026!$O$2)), "CÓ G7", "---") | F102: =IF(E102="CÓ G7", "CÓ NGUỒN", "---") | G102: =IF(OR(ISNUMBER(SEARCH(LEFT(B102,1),$G$2)), ISNUMBER(SEARCH(RIGHT(B102,1),$G$2))), "ĐÚNG CHẠM", "KHÔNG") | H102: =IF(D102="ĐÚNG TỔNG", 15, 0) + IF(G102="ĐÚNG CHẠM", 15, 0) + IF(E102="CÓ G7", 10, 0) + (100-ROW())/1000 | I102: =IF(RANK(H102,$H$3:$H$102)<=20, B102, "") | J102: =IF(AND(D102="ĐÚNG TỔNG", G102="ĐÚNG CHẠM", RANK(H102,$H$3:$H$102)<=10), B102, "")

Sheet LIVE_LOC_THEO_THU
A1: ⚡ BỘ LỌC TỰ ĐỘNG THEO THỨ (LIVE EXCEL FORMULAS)
A2: Chọn Chạm Lọc (Dropdown C4) | B2: Chọn Tổng Lọc (Dropdown D4) | C2: Liên Kết File Gốc | D2: Tổng Số Con Dàn Hạ | E2: Trạng Thái
A3: Tất cả | B3: Tất cả | C3: =LOC_COPY!$C$5 | D3: =COUNTA(A7:Z20) | E3: Đang Tự Động Kết Nối Live
A5: --- DÀN SỐ HẠ TỰ ĐỘNG THEO CHẠM & TỔNG ĐÃ CHỌN ---
B6: =IF(AND(OR(A$3="Tất cả", 0=INT(A$3), 1=INT(A$3)), OR(B$3="Tất cả", 1=INT(B$3))), "01", "") | C6: =IF(AND(OR(A$3="Tất cả", 0=INT(A$3), 2=INT(A$3)), OR(B$3="Tất cả", 2=INT(B$3))), "02", "") | D6: =IF(AND(OR(A$3="Tất cả", 0=INT(A$3), 3=INT(A$3)), OR(B$3="Tất cả", 3=INT(B$3))), "03", "") | G6: =IF(AND(OR(A$3="Tất cả", 0=INT(A$3), 6=INT(A$3)), OR(B$3="Tất cả", 6=INT(B$3))), "06", "") | H6: =IF(AND(OR(A$3="Tất cả", 0=INT(A$3), 7=INT(A$3)), OR(B$3="Tất cả", 7=INT(B$3))), "07", "") | I6: =IF(AND(OR(A$3="Tất cả", 0=INT(A$3), 8=INT(A$3)), OR(B$3="Tất cả", 8=INT(B$3))), "08", "")
A7: =IF(AND(OR(A$3="Tất cả", 1=INT(A$3), 0=INT(A$3)), OR(B$3="Tất cả", 1=INT(B$3))), "10", "") | B7: =IF(AND(OR(A$3="Tất cả", 1=INT(A$3), 1=INT(A$3)), OR(B$3="Tất cả", 2=INT(B$3))), "11", "") | C7: =IF(AND(OR(A$3="Tất cả", 1=INT(A$3), 2=INT(A$3)), OR(B$3="Tất cả", 3=INT(B$3))), "12", "") | F7: =IF(AND(OR(A$3="Tất cả", 1=INT(A$3), 5=INT(A$3)), OR(B$3="Tất cả", 6=INT(B$3))), "15", "") | G7: =IF(AND(OR(A$3="Tất cả", 1=INT(A$3), 6=INT(A$3)), OR(B$3="Tất cả", 7=INT(B$3))), "16", "") | H7: =IF(AND(OR(A$3="Tất cả", 1=INT(A$3), 7=INT(A$3)), OR(B$3="Tất cả", 8=INT(B$3))), "17", "")
A8: =IF(AND(OR(A$3="Tất cả", 2=INT(A$3), 0=INT(A$3)), OR(B$3="Tất cả", 2=INT(B$3))), "20", "") | B8: =IF(AND(OR(A$3="Tất cả", 2=INT(A$3), 1=INT(A$3)), OR(B$3="Tất cả", 3=INT(B$3))), "21", "") | E8: =IF(AND(OR(A$3="Tất cả", 2=INT(A$3), 4=INT(A$3)), OR(B$3="Tất cả", 6=INT(B$3))), "24", "") | F8: =IF(AND(OR(A$3="Tất cả", 2=INT(A$3), 5=INT(A$3)), OR(B$3="Tất cả", 7=INT(B$3))), "25", "") | G8: =IF(AND(OR(A$3="Tất cả", 2=INT(A$3), 6=INT(A$3)), OR(B$3="Tất cả", 8=INT(B$3))), "26", "") | J8: =IF(AND(OR(A$3="Tất cả", 2=INT(A$3), 9=INT(A$3)), OR(B$3="Tất cả", 1=INT(B$3))), "29", "")
A9: =IF(AND(OR(A$3="Tất cả", 3=INT(A$3), 0=INT(A$3)), OR(B$3="Tất cả", 3=INT(B$3))), "30", "") | D9: =IF(AND(OR(A$3="Tất cả", 3=INT(A$3), 3=INT(A$3)), OR(B$3="Tất cả", 6=INT(B$3))), "33", "") | E9: =IF(AND(OR(A$3="Tất cả", 3=INT(A$3), 4=INT(A$3)), OR(B$3="Tất cả", 7=INT(B$3))), "34", "") | F9: =IF(AND(OR(A$3="Tất cả", 3=INT(A$3), 5=INT(A$3)), OR(B$3="Tất cả", 8=INT(B$3))), "35", "") | I9: =IF(AND(OR(A$3="Tất cả", 3=INT(A$3), 8=INT(A$3)), OR(B$3="Tất cả", 1=INT(B$3))), "38", "") | J9: =IF(AND(OR(A$3="Tất cả", 3=INT(A$3), 9=INT(A$3)), OR(B$3="Tất cả", 2=INT(B$3))), "39", "")
C10: =IF(AND(OR(A$3="Tất cả", 4=INT(A$3), 2=INT(A$3)), OR(B$3="Tất cả", 6=INT(B$3))), "42", "") | D10: =IF(AND(OR(A$3="Tất cả", 4=INT(A$3), 3=INT(A$3)), OR(B$3="Tất cả", 7=INT(B$3))), "43", "") | E10: =IF(AND(OR(A$3="Tất cả", 4=INT(A$3), 4=INT(A$3)), OR(B$3="Tất cả", 8=INT(B$3))), "44", "") | H10: =IF(AND(OR(A$3="Tất cả", 4=INT(A$3), 7=INT(A$3)), OR(B$3="Tất cả", 1=INT(B$3))), "47", "") | I10: =IF(AND(OR(A$3="Tất cả", 4=INT(A$3), 8=INT(A$3)), OR(B$3="Tất cả", 2=INT(B$3))), "48", "") | J10: =IF(AND(OR(A$3="Tất cả", 4=INT(A$3), 9=INT(A$3)), OR(B$3="Tất cả", 3=INT(B$3))), "49", "")
B11: =IF(AND(OR(A$3="Tất cả", 5=INT(A$3), 1=INT(A$3)), OR(B$3="Tất cả", 6=INT(B$3))), "51", "") | C11: =IF(AND(OR(A$3="Tất cả", 5=INT(A$3), 2=INT(A$3)), OR(B$3="Tất cả", 7=INT(B$3))), "52", "") | D11: =IF(AND(OR(A$3="Tất cả", 5=INT(A$3), 3=INT(A$3)), OR(B$3="Tất cả", 8=INT(B$3))), "53", "") | G11: =IF(AND(OR(A$3="Tất cả", 5=INT(A$3), 6=INT(A$3)), OR(B$3="Tất cả", 1=INT(B$3))), "56", "") | H11: =IF(AND(OR(A$3="Tất cả", 5=INT(A$3), 7=INT(A$3)), OR(B$3="Tất cả", 2=INT(B$3))), "57", "") | I11: =IF(AND(OR(A$3="Tất cả", 5=INT(A$3), 8=INT(A$3)), OR(B$3="Tất cả", 3=INT(B$3))), "58", "")
A12: =IF(AND(OR(A$3="Tất cả", 6=INT(A$3), 0=INT(A$3)), OR(B$3="Tất cả", 6=INT(B$3))), "60", "") | B12: =IF(AND(OR(A$3="Tất cả", 6=INT(A$3), 1=INT(A$3)), OR(B$3="Tất cả", 7=INT(B$3))), "61", "") | C12: =IF(AND(OR(A$3="Tất cả", 6=INT(A$3), 2=INT(A$3)), OR(B$3="Tất cả", 8=INT(B$3))), "62", "") | F12: =IF(AND(OR(A$3="Tất cả", 6=INT(A$3), 5=INT(A$3)), OR(B$3="Tất cả", 1=INT(B$3))), "65", "") | G12: =IF(AND(OR(A$3="Tất cả", 6=INT(A$3), 6=INT(A$3)), OR(B$3="Tất cả", 2=INT(B$3))), "66", "") | H12: =IF(AND(OR(A$3="Tất cả", 6=INT(A$3), 7=INT(A$3)), OR(B$3="Tất cả", 3=INT(B$3))), "67", "")
A13: =IF(AND(OR(A$3="Tất cả", 7=INT(A$3), 0=INT(A$3)), OR(B$3="Tất cả", 7=INT(B$3))), "70", "") | B13: =IF(AND(OR(A$3="Tất cả", 7=INT(A$3), 1=INT(A$3)), OR(B$3="Tất cả", 8=INT(B$3))), "71", "") | E13: =IF(AND(OR(A$3="Tất cả", 7=INT(A$3), 4=INT(A$3)), OR(B$3="Tất cả", 1=INT(B$3))), "74", "") | F13: =IF(AND(OR(A$3="Tất cả", 7=INT(A$3), 5=INT(A$3)), OR(B$3="Tất cả", 2=INT(B$3))), "75", "") | G13: =IF(AND(OR(A$3="Tất cả", 7=INT(A$3), 6=INT(A$3)), OR(B$3="Tất cả", 3=INT(B$3))), "76", "") | J13: =IF(AND(OR(A$3="Tất cả", 7=INT(A$3), 9=INT(A$3)), OR(B$3="Tất cả", 6=INT(B$3))), "79", "")
A14: =IF(AND(OR(A$3="Tất cả", 8=INT(A$3), 0=INT(A$3)), OR(B$3="Tất cả", 8=INT(B$3))), "80", "") | D14: =IF(AND(OR(A$3="Tất cả", 8=INT(A$3), 3=INT(A$3)), OR(B$3="Tất cả", 1=INT(B$3))), "83", "") | E14: =IF(AND(OR(A$3="Tất cả", 8=INT(A$3), 4=INT(A$3)), OR(B$3="Tất cả", 2=INT(B$3))), "84", "") | F14: =IF(AND(OR(A$3="Tất cả", 8=INT(A$3), 5=INT(A$3)), OR(B$3="Tất cả", 3=INT(B$3))), "85", "") | I14: =IF(AND(OR(A$3="Tất cả", 8=INT(A$3), 8=INT(A$3)), OR(B$3="Tất cả", 6=INT(B$3))), "88", "") | J14: =IF(AND(OR(A$3="Tất cả", 8=INT(A$3), 9=INT(A$3)), OR(B$3="Tất cả", 7=INT(B$3))), "89", "")
C15: =IF(AND(OR(A$3="Tất cả", 9=INT(A$3), 2=INT(A$3)), OR(B$3="Tất cả", 1=INT(B$3))), "92", "") | D15: =IF(AND(OR(A$3="Tất cả", 9=INT(A$3), 3=INT(A$3)), OR(B$3="Tất cả", 2=INT(B$3))), "93", "") | E15: =IF(AND(OR(A$3="Tất cả", 9=INT(A$3), 4=INT(A$3)), OR(B$3="Tất cả", 3=INT(B$3))), "94", "") | H15: =IF(AND(OR(A$3="Tất cả", 9=INT(A$3), 7=INT(A$3)), OR(B$3="Tất cả", 6=INT(B$3))), "97", "") | I15: =IF(AND(OR(A$3="Tất cả", 9=INT(A$3), 8=INT(A$3)), OR(B$3="Tất cả", 7=INT(B$3))), "98", "") | J15: =IF(AND(OR(A$3="Tất cả", 9=INT(A$3), 9=INT(A$3)), OR(B$3="Tất cả", 8=INT(B$3))), "99", "")

Sheet Du_Lieu_2026
A1: STT | B1: Ngày Quay | C1: Giải Đặc Biệt (5 số) | D1: Số Đề (2 số cuối) | E1: G7.1 | F1: Tổng/Bóng G7.1 | G1: Trúng Đề Hôm Sau (G7.1) | H1: G7.2 | I1: Tổng/Bóng G7.2 | J1: Trúng Đề Hôm Sau (G7.2) | K1: G7.3 | L1: Tổng/Bóng G7.3 | M1: Trúng Đề Hôm Sau (G7.3) | N1: G7.4 | O1: Tổng/Bóng G7.4 | P1: Trúng Đề Hôm Sau (G7.4)
A2: 1 | B2: Thứ năm ngày 01-01-2026 | C2: 57068 | D2: 68 | E2: 91 | F2: T0-B5 | G2: Không | H2: 25 | I2: T7-B2 | J2: Trúng | K2: 69 | L2: T5-B0 | M2: Không | N2: 67 | O2: T3-B8 | P2: Không
A3: 2 | B3: Thứ sáu ngày 02-01-2026 | C3: 45748 | D3: 48 | E3: 29 | F3: T1-B6 | G3: Không | H3: 24 | I3: T6-B1 | J3: Không | K3: 38 | L3: T1-B6 | M3: Không | N3: 22 | O3: T4-B9 | P3: Không
A4: 3 | B4: Thứ bảy ngày 03-01-2026 | C4: 00949 | D4: 49 | E4: 46 | F4: T0-B5 | G4: Không | H4: 33 | I4: T6-B1 | J4: Trúng | K4: 92 | L4: T1-B6 | M4: Trúng | N4: 48 | O4: T2-B7 | P4: Không
A5: 4 | B5: Chủ nhật ngày 04-01-2026 | C5: 72397 | D5: 97 | E5: 68 | F5: T4-B9 | G5: Không | H5: 34 | I5: T7-B2 | J5: Không | K5: 77 | L5: T4-B9 | M5: Không | N5: 25 | O5: T7-B2 | P5: Không
A6: 5 | B6: Thứ hai ngày 05-01-2026 | C6: 70505 | D6: 05 | E6: 47 | F6: T1-B6 | G6: Trúng | H6: 43 | I6: T7-B2 | J6: Không | K6: 65 | L6: T1-B6 | M6: Trúng | N6: 27 | O6: T9-B4 | P6: Không
A7: 6 | B7: Thứ ba ngày 06-01-2026 | C7: 78447 | D7: 47 | E7: 50 | F7: T5-B0 | G7: Không | H7: 10 | I7: T1-B6 | J7: Không | K7: 65 | L7: T1-B6 | M7: Không | N7: 12 | O7: T3-B8 | P7: Không
A8: 7 | B8: Thứ tư ngày 07-01-2026 | C8: 14389 | D8: 89 | E8: 39 | F8: T2-B7 | G8: Không | H8: 64 | I8: T0-B5 | J8: Không | K8: 24 | L8: T6-B1 | M8: Không | N8: 57 | O8: T2-B7 | P8: Không
A9: 8 | B9: Thứ năm ngày 08-01-2026 | C9: 40162 | D9: 62 | E9: 54 | F9: T9-B4 | G9: Không | H9: 88 | I9: T6-B1 | J9: Không | K9: 82 | L9: T0-B5 | M9: Trúng | N9: 13 | O9: T4-B9 | P9: Không
A10: 9 | B10: Thứ sáu ngày 09-01-2026 | C10: 39523 | D10: 23 | E10: 47 | F10: T1-B6 | G10: Không | H10: 87 | I10: T5-B0 | J10: Không | K10: 52 | L10: T7-B2 | M10: Trúng | N10: 46 | O10: T0-B5 | P10: Không
A11: 10 | B11: Thứ bảy ngày 10-01-2026 | C11: 67793 | D11: 93 | E11: 70 | F11: T7-B2 | G11: Không | H11: 45 | I11: T9-B4 | J11: Không | K11: 14 | L11: T5-B0 | M11: Không | N11: 13 | O11: T4-B9 | P11: Không
A12: 11 | B12: Chủ nhật ngày 11-01-2026 | C12: 82438 | D12: 38 | E12: 70 | F12: T7-B2 | G12: Không | H12: 95 | I12: T4-B9 | J12: Không | K12: 10 | L12: T1-B6 | M12: Không | N12: 43 | O12: T7-B2 | P12: Không
A13: 12 | B13: Thứ hai ngày 12-01-2026 | C13: 31894 | D13: 94 | E13: 31 | F13: T4-B9 | G13: Trúng | H13: 34 | I13: T7-B2 | J13: Không | K13: 20 | L13: T2-B7 | M13: Không | N13: 42 | O13: T6-B1 | P13: Không
... A291: 290 | B291: Thứ Tư ngày 21-10-2026 | C291: 94163 | D291: 63 | E291: 42 | F291: T6-B1 | G291: N/A | H291: 62 | I291: T8-B3 | J291: N/A | K291: 94 | L291: T3-B8 | M291: N/A | N291: 08 | O291: T8-B3 | P291: N/A

Sheet Thong_Ke_G7_MultiWindow
A1: Cửa Sổ / Mô Hình | B1: Tỷ Lệ Trúng 2026 | C1: Số Lần Trúng | D1: Đánh Giá Chiến Thuật
A2: 🎯 KHUNG NUÔI 1 NGÀY (Trúng Ngay) | B2: 47.75% | C2: 138 / 289 ngày | D2: Chơi Ngày Nào Biết Ngày Đó
A3: 🔥 KHUNG NUÔI 2 NGÀY (Nối Tiếp) | B3: 72.5% | C3: 220 / 289 ngày | D3: Vốn An Toàn - Tỷ Lệ Trúng > 72%
A4: 🚀 KHUNG NUÔI 3 NGÀY (Max Khung) | B4: 87.5% | C4: 273 / 289 ngày | D4: Tối Ưu Cực Đại - Tỷ Lệ Trúng Gần 88%
A5: Tuần 43 (Tuần Trước) | B5: Top 1: G7_2 | C5: Top 2: G7_1 | D5: Top 3: G7_3 (Loại G7_4)
A6: Khung 30 Ngày Gần Nhất | B6: Top 1: G7_1 (33.3%) | C6: Top 2: G7_2 (30.0%) | D6: Top 3: G7_3 (20.0%) | Loại: G7_4
A7: Khung 60 Ngày Gần Nhất | B7: Top 1: G7_2 (25.0%) | C7: Top 2: G7_1 (23.3%) | D7: Top 3: G7_3 (21.7%) | Loại: G7_4
A8: Khung 90 Ngày Gần Nhất | B8: Top 1: G7_1 (24.4%) | C8: Top 2: G7_3 (23.3%) | D8: Top 3: G7_2 (22.2%) | Loại: G7_4

Sheet Top20_Dong_Thuan
A1: Thứ Hạng | B1: Con Số | C1: Thuộc Tổng | D1: Chạm G7 Hợp Lệ | E1: TS 30 Ngày | F1: TS 60 Ngày | G1: TS 90 Ngày | H1: Nhịp Gan (ngày) | I1: Đánh Giá Nhịp | J1: Điểm Đồng Thuận Super-Score
A2: Top 01 | B2: 42 | C2: Tổng 6 | D2: CÓ | E2: 2 | F2: 3 | G2: 3 | H2: 3 | I2: Nhịp Đẹp | J2: 50
A3: Top 02 | B3: 38 | C3: Tổng 1 | D3: CÓ | E3: 1 | F3: 3 | G3: 4 | H3: 4 | I3: Nhịp Đẹp | J3: 48
A4: Top 03 | B4: 51 | C4: Tổng 6 | D4: KHÔNG | E4: 2 | F4: 3 | G4: 3 | H4: 17 | I4: Nhịp Đẹp | J4: 45
A5: Top 04 | B5: 83 | C5: Tổng 1 | D5: CÓ | E5: 1 | F5: 1 | G5: 3 | H5: 19 | I5: Nhịp Đẹp | J5: 43
A6: Top 05 | B6: 08 | C6: Tổng 8 | D6: CÓ | E6: 1 | F6: 1 | G6: 1 | H6: 20 | I6: Nhịp Đẹp | J6: 41
A7: Top 06 | B7: 56 | C7: Tổng 1 | D7: CÓ | E7: 1 | F7: 1 | G7: 1 | H7: 5 | I7: Nhịp Đẹp | J7: 41
A8: Top 07 | B8: 88 | C8: Tổng 6 | D8: CÓ | E8: 1 | F8: 1 | G8: 1 | H8: 14 | I8: Nhịp Đẹp | J8: 41
A9: Top 08 | B9: 35 | C9: Tổng 8 | D9: KHÔNG | E9: 1 | F9: 2 | G9: 2 | H9: 12 | I9: Nhịp Đẹp | J9: 39
A10: Top 09 | B10: 15 | C10: Tổng 6 | D10: KHÔNG | E10: 1 | F10: 1 | G10: 1 | H10: 23 | I10: Nhịp Đẹp | J10: 36
A11: Top 10 | B11: 53 | C11: Tổng 8 | D11: KHÔNG | E11: 1 | F11: 1 | G11: 1 | H11: 11 | I11: Nhịp Đẹp | J11: 36
A12: Top 11 | B12: 44 | C12: Tổng 8 | D12: CÓ | E12: 0 | F12: 2 | G12: 3 | H12: 35 | I12: Gan Dài | J12: 32
A13: Top 12 | B13: 06 | C13: Tổng 6 | D13: CÓ | E13: 1 | F13: 1 | G13: 1 | H13: 28 | I13: Gan Dài | J13: 31
... A21: Top 20 | B21: 99 | C21: Tổng 8 | D21: CÓ | E21: 0 | F21: 1 | G21: 1 | H21: 38 | I21: Gan Dài | J21: 28

Sheet Thong_Ke_Theo_Thu
A1: Thứ Trong Tuần | B1: Số Ngày | C1: G7.1 Trực Diện | D1: G7.1 Bóng | E1: G7.1 Tổng Trúng | F1: G7.2 Trực Diện | G1: G7.2 Bóng | H1: G7.2 Tổng Trúng | I1: G7.3 Trực Diện | J1: G7.3 Bóng | K1: G7.3 Tổng Trúng | L1: G7.4 Trực Diện | M1: G7.4 Bóng | N1: G7.4 Tổng Trúng | O1: Tỷ lệ ăn Chạm G7 gốc (%) | P1: Tỷ lệ ăn khi ép [Chạm Chính B9 x Tổng/Bóng G7] (%) | Q1: Số lượng con số bình quân sau khi hạ dàn | R1: Đánh Giá Vị Trí G7 Ưu Tiên
A2: Thứ Hai | B2: 41 ngày | C2: 2 (4.9%) | D2: 5 (12.2%) | E2: 7 (17.1%) | F2: 2 (4.9%) | G2: 5 (12.2%) | H2: 7 (17.1%) | I2: 8 (19.5%) | J2: 3 (7.3%) | K2: 11 (26.8%) | L2: 2 (4.9%) | M2: 4 (9.8%) | N2: 6 (14.6%) | O2: 34 (82.9%) | P2: 21 (51.2%) | Q2: TB ~48 con | R2: Tối Ưu Theo Thứ
A3: Thứ Ba | B3: 41 ngày | C3: 0 (0.0%) | D3: 5 (12.2%) | E3: 5 (12.2%) | F3: 5 (12.2%) | G3: 5 (12.2%) | H3: 10 (24.4%) | I3: 4 (9.8%) | J3: 4 (9.8%) | K3: 8 (19.5%) | L3: 2 (4.9%) | M3: 3 (7.3%) | N3: 5 (12.2%) | O3: 32 (78.0%) | P3: 17 (41.5%) | Q3: TB ~48 con | R3: Tối Ưu Theo Thứ
A4: Thứ Tư | B4: 40 ngày | C4: 7 (17.5%) | D4: 6 (15.0%) | E4: 13 (32.5%) | F4: 2 (5.0%) | G4: 3 (7.5%) | H4: 5 (12.5%) | I4: 1 (2.5%) | J4: 3 (7.5%) | K4: 4 (10.0%) | L4: 0 (0.0%) | M4: 1 (2.5%) | N4: 1 (2.5%) | O4: 38 (95.0%) | P4: 16 (40.0%) | Q4: TB ~48 con | R4: Tối Ưu Theo Thứ
A5: Thứ Năm | B5: 41 ngày | C5: 4 (9.8%) | D5: 8 (19.5%) | E5: 12 (29.3%) | F5: 4 (9.8%) | G5: 2 (4.9%) | H5: 6 (14.6%) | I5: 3 (7.3%) | J5: 9 (22.0%) | K5: 12 (29.3%) | L5: 3 (7.3%) | M5: 2 (4.9%) | N5: 5 (12.2%) | O5: 33 (80.5%) | P5: 22 (53.7%) | Q5: TB ~48 con | R5: Tối Ưu Theo Thứ
A6: Thứ Sáu | B6: 42 ngày | C6: 1 (2.4%) | D6: 3 (7.1%) | E6: 4 (9.5%) | F6: 3 (7.1%) | G6: 5 (11.9%) | H6: 8 (19.0%) | I6: 5 (11.9%) | J6: 7 (16.7%) | K6: 12 (28.6%) | L6: 2 (4.8%) | M6: 6 (14.3%) | N6: 8 (19.0%) | O6: 36 (85.7%) | P6: 18 (42.9%) | Q6: TB ~48 con | R6: Tối Ưu Theo Thứ
A7: Thứ Bảy | B7: 42 ngày | C7: 5 (11.9%) | D7: 2 (4.8%) | E7: 7 (16.7%) | F7: 2 (4.8%) | G7: 6 (14.3%) | H7: 8 (19.0%) | I7: 2 (4.8%) | J7: 5 (11.9%) | K7: 7 (16.7%) | L7: 2 (4.8%) | M7: 7 (16.7%) | N7: 9 (21.4%) | O7: 35 (83.3%) | P7: 18 (42.9%) | Q7: TB ~48 con | R7: Tối Ưu Theo Thứ
A8: Chủ Nhật | B8: 42 ngày | C8: 4 (9.5%) | D8: 1 (2.4%) | E8: 5 (11.9%) | F8: 3 (7.1%) | G8: 7 (16.7%) | H8: 10 (23.8%) | I8: 5 (11.9%) | J8: 2 (4.8%) | K8: 7 (16.7%) | L8: 5 (11.9%) | M8: 5 (11.9%) | N8: 10 (23.8%) | O8: 36 (85.7%) | P8: 21 (50.0%) | Q8: TB ~48 con | R8: Tối Ưu Theo Thứ

Sheet Du_Doan_Tong_Theo_Thu
A1: Hạng Mục Dự Đoán | B1: Chi Tiết Kế Thừa & Dự Đoán Theo Thứ
A2: Hạng Mục Dự Đoán | B2: Chi Tiết Kế Thừa & Dự Đoán Theo Thứ
A3: Ngày Dự Đoán Tiếp Theo | B3: Thứ Năm (Kế thừa phong độ Thứ Năm năm 2026)
A4: Top 2 Vị Trí G7 Ưu Tiên | B4: G7.1, G7.4
A5: Các Tổng & Bóng Ưu Tiên Nổ | B5: Tổng 1, Tổng 2, Tổng 3, Tổng 6, Tổng 7, Tổng 8
A6: Tập Chạm Ngày Ưu Tiên | B6: 0123456789
A7: Cầu Ghép Góc (G7.1[0] + G7.4[1]) | B7: Tổng 2 - Bóng 7
A8: Dàn Giao Thoa Dự Đoán (~47 con) | B8: 01, 02, 03, 06, 07, 08, 10, 11, 12, 15, 16, 17, 20, 21, 24, 25, 26, 29, 30, 33, 34, 35, 38, 39, 42, 43, 44, 47, 48, 49, 51, 52, 53, 56, 57, 58, 60, 61, 62, 65, 66, 67, 70, 71, 74, 75, 76, 79, 80, 83, 84, 85, 88, 89, 92, 93, 94, 97, 98, 99
A9: Dàn Hạ Số Hỏa Lực Top 20 | B9: 42, 38, 66, 51, 56, 61, 35, 83, 39, 08, 88, 53, 44, 15, 06, 65, 60, 67, 21, 99
A10: --- XU HƯỚNG VỊ TRÍ G7 THEO TỪNG THỨ (2026) ---
A11: Phong Độ Thứ Hai | B11: Top 1 Vị Trí G7.3 (Trúng 11/41 ngày - 26.8%)
A12: Phong Độ Thứ Ba | B12: Top 1 Vị Trí G7.2 (Trúng 10/41 ngày - 24.4%)
A13: Phong Độ Thứ Tư | B13: Top 1 Vị Trí G7.1 (Trúng 13/40 ngày - 32.5%)
A14: Phong Độ Thứ Năm | B14: Top 1 Vị Trí G7.1 (Trúng 12/41 ngày - 29.3%)
A15: Phong Độ Thứ Sáu | B15: Top 1 Vị Trí G7.3 (Trúng 12/42 ngày - 28.6%)
A16: Phong Độ Thứ Bảy | B16: Top 1 Vị Trí G7.4 (Trúng 9/42 ngày - 21.4%)
A17: Phong Độ Chủ Nhật | B17: Top 1 Vị Trí G7.2 (Trúng 10/42 ngày - 23.8%)

Sheet Thong_Ke_Phong_Do_G7_Thu
A1: Thứ Trong Tuần | B1: Số Ngày Phân Tích | C1: G7.1 Trúng Tổng/Bóng | D1: G7.2 Trúng Tổng/Bóng | E1: G7.3 Trúng Tổng/Bóng | F1: G7.4 Trúng Tổng/Bóng | G1: Vị Trí G7 Tối Ưu Nhất | H1: Khuyên Dùng Đánh Theo Thứ
A2: Thứ Hai | B2: 41 ngày | C2: 7 lần (17.1%) | D2: 7 lần (17.1%) | E2: 11 lần (26.8%) | F2: 6 lần (14.6%) | G2: Top 1: G7.3 | Top 2: G7.1 | H2: Ưu tiên ép Tổng G7.3 & G7.1
A3: Thứ Ba | B3: 41 ngày | C3: 5 lần (12.2%) | D3: 10 lần (24.4%) | E3: 8 lần (19.5%) | F3: 5 lần (12.2%) | G3: Top 1: G7.2 | Top 2: G7.3 | H3: Ưu tiên ép Tổng G7.2 & G7.3
A4: Thứ Tư | B4: 40 ngày | C4: 13 lần (32.5%) | D4: 5 lần (12.5%) | E4: 4 lần (10.0%) | F4: 1 lần (2.5%) | G4: Top 1: G7.1 | Top 2: G7.2 | H4: Ưu tiên ép Tổng G7.1 & G7.2
A5: Thứ Năm | B5: 41 ngày | C5: 12 lần (29.3%) | D5: 6 lần (14.6%) | E5: 12 lần (29.3%) | F5: 5 lần (12.2%) | G5: Top 1: G7.1 | Top 2: G7.3 | H5: Ưu tiên ép Tổng G7.1 & G7.3
A6: Thứ Sáu | B6: 42 ngày | C6: 4 lần (9.5%) | D6: 8 lần (19.0%) | E6: 12 lần (28.6%) | F6: 8 lần (19.0%) | G6: Top 1: G7.3 | Top 2: G7.2 | H6: Ưu tiên ép Tổng G7.3 & G7.2
A7: Thứ Bảy | B7: 42 ngày | C7: 7 lần (16.7%) | D7: 8 lần (19.0%) | E7: 7 lần (16.7%) | F7: 9 lần (21.4%) | G7: Top 1: G7.4 | Top 2: G7.2 | H7: Ưu tiên ép Tổng G7.4 & G7.2
A8: Chủ Nhật | B8: 42 ngày | C8: 5 lần (11.9%) | D8: 10 lần (23.8%) | E8: 7 lần (16.7%) | F8: 10 lần (23.8%) | G8: Top 1: G7.2 | Top 2: G7.4 | H8: Ưu tiên ép Tổng G7.2 & G7.4

Sheet Nhat_Ky_Kiem_Chung_Thu
A1: STT | B1: Ngày Quay | C1: Thứ | D1: Giải Đặc Biệt | E1: Số Đề | F1: Top 2 G7 Theo Thứ | G1: Tổng & Bóng Dự Đoán | H1: Tập Chạm Ngày | I1: Cầu Ghép Góc | J1: Số Con Dàn | K1: Kết Quả Trúng 1 Ngày (K1) | L1: Dàn Hạ Số Hỏa Lực | M1: Kết Quả Dàn Hạ Số | N1: Kết Quả Nuôi Khung 3 Ngày | O1: Danh Sách Dàn Giao Thoa
A2: TỔNG CỘNG 2026 | B2: Tổng: 289 Ngày | C2: --- | D2: TỔNG QUAN | E2: --- | F2: --- | G2: --- | H2: --- | I2: --- | J2: TB 47.2 con | K2: Trúng 1N: 127/289 (43.94%) | L2: TB 19.9 con | M2: Trúng Hỏa Lực: 46/289 (15.92%) | N2: Trúng Khung 3N: 246/287 (85.71%) | O2: Mô Hình Giao Thoa G7 Theo Thứ
A3: 289 | B3: Thứ Tư ngày 21-10-2026 | C3: Thứ Ba | D3: 94163 | E3: 63 | F3: G7.3, G7.1 | G3: Tổng 1, Tổng 4, Tổng 6, Tổng 9 | H3: 0123456789 | I3: Tổng 9-Bóng 4 | J3: 40 | K3: TRÚNG N1 🎯 | L3: 04, 06, 09, 13, 15, 18, 22, 38, 42, 51, 54, 56, 59, 60, 63, 65, 68, 83, 88, 90 | M3: TRÚNG HỎA LỰC 🎯 | N3: TRƯỢT KHUNG ❌ | O3: 01, 04, 06, 09, 10, 13, 15, 18, 22, 24, 27, 29, 31, 33, 36, 38, 40, 42, 45, 47, 51, 54, 56, 59, 60, 63, 65, 68, 72, 74, 77, 79, 81, 83, 86, 88, 90, 92, 95, 97
A4: 288 | B4: Thứ Ba ngày 20-10-2026 | C4: Thứ Hai | D4: 86809 | E4: 09 | F4: G7.2, G7.4 | G4: Tổng 0, Tổng 1, Tổng 3, Tổng 5, Tổng 6, Tổng 8 | H4: 034589 | I4: Tổng 5-Bóng 0 | J4: 52 | K4: TRƯỢT ❌ | L4: 06, 08, 15, 32, 35, 37, 38, 42, 44, 51, 53, 56, 60, 65, 73, 83, 87, 88, 96, 99 | M4: TRƯỢT ❌ | N4: TRƯỢT KHUNG ❌ | O4: 00, 01, 03, 05, 06, 08, 10, 14, 15, 19, 23, 24, 28, 29, 30, 32, 33, 35, 37, 38, 41, 42, 44, 46, 47, 49, 50, 51, 53, 55, 56, 58, 60, 64, 65, 69, 73, 74, 78, 79, 80, 82, 83, 85, 87, 88, 91, 92, 94, 96, 97, 99
A5: 287 | B5: Thứ Hai ngày 19-10-2026 | C5: Chủ Nhật | D5: 55390 | E5: 90 | F5: G7.3, G7.1 | G5: Tổng 3, Tổng 4, Tổng 8, Tổng 9 | H5: 01245679 | I5: Tổng 4-Bóng 9 | J5: 40 | K5: TRÚNG N1 🎯 | L5: 04, 08, 12, 13, 17, 18, 21, 22, 35, 44, 53, 54, 59, 63, 67, 68, 80, 81, 90, 99 | M5: TRÚNG HỎA LỰC 🎯 | N5: TRÚNG N1 🎯 | O5: 03, 04, 08, 09, 12, 13, 17, 18, 21, 22, 26, 27, 30, 31, 35, 36, 40, 44, 45, 49, 53, 54, 58, 59, 62, 63, 67, 68, 71, 72, 76, 77, 80, 81, 85, 86, 90, 94, 95, 99
A6: 286 | B6: Chủ Nhật ngày 18-10-2026 | C6: Thứ Bảy | D6: 84642 | E6: 42 | F6: G7.1, G7.3 | G6: Tổng 1, Tổng 3, Tổng 4, Tổng 6, Tổng 8, Tổng 9 | H6: 01245679 | I6: Tổng 6-Bóng 1 | J6: 56 | K6: TRÚNG N1 🎯 | L6: 06, 08, 12, 15, 18, 21, 22, 35, 42, 44, 51, 53, 54, 56, 59, 60, 63, 65, 67, 99 | M6: TRÚNG HỎA LỰC 🎯 | N6: TRÚNG N1 🎯 | O6: 01, 03, 04, 06, 08, 09, 10, 12, 13, 15, 17, 18, 21, 22, 24, 26, 27, 29, 30, 31, 35, 36, 40, 42, 44, 45, 47, 49, 51, 53, 54, 56, 58, 59, 60, 62, 63, 65, 67, 68, 71, 72, 74, 76, 77, 79, 80, 81, 85, 86, 90, 92, 94, 95, 97, 99
A7: 285 | B7: Thứ Bảy ngày 17-10-2026 | C7: Thứ Sáu | D7: 64538 | E7: 38 | F7: G7.1, G7.4 | G7: Tổng 1, Tổng 4, Tổng 6, Tổng 9 | H7: 02345789 | I7: Tổng 9-Bóng 4 | J7: 40 | K7: TRÚNG N1 🎯 | L7: 04, 06, 13, 15, 18, 22, 38, 42, 51, 54, 56, 59, 60, 63, 65, 68, 81, 83, 88, 90 | M7: TRÚNG HỎA LỰC 🎯 | N7: TRÚNG N1 🎯 | O7: 01, 04, 06, 09, 10, 13, 15, 18, 22, 24, 27, 29, 31, 33, 36, 38, 40, 42, 45, 47, 51, 54, 56, 59, 60, 63, 65, 68, 72, 74, 77, 79, 81, 83, 86, 88, 90, 92, 95, 97
A8: 284 | B8: Thứ Sáu ngày 16-10-2026 | C8: Thứ Năm | D8: 63756 | E8: 56 | F8: G7.1, G7.4 | G8: Tổng 0, Tổng 5 | H8: 0123456789 | I8: Tổng 0-Bóng 5 | J8: 20 | K8: TRƯỢT ❌ | L8: 00, 05, 14, 19, 23, 28, 32, 37, 41, 46, 50, 55, 64, 69, 73, 78, 82, 87, 91, 96 | M8: TRƯỢT ❌ | N8: TRƯỢT KHUNG ❌ | O8: 00, 05, 14, 19, 23, 28, 32, 37, 41, 46, 50, 55, 64, 69, 73, 78, 82, 87, 91, 96
A9: 283 | B9: Thứ Năm ngày 15-10-2026 | C9: Thứ Tư | D9: 62066 | E9: 66 | F9: G7.2, G7.4 | G9: Tổng 0, Tổng 4, Tổng 5, Tổng 9 | H9: 01345689 | I9: Tổng 5-Bóng 0 | J9: 36 | K9: TRƯỢT ❌ | L9: 00, 04, 13, 18, 23, 28, 32, 37, 45, 54, 59, 63, 68, 73, 78, 81, 87, 90, 91, 96 | M9: TRƯỢT ❌ | N9: TRƯỢT KHUNG ❌ | O9: 00, 04, 05, 09, 13, 14, 18, 19, 23, 28, 31, 32, 36, 37, 40, 41, 45, 46, 50, 54, 55, 59, 63, 64, 68, 69, 73, 78, 81, 82, 86, 87, 90, 91, 95, 96
A10: 282 | B10: Thứ Tư ngày 14-10-2026 | C10: Thứ Ba | D10: 28259 | E10: 59 | F10: G7.3, G7.1 | G10: Tổng 0, Tổng 2, Tổng 3, Tổng 5, Tổng 7, Tổng 8 | H10: 0123456789 | I10: Tổng 8-Bóng 3 | J10: 60 | K10: TRƯỢT ❌ | L10: 08, 12, 17, 21, 23, 32, 35, 37, 39, 44, 52, 53, 61, 66, 67, 73, 78, 87, 96, 99 | M10: TRƯỢT ❌ | N10: TRÚNG N2 🎯 | O10: 00, 02, 03, 05, 07, 08, 11, 12, 14, 16, 17, 19, 20, 21, 23, 25, 26, 28, 30, 32, 34, 35, 37, 39, 41, 43, 44, 46, 48, 49, 50, 52, 53, 55, 57, 58, 61, 62, 64, 66, 67, 69, 70, 71, 73, 75, 76, 78, 80, 82, 84, 85, 87, 89, 91, 93, 94, 96, 98, 99
A11: 281 | B11: Thứ Ba ngày 13-10-2026 | C11: Thứ Hai | D11: 53618 | E11: 18 | F11: G7.4, G7.2 | G11: Tổng 2, Tổng 4, Tổng 7, Tổng 9 | H11: 0123456789 | I11: Tổng 9-Bóng 4 | J11: 40 | K11: TRÚNG N1 🎯 | L11: 04, 11, 13, 16, 18, 22, 34, 39, 43, 45, 52, 54, 61, 63, 66, 68, 70, 72, 81, 90 | M11: TRÚNG HỎA LỰC 🎯 | N11: TRÚNG N1 🎯 | O11: 02, 04, 07, 09, 11, 13, 16, 18, 20, 22, 25, 27, 31, 34, 36, 39, 40, 43, 45, 48, 52, 54, 57, 59, 61, 63, 66, 68, 70, 72, 75, 77, 81, 84, 86, 89, 90, 93, 95, 98
A12: 280 | B12: Thứ Hai ngày 12-10-2026 | C12: Chủ Nhật | D12: 38287 | E12: 87 | F12: G7.3, G7.1 | G12: Tổng 1, Tổng 3, Tổng 6, Tổng 8 | H12: 01345689 | I12: Tổng 6-Bóng 1 | J12: 40 | K12: TRƯỢT ❌ | L12: 06, 08, 12, 15, 17, 21, 29, 35, 38, 42, 44, 51, 53, 60, 65, 67, 80, 83, 88, 99 | M12: TRƯỢT ❌ | N12: TRƯỢT KHUNG ❌ | O12: 01, 03, 06, 08, 10, 12, 15, 17, 21, 24, 26, 29, 30, 33, 35, 38, 42, 44, 47, 49, 51, 53, 56, 58, 60, 62, 65, 67, 71, 74, 76, 79, 80, 83, 85, 88, 92, 94, 97, 99
A13: 279 | B13: Chủ Nhật ngày 11-10-2026 | C13: Thứ Bảy | D13: 07363 | E13: 63 | F13: G7.1, G7.3 | G13: Tổng 1, Tổng 3, Tổng 4, Tổng 6, Tổng 8, Tổng 9 | H13: 0123456789 | I13: Tổng 6-Bóng 1 | J13: 60 | K13: TRÚNG N1 🎯 | L13: 06, 08, 12, 15, 22, 29, 35, 38, 42, 44, 51, 53, 54, 60, 65, 67, 83, 88, 90, 99 | M13: TRƯỢT ❌ | N13: TRÚNG N1 🎯 | O13: 01, 03, 04, 06, 08, 09, 10, 12, 13, 15, 17, 18, 21, 22, 24, 26, 27, 29, 30, 31, 33, 35, 36, 38, 40, 42, 44, 45, 47, 49, 51, 53, 54, 56, 58, 59, 60, 62, 63, 65, 67, 68, 71, 72, 74, 76, 77, 79, 80, 81, 83, 85, 86, 88, 90, 92, 94, 95, 97, 99
A14: 278 | B14: Thứ Bảy ngày 10-10-2026 | C14: Thứ Sáu | D14: 82153 | E14: 53 | F14: G7.1, G7.4 | G14: Tổng 2, Tổng 3, Tổng 4, Tổng 7, Tổng 8, Tổng 9 | H14: 01235678 | I14: Tổng 3-Bóng 8 | J14: 56 | K14: TRÚNG N1 🎯 | L14: 04, 08, 12, 13, 17, 18, 21, 22, 26, 35, 39, 43, 52, 54, 61, 66, 67, 68, 81, 90 | M14: TRƯỢT ❌ | N14: TRÚNG N1 🎯 | O14: 02, 03, 04, 07, 08, 09, 11, 12, 13, 16, 17, 18, 20, 21, 22, 25, 26, 27, 30, 31, 34, 35, 36, 39, 40, 43, 45, 48, 52, 53, 54, 57, 58, 59, 61, 62, 63, 66, 67, 68, 70, 71, 72, 75, 76, 77, 80, 81, 84, 85, 86, 89, 90, 93, 95, 98
... A291: 1 | B291: Thứ sáu ngày 02-01-2026 | C291: Thứ Năm | D291: 45748 | E291: 48 | F291: G7.1, G7.2 | G291: Tổng 0, Tổng 1, Tổng 2, Tổng 5, Tổng 6, Tổng 7 | H291: 01245679 | I291: Tổng 6-Bóng 1 | J291: 56 | K291: TRÚNG N1 🎯 | L291: 01, 05, 06, 07, 15, 16, 28, 39, 42, 46, 51, 52, 56, 60, 64, 78, 82, 93, 96, 97 | M291: TRƯỢT ❌ | N291: TRÚNG N1 🎯 | O291: 00, 01, 02, 05, 06, 07, 10, 11, 14, 15, 16, 19, 20, 23, 24, 25, 28, 29, 32, 34, 37, 39, 41, 42, 43, 46, 47, 48, 50, 51, 52, 55, 56, 57, 60, 61, 64, 65, 66, 69, 70, 73, 74, 75, 78, 79, 82, 84, 87, 89, 91, 92, 93, 96, 97, 98

Sheet Phan_Tich_Cau_Ghep_Goc
A1: Thành Phần Cầu Ghép Góc | B1: Thuật Toán & Cách Tính | C1: Số Lần Nổ N1 2026 | D1: Tỷ Lệ Trúng (%) | E1: Đánh Giá Ưu Điểm
A2: Song Thủ Lô Cầu Ghép Góc (Móc Ghép G7.1 + G7.4) | B2: Ghép G7.1[0] và G7.4[1] -> Cặp Lô 48 - 84 | C2: 108 lần (135 nháy) | D2: 37.37% | E2: Cầu Lô Móc Chung cực chuẩn, xuất hiện nháy đều đặn
A3: Cầu Ghép Góc Đề (Head 7.1 + Tail 7.4) | B3: Tổng (G7.1[0] + G7.4[1]) mod 10 & Bóng | C3: 96 lần | D3: 42.67% | E3: Độc lập với G7 đơn, nổ cực mạnh Thứ 2 (50%) & Thứ 7 (48.5%)
A4: Tích Hợp Chạm G7 Ngày | B4: Bắt chữ số G7.1-G7.4 + Bóng dương | C4: 189 lần | D4: 84.70% | E4: Độ phủ rộng, giữ tỷ lệ trúng khung 3N 87.00%

Sheet Dan_Ha_So_Nhip_Vang
A1: Thứ Hạng Hỏa Lực | B1: Con Số 2D | C1: Thuộc Tổng | D1: Nhịp Gan (Ngày) | E1: Điểm Nhịp Vàng Gaussian | F1: Khuyến Nghị Vốn
A2: Top 01 | B2: 42 | C2: Tổng 6 | D2: 3 ngày | E2: 31.0 điểm | F2: Ưu tiên hỏa lực chính
A3: Top 02 | B3: 38 | C3: Tổng 1 | D3: 4 ngày | E3: 28.5 điểm | F3: Ưu tiên hỏa lực chính
A4: Top 03 | B4: 66 | C4: Tổng 2 | D4: 6 ngày | E4: 24.5 điểm | F4: Ưu tiên hỏa lực chính
A5: Top 04 | B5: 51 | C5: Tổng 6 | D5: 17 ngày | E5: 22.0 điểm | F5: Ưu tiên hỏa lực chính
A6: Top 05 | B6: 56 | C6: Tổng 1 | D6: 5 ngày | E6: 21.5 điểm | F6: Ưu tiên hỏa lực chính
A7: Top 06 | B7: 61 | C7: Tổng 7 | D7: 18 ngày | E7: 15.5 điểm | F7: Dàn lót bổ trợ
A8: Top 07 | B8: 35 | C8: Tổng 8 | D8: 12 ngày | E8: 15.5 điểm | F8: Dàn lót bổ trợ
A9: Top 08 | B9: 83 | C9: Tổng 1 | D9: 19 ngày | E9: 14.5 điểm | F9: Dàn lót bổ trợ
A10: Top 09 | B10: 39 | C10: Tổng 2 | D10: 13 ngày | E10: 13.5 điểm | F10: Dàn lót bổ trợ
A11: Top 10 | B11: 08 | C11: Tổng 8 | D11: 20 ngày | E11: 12.5 điểm | F11: Dàn lót bổ trợ
A12: Top 11 | B12: 88 | C12: Tổng 6 | D12: 14 ngày | E12: 12.5 điểm | F12: Dàn lót bổ trợ
... A21: Top 20 | B21: 99 | C21: Tổng 8 | D21: 38 ngày | E21: 4.0 điểm | F21: Dàn lót bổ trợ

Sheet Thong_Ke_Nang_Cao_G7
A1: STT | B1: Ngày Quay | C1: G7.1 | D1: G7.2 | E1: G7.3 | F1: G7.4 | G1: Tập Chạm G7 | H1: Tổng/Bóng G7 | I1: Tổng/Bóng Cầu Ghép Góc | J1: Dàn Giao Thoa (Chạm x Tổng) | K1: Số Đề Hôm Sau | L1: Kết Quả Chạm G7 | M1: Kết Quả Cầu Ghép Góc | N1: Kết Quả Dàn Giao Thoa
A2: BẢNG 1 | B2: TỔNG QUAN 4 THUẬT TOÁN G7 NÂNG CAO 2026 | C2: --- | D2: --- | E2: --- | F2: --- | G2: Mô Tả & Kích Thước Dàn | H2: Số Lần Trúng | I2: Tỷ Lệ Trúng (%) | J2: Đánh Giá Khuyên Dùng | K2: --- | L2: --- | M2: --- | N2: ---
A3: TT 1 | B3: Thuật toán 1: Tổng Trực diện vs Tổng Bóng G7 | C3: G7.1-G7.4 | D3: --- | E3: --- | F3: --- | G3: 20 con / vị trí G7 (G7.3 Top 1) | H3: 45 / 222 lần (G7.3) | I3: 20.3% | J3: Bóng (42.3%) áp đảo Trực diện (26.1%). Ưu tiên G7.3 & G7.2 | K3: --- | L3: --- | M3: --- | N3: ---
A4: TT 2 | B4: Thuật toán 2: Màng Lọc Chạm G7 (Độ Phủ Cao) | C4: G7.1-G7.4 | D4: --- | E4: --- | F4: --- | G4: ~50-60 con (6-7 chữ số chạm) | H4: 244 / 289 ngày | I4: 84.4% | J4: Độ phủ 84.7%. Màng lọc bắt buộc để hạ dàn nguyên liệu | K4: --- | L4: --- | M4: --- | N4: ---
A5: TT 3 | B5: Thuật toán 3: Cầu Ghép Góc (Đầu G7.1 + Đuôi G7.4) | C5: G7.1[0] | D5: --- | E5: --- | F5: G7.4[1] | G5: 20 con (2 bộ Tổng/Bóng) | H5: 64 / 289 ngày | I5: 22.1% | J5: Cầu độc lập hiệu quả cao, nổ mạnh Thứ Hai & Thứ Bảy (~29%) | K5: --- | L5: --- | M5: --- | N5: ---
A6: TT 4 | B6: Thuật toán 4: Dàn Giao Thoa Ép Cầu [Chạm x Tổng] | C6: G7.1-G7.4 | D6: --- | E6: --- | F6: --- | G6: ~48 con (Giao giữa Chạm G7 & Tổng G7) | H6: 133 / 289 ngày | I6: 46.0% | J6: Ép dàn cực đỉnh (~48 con) giữ tỷ lệ ăn 42.8%, nổ 56.2% Thứ Năm | K6: --- | L6: --- | M6: --- | N6: ---
A7: BẢNG 2 | B7: NHẬT KÝ KIỂM CHỨNG TỰ ĐỘNG THỰC TẾ 2026 | C7: --- | D7: --- | E7: --- | F7: --- | G7: --- | H7: --- | I7: --- | J7: --- | K7: --- | L7: --- | M7: --- | N7: --- | O7: --- | P7: --- | Q7: ---
A8: 1 | B8: Thứ năm ngày 01-01-2026 (Thứ Năm) | C8: 91 | D8: 25 | E8: 69 | F8: 67 | G8: 125679 | H8: T0, T2, T3, T5, T7, T8 | I8: T6-B1 | J8: 50 con | K8: 48 | L8: KHÔNG | M8: KHÔNG | N8: KHÔNG | O8: 97 - 79 | P8: 0 nháy | Q8: 10 nháy
A9: 2 | B9: Thứ sáu ngày 02-01-2026 (Thứ Sáu) | C9: 29 | D9: 24 | E9: 38 | F9: 22 | G9: 23489 | H9: T1, T4, T6, T9 | I9: T4-B9 | J9: 31 con | K9: 49 | L9: TRÚNG | M9: KHÔNG | N9: KHÔNG | O9: 22 | P9: 0 nháy | Q9: 8 nháy
A10: 3 | B10: Thứ bảy ngày 03-01-2026 (Thứ Bảy) | C10: 46 | D10: 33 | E10: 92 | F10: 48 | G10: 234689 | H10: T0, T1, T2, T5, T6, T7 | I10: T2-B7 | J10: 47 con | K10: 97 | L10: TRÚNG | M10: KHÔNG | N10: TRÚNG | O10: 48 - 84 | P10: 2 nháy 🎯 | Q10: 13 nháy
A11: 4 | B11: Chủ nhật ngày 04-01-2026 (Chủ Nhật) | C11: 68 | D11: 34 | E11: 77 | F11: 25 | G11: 2345678 | H11: T2, T4, T7, T9 | I11: T1-B6 | J11: 37 con | K11: 05 | L11: TRÚNG | M11: KHÔNG | N11: KHÔNG | O11: 65 - 56 | P11: 1 nháy 🎯 | Q11: 11 nháy
A12: 5 | B12: Thứ hai ngày 05-01-2026 (Thứ Hai) | C12: 47 | D12: 43 | E12: 65 | F12: 27 | G12: 234567 | H12: T1, T2, T4, T6, T7, T9 | I12: T1-B6 | J12: 50 con | K12: 47 | L12: TRÚNG | M12: TRÚNG | N12: TRÚNG | O12: 47 - 74 | P12: 1 nháy 🎯 | Q12: 13 nháy
A13: 6 | B13: Thứ ba ngày 06-01-2026 (Thứ Ba) | C13: 50 | D13: 10 | E13: 65 | F13: 12 | G13: 01256 | H13: T0, T1, T3, T5, T6, T8 | I13: T7-B2 | J13: 44 con | K13: 89 | L13: KHÔNG | M13: TRÚNG | N13: KHÔNG | O13: 52 - 25 | P13: 0 nháy | Q13: 11 nháy
A14: 7 | B14: Thứ tư ngày 07-01-2026 (Thứ Tư) | C14: 39 | D14: 64 | E14: 24 | F14: 57 | G14: 2345679 | H14: T0, T1, T2, T5, T6, T7 | I14: T0-B5 | J14: 55 con | K14: 62 | L14: TRÚNG | M14: KHÔNG | N14: KHÔNG | O14: 37 - 73 | P14: 1 nháy 🎯 | Q14: 11 nháy
A15: 8 | B15: Thứ năm ngày 08-01-2026 (Thứ Năm) | C15: 54 | D15: 88 | E15: 82 | F15: 13 | G15: 123458 | H15: T0, T1, T4, T5, T6, T9 | I15: T8-B3 | J15: 50 con | K15: 23 | L15: TRÚNG | M15: KHÔNG | N15: TRÚNG | O15: 53 - 35 | P15: 0 nháy | Q15: 14 nháy
A16: 9 | B16: Thứ sáu ngày 09-01-2026 (Thứ Sáu) | C16: 47 | D16: 87 | E16: 52 | F16: 46 | G16: 245678 | H16: T0, T1, T2, T5, T6, T7 | I16: T0-B5 | J16: 51 con | K16: 93 | L16: KHÔNG | M16: KHÔNG | N16: KHÔNG | O16: 46 - 64 | P16: 0 nháy | Q16: 11 nháy
A17: 10 | B17: Thứ bảy ngày 10-01-2026 (Thứ Bảy) | C17: 70 | D17: 45 | E17: 14 | F17: 13 | G17: 013457 | H17: T0, T2, T4, T5, T7, T9 | I17: T0-B5 | J17: 50 con | K17: 38 | L17: TRÚNG | M17: KHÔNG | N17: KHÔNG | O17: 73 - 37 | P17: 1 nháy 🎯 | Q17: 14 nháy
A18: 11 | B18: Chủ nhật ngày 11-01-2026 (Chủ Nhật) | C18: 70 | D18: 95 | E18: 10 | F18: 43 | G18: 0134579 | H18: T1, T2, T4, T6, T7, T9 | I18: T0-B5 | J18: 55 con | K18: 94 | L18: TRÚNG | M18: KHÔNG | N18: KHÔNG | O18: 73 - 37 | P18: 1 nháy 🎯 | Q18: 18 nháy
A19: 12 | B19: Thứ hai ngày 12-01-2026 (Thứ Hai) | C19: 31 | D19: 34 | E19: 20 | F19: 42 | G19: 01234 | H19: T1, T2, T4, T6, T7, T9 | I19: T5-B0 | J19: 45 con | K19: 27 | L19: TRÚNG | M19: KHÔNG | N19: TRÚNG | O19: 32 - 23 | P19: 0 nháy | Q19: 12 nháy
... A296: 289 | B296: Thứ Ba ngày 20-10-2026 (Thứ Ba) | C296: 77 | D296: 90 | E296: 06 | F296: 32 | G296: 023679 | H296: T0, T1, T4, T5, T6, T9 | I296: T9-B4 | J296: 50 con | K296: 63 | L296: TRÚNG | M296: TRÚNG | N296: TRÚNG | O296: 72 - 27 | P296: 1 nháy 🎯 | Q296: 13 nháy

Sheet Lich_Su_Truc_Tiep_2026
A1: STT | B1: Ngày Quay | C1: Giải Đặc Biệt | D1: Số Đề (2 số) | E1: Đầu Đề | F1: Đuôi Đề | G1: Dàn Số Dự Đoán (G7 Top 1-3) | H1: Kết Quả Dự Đoán
A2: TỔNG KẾT 2026 | B2: Tổng: 289 Ngày | C2: Trúng K1: 138 Ngày (47.75%) | D2: Trúng K2: 220 Ngày (72.5%) | E2: Trúng K3: 273 Ngày (87.5%) | G2: Dàn 40 Con Số Từ G7 Top 1-3 Ngày Trước
A3: 1 | B3: Thứ năm ngày 01-01-2026 | C3: 45748 | D3: 48 | E3: Đầu 4 | F3: Đuôi 8 | G3: 00, 02, 05, 07, 11, 14, 16, 19, 20, 23, 25, 28, 32, 34, 37, 39, 41, 43, 46, 48, 50, 52, 55, 57, 61, 64, 66, 69, 70, 73, 75, 78, 82, 84, 87, 89, 91, 93, 96, 98 | H3: TRÚNG 🎯
A4: 2 | B4: Thứ sáu ngày 02-01-2026 | C4: 00949 | D4: 49 | E4: Đầu 4 | F4: Đuôi 9 | G4: 01, 06, 10, 15, 24, 29, 33, 38, 42, 47, 51, 56, 60, 65, 74, 79, 83, 88, 92, 97 | H4: TRƯỢT ❌
A5: 3 | B5: Thứ bảy ngày 03-01-2026 | C5: 72397 | D5: 97 | E5: Đầu 9 | F5: Đuôi 7 | G5: 00, 01, 05, 06, 10, 14, 15, 19, 23, 24, 28, 29, 32, 33, 37, 38, 41, 42, 46, 47, 50, 51, 55, 56, 60, 64, 65, 69, 73, 74, 78, 79, 82, 83, 87, 88, 91, 92, 96, 97 | H5: TRÚNG 🎯
A6: 4 | B6: Chủ nhật ngày 04-01-2026 | C6: 70505 | D6: 05 | E6: Đầu 0 | F6: Đuôi 5 | G6: 02, 04, 07, 09, 11, 13, 16, 18, 20, 22, 25, 27, 31, 34, 36, 39, 40, 43, 45, 48, 52, 54, 57, 59, 61, 63, 66, 68, 70, 72, 75, 77, 81, 84, 86, 89, 90, 93, 95, 98 | H6: TRƯỢT ❌
A7: 5 | B7: Thứ hai ngày 05-01-2026 | C7: 78447 | D7: 47 | E7: Đầu 4 | F7: Đuôi 7 | G7: 01, 02, 06, 07, 10, 11, 15, 16, 20, 24, 25, 29, 33, 34, 38, 39, 42, 43, 47, 48, 51, 52, 56, 57, 60, 61, 65, 66, 70, 74, 75, 79, 83, 84, 88, 89, 92, 93, 97, 98 | H7: TRÚNG 🎯
A8: 6 | B8: Thứ ba ngày 06-01-2026 | C8: 14389 | D8: 89 | E8: Đầu 8 | F8: Đuôi 9 | G8: 00, 01, 05, 06, 10, 14, 15, 19, 23, 24, 28, 29, 32, 33, 37, 38, 41, 42, 46, 47, 50, 51, 55, 56, 60, 64, 65, 69, 73, 74, 78, 79, 82, 83, 87, 88, 91, 92, 96, 97 | H8: TRƯỢT ❌
A9: 7 | B9: Thứ tư ngày 07-01-2026 | C9: 40162 | D9: 62 | E9: Đầu 6 | F9: Đuôi 2 | G9: 00, 01, 02, 05, 06, 07, 10, 11, 14, 15, 16, 19, 20, 23, 24, 25, 28, 29, 32, 33, 34, 37, 38, 39, 41, 42, 43, 46, 47, 48, 50, 51, 52, 55, 56, 57, 60, 61, 64, 65, 66, 69, 70, 73, 74, 75, 78, 79, 82, 83, 84, 87, 88, 89, 91, 92, 93, 96, 97, 98 | H9: TRƯỢT ❌
A10: 8 | B10: Thứ năm ngày 08-01-2026 | C10: 39523 | D10: 23 | E10: Đầu 2 | F10: Đuôi 3 | G10: 00, 01, 04, 05, 06, 09, 10, 13, 14, 15, 18, 19, 22, 23, 24, 27, 28, 29, 31, 32, 33, 36, 37, 38, 40, 41, 42, 45, 46, 47, 50, 51, 54, 55, 56, 59, 60, 63, 64, 65, 68, 69, 72, 73, 74, 77, 78, 79, 81, 82, 83, 86, 87, 88, 90, 91, 92, 95, 96, 97 | H10: TRÚNG 🎯
A11: 9 | B11: Thứ sáu ngày 09-01-2026 | C11: 67793 | D11: 93 | E11: Đầu 9 | F11: Đuôi 3 | G11: 00, 01, 02, 05, 06, 07, 10, 11, 14, 15, 16, 19, 20, 23, 24, 25, 28, 29, 32, 33, 34, 37, 38, 39, 41, 42, 43, 46, 47, 48, 50, 51, 52, 55, 56, 57, 60, 61, 64, 65, 66, 69, 70, 73, 74, 75, 78, 79, 82, 83, 84, 87, 88, 89, 91, 92, 93, 96, 97, 98 | H11: TRÚNG 🎯
A12: 10 | B12: Thứ bảy ngày 10-01-2026 | C12: 82438 | D12: 38 | E12: Đầu 3 | F12: Đuôi 8 | G12: 00, 02, 04, 05, 07, 09, 11, 13, 14, 16, 18, 19, 20, 22, 23, 25, 27, 28, 31, 32, 34, 36, 37, 39, 40, 41, 43, 45, 46, 48, 50, 52, 54, 55, 57, 59, 61, 63, 64, 66, 68, 69, 70, 72, 73, 75, 77, 78, 81, 82, 84, 86, 87, 89, 90, 91, 93, 95, 96, 98 | H12: TRƯỢT ❌
A13: 11 | B13: Chủ nhật ngày 11-01-2026 | C13: 31894 | D13: 94 | E13: Đầu 9 | F13: Đuôi 4 | G13: 01, 02, 04, 06, 07, 09, 10, 11, 13, 15, 16, 18, 20, 22, 24, 25, 27, 29, 31, 33, 34, 36, 38, 39, 40, 42, 43, 45, 47, 48, 51, 52, 54, 56, 57, 59, 60, 61, 63, 65, 66, 68, 70, 72, 74, 75, 77, 79, 81, 83, 84, 86, 88, 89, 90, 92, 93, 95, 97, 98 | H13: TRƯỢT ❌
A14: 12 | B14: Thứ hai ngày 12-01-2026 | C14: 28027 | D14: 27 | E14: Đầu 2 | F14: Đuôi 7 | G14: 02, 04, 07, 09, 11, 13, 16, 18, 20, 22, 25, 27, 31, 34, 36, 39, 40, 43, 45, 48, 52, 54, 57, 59, 61, 63, 66, 68, 70, 72, 75, 77, 81, 84, 86, 89, 90, 93, 95, 98 | H14: TRÚNG 🎯
... A291: 289 | B291: Thứ Ba ngày 20-10-2026 | C291: 94163 | D291: 63 | E291: Đầu 6 | F291: Đuôi 3 | G291: 01, 04, 06, 09, 10, 13, 15, 18, 22, 24, 27, 29, 31, 33, 36, 38, 40, 42, 45, 47, 51, 54, 56, 59, 60, 63, 65, 68, 72, 74, 77, 79, 81, 83, 86, 88, 90, 92, 95, 97 | H291: TRÚNG 🎯

Sheet Thong_Ke_Dau_Duoi
A1: Hạng Mục Báo Cáo | B1: Chi Tiết Kế Thừa & Dự Đoán
A2: --- DỰ ĐOÁN ĐẦU / ĐUÔI VÀ DÀN SỐ CHO NGÀY TỚI ---
A3: Top 3 Đầu Tiềm Năng | B3: Đầu 5, Đầu 3, Đầu 8
A4: Top 3 Đuôi Tiềm Năng | B4: Đuôi 6, Đuôi 8, Đuôi 5
A5: Dàn 20 Con Số Dự Đoán Đồng Thuận Super-Score | B5: 42, 38, 51, 83, 08, 56, 88, 35, 15, 53, 44, 06, 65, 21, 60, 67, 12, 29, 80, 99
A6: --- TẦN SUẤT ĐẦU NĂM 2026 ---
A7: Đầu 3 | B7: 37 lần
A8: Đầu 5 | B8: 37 lần
A9: Đầu 6 | B9: 35 lần
A10: Đầu 8 | B10: 32 lần
A11: Đầu 2 | B11: 30 lần
A12: Đầu 4 | B12: 29 lần
A13: Đầu 9 | B13: 25 lần
A14: Đầu 1 | B14: 25 lần
A15: Đầu 0 | B15: 21 lần
A16: Đầu 7 | B16: 19 lần
A17: --- TẦN SUẤT ĐUÔI NĂM 2026 ---
A18: Đuôi 8 | B18: 35 lần
A19: Đuôi 3 | B19: 35 lần
A20: Đuôi 4 | B20: 35 lần
A21: Đuôi 7 | B21: 32 lần
A22: Đuôi 2 | B22: 29 lần
A23: Đuôi 1 | B23: 29 lần
A24: Đuôi 9 | B24: 28 lần
A25: Đuôi 5 | B25: 24 lần
A26: Đuôi 0 | B26: 23 lần
A27: Đuôi 6 | B27: 20 lần

Sheet Thong_Ke_Top3_Dau_Duoi
A1: STT | B1: Ngày Quay | C1: Giải Đặc Biệt | D1: Số Đề 2D | E1: Đầu Thực Tế | F1: Đuôi Thực Tế | G1: Top 3 Đầu Dự Đoán | H1: Kết Quả Top 3 Đầu (1 Ngày) | I1: Top 3 Đuôi Dự Đoán | J1: Kết Quả Top 3 Đuôi (1 Ngày) | K1: Dàn 9 Số Ghép (Đầu x Đuôi) | L1: Kết Quả Dàn 9 Số (1 Ngày) | M1: Kết Quả Khung 3 Ngày (Dàn 9 Số)
A2: TOP 3 (VIP 30 SỐ) | B2: Tổng: 289 Ngày | C2: Trúng Đầu (1N): 85/289 (29.41%) | D2: Trúng Đuôi (1N): 75/289 (25.95%) | E2: Trúng Ghép 9 Số (1N): 22/289 (7.61%) | F2: Trúng Đầu/Đuôi: 138/289 (47.75%) | G2: --- | H2: Khung 3N (Đầu): 197/287 (68.64%) | I2: --- | J2: Khung 3N (Đuôi): 175/287 (60.98%) | K2: --- | L2: Khung 3N (Ghép 9 Số): 63/287 (21.95%) | M2: ---
A3: TOP 4 (HỎA LỰC 40 SỐ) | B3: Tổng: 289 Ngày | C3: Trúng Đầu (1N): 109/289 (37.72%) | D3: Trúng Đuôi (1N): 100/289 (34.6%) | E3: Trúng Ghép 16 Số (1N): 40/289 (13.84%) | F3: --- | G3: --- | H3: Khung 3N (Đầu): 77.7% | I3: --- | J3: Khung 3N (Đuôi): 74.56% | K3: --- | L3: Khung 3N (Ghép 16 Số): 36.93% | M3: ---
A4: TOP 5 (PHỦ RỘNG 50 SỐ) | B4: Tổng: 289 Ngày | C4: Trúng Đầu (1N): 138/289 (47.75%) | D4: Trúng Đuôi (1N): 126/289 (43.6%) | E4: Trúng Ghép 25 Số (1N): 58/289 (20.07%) | F4: --- | G4: --- | H4: Khung 3N (Đầu): 86.41% | I4: --- | J4: Khung 3N (Đuôi): 82.23% | K4: --- | L4: Khung 3N (Ghép 25 Số): 52.26% | M4: ---
A5: 1 | B5: Thứ năm ngày 01-01-2026 | C5: 45748 | D5: 48 | E5: Đầu 4 | F5: Đuôi 8 | G5: 0, 1, 2 | H5: TRƯỢT ❌ | I5: 0, 1, 2 | J5: TRƯỢT ❌ | K5: 00, 01, 02, 10, 11, 12, 20, 21, 22 | L5: TRƯỢT ❌ | M5: TRƯỢT KHUNG ❌
A6: 2 | B6: Thứ sáu ngày 02-01-2026 | C6: 00949 | D6: 49 | E6: Đầu 4 | F6: Đuôi 9 | G6: 6, 0, 1 | H6: TRƯỢT ❌ | I6: 8, 0, 1 | J6: TRƯỢT ❌ | K6: 00, 01, 08, 10, 11, 18, 60, 61, 68 | L6: TRƯỢT ❌ | M6: TRƯỢT KHUNG ❌
A7: 3 | B7: Thứ bảy ngày 03-01-2026 | C7: 72397 | D7: 97 | E7: Đầu 9 | F7: Đuôi 7 | G7: 6, 4, 0 | H7: TRƯỢT ❌ | I7: 8, 0, 1 | J7: TRƯỢT ❌ | K7: 00, 01, 08, 40, 41, 48, 60, 61, 68 | L7: TRƯỢT ❌ | M7: TRƯỢT KHUNG ❌
A8: 4 | B8: Chủ nhật ngày 04-01-2026 | C8: 70505 | D8: 05 | E8: Đầu 0 | F8: Đuôi 5 | G8: 6, 4, 0 | H8: TRÚNG 🎯 | I8: 8, 9, 0 | J8: TRƯỢT ❌ | K8: 00, 08, 09, 40, 48, 49, 60, 68, 69 | L8: TRƯỢT ❌ | M8: TRƯỢT KHUNG ❌
A9: 5 | B9: Thứ hai ngày 05-01-2026 | C9: 78447 | D9: 47 | E9: Đầu 4 | F9: Đuôi 7 | G9: 6, 4, 9 | H9: TRÚNG 🎯 | I9: 8, 9, 7 | J9: TRÚNG 🎯 | K9: 47, 48, 49, 67, 68, 69, 97, 98, 99 | L9: TRÚNG 🎯 | M9: TRÚNG KHUNG 🎯
A10: 6 | B10: Thứ ba ngày 06-01-2026 | C10: 14389 | D10: 89 | E10: Đầu 8 | F10: Đuôi 9 | G10: 6, 4, 9 | H10: TRƯỢT ❌ | I10: 8, 9, 7 | J10: TRÚNG 🎯 | K10: 47, 48, 49, 67, 68, 69, 97, 98, 99 | L10: TRƯỢT ❌ | M10: TRƯỢT KHUNG ❌
A11: 7 | B11: Thứ tư ngày 07-01-2026 | C11: 40162 | D11: 62 | E11: Đầu 6 | F11: Đuôi 2 | G11: 6, 4, 9 | H11: TRÚNG 🎯 | I11: 8, 7, 5 | J11: TRƯỢT ❌ | K11: 45, 47, 48, 65, 67, 68, 95, 97, 98 | L11: TRƯỢT ❌ | M11: TRƯỢT KHUNG ❌
A12: 8 | B12: Thứ năm ngày 08-01-2026 | C12: 39523 | D12: 23 | E12: Đầu 2 | F12: Đuôi 3 | G12: 4, 9, 0 | H12: TRƯỢT ❌ | I12: 8, 7, 5 | J12: TRƯỢT ❌ | K12: 05, 07, 08, 45, 47, 48, 95, 97, 98 | L12: TRƯỢT ❌ | M12: TRƯỢT KHUNG ❌
A13: 9 | B13: Thứ sáu ngày 09-01-2026 | C13: 67793 | D13: 93 | E13: Đầu 9 | F13: Đuôi 3 | G13: 4, 0, 9 | H13: TRÚNG 🎯 | I13: 8, 5, 7 | J13: TRƯỢT ❌ | K13: 05, 07, 08, 45, 47, 48, 95, 97, 98 | L13: TRƯỢT ❌ | M13: TRƯỢT KHUNG ❌
A14: 10 | B14: Thứ bảy ngày 10-01-2026 | C14: 82438 | D14: 38 | E14: Đầu 3 | F14: Đuôi 8 | G14: 4, 0, 6 | H14: TRƯỢT ❌ | I14: 7, 8, 5 | J14: TRÚNG 🎯 | K14: 05, 07, 08, 45, 47, 48, 65, 67, 68 | L14: TRƯỢT ❌ | M14: TRƯỢT KHUNG ❌
A15: 11 | B15: Chủ nhật ngày 11-01-2026 | C15: 31894 | D15: 94 | E15: Đầu 9 | F15: Đuôi 4 | G15: 4, 0, 8 | H15: TRƯỢT ❌ | I15: 7, 9, 5 | J15: TRƯỢT ❌ | K15: 05, 07, 09, 45, 47, 49, 85, 87, 89 | L15: TRƯỢT ❌ | M15: TRƯỢT KHUNG ❌
A16: 12 | B16: Thứ hai ngày 12-01-2026 | C16: 28027 | D16: 27 | E16: Đầu 2 | F16: Đuôi 7 | G16: 4, 6, 0 | H16: TRƯỢT ❌ | I16: 7, 9, 2 | J16: TRÚNG 🎯 | K16: 02, 07, 09, 42, 47, 49, 62, 67, 69 | L16: TRƯỢT ❌ | M16: TRƯỢT KHUNG ❌
... A293: 289 | B293: Thứ Ba ngày 20-10-2026 | C293: 94163 | D293: 63 | E293: Đầu 6 | F293: Đuôi 3 | G293: 5, 6, 3 | H293: TRÚNG 🎯 | I293: 6, 3, 2 | J293: TRÚNG 🎯 | K293: 32, 33, 36, 52, 53, 56, 62, 63, 66 | L293: TRÚNG 🎯 | M293: TRƯỢT KHUNG ❌
A294: BẢNG PHÂN TÍCH CHUYÊN SÂU | B294: TỪNG ĐẦU DỰ ĐOÁN (0-9) | C294: Số Lần Dự Đoán | D294: Số Lần TRÚNG Thực Tế | E294: Tỷ Lệ Trúng % | F294: --- | G294: --- | H294: --- | I294: --- | J294: --- | K294: --- | L294: --- | M294: ---
A295: ĐẦU CHI TIẾT | B295: Đầu 0 | C295: 56 lần | D295: 2 lần | E295: 3.57%
A296: ĐẦU CHI TIẾT | B296: Đầu 1 | C296: 73 lần | D296: 7 lần | E296: 9.59%
A297: ĐẦU CHI TIẾT | B297: Đầu 2 | C297: 97 lần | D297: 9 lần | E297: 9.28%
A298: ĐẦU CHI TIẾT | B298: Đầu 3 | C298: 120 lần | D298: 15 lần | E298: 12.5%
A299: ĐẦU CHI TIẾT | B299: Đầu 4 | C299: 92 lần | D299: 6 lần | E299: 6.52%
A300: ĐẦU CHI TIẾT | B300: Đầu 5 | C300: 104 lần | D300: 13 lần | E300: 12.5%
A301: ĐẦU CHI TIẾT | B301: Đầu 6 | C301: 118 lần | D301: 12 lần | E301: 10.17%
A302: ĐẦU CHI TIẾT | B302: Đầu 7 | C302: 38 lần | D302: 2 lần | E302: 5.26%
A303: ĐẦU CHI TIẾT | B303: Đầu 8 | C303: 103 lần | D303: 12 lần | E303: 11.65%
A304: ĐẦU CHI TIẾT | B304: Đầu 9 | C304: 66 lần | D304: 7 lần | E304: 10.61%
A305: BẢNG PHÂN TÍCH CHUYÊN SÂU | B305: TỪNG ĐUÔI DỰ ĐOÁN (0-9) | C305: Số Lần Dự Đoán | D305: Số Lần TRÚNG Thực Tế | E305: Tỷ Lệ Trúng % | F305: --- | G305: --- | H305: --- | I305: --- | J305: --- | K305: --- | L305: --- | M305: ---
A306: ĐUÔI CHI TIẾT | B306: Đuôi 0 | C306: 50 lần | D306: 3 lần | E306: 6.0%
A307: ĐUÔI CHI TIẾT | B307: Đuôi 1 | C307: 94 lần | D307: 8 lần | E307: 8.51%
A308: ĐUÔI CHI TIẾT | B308: Đuôi 2 | C308: 89 lần | D308: 8 lần | E308: 8.99%
A309: ĐUÔI CHI TIẾT | B309: Đuôi 3 | C309: 110 lần | D309: 9 lần | E309: 8.18%
A310: ĐUÔI CHI TIẾT | B310: Đuôi 4 | C310: 121 lần | D310: 12 lần | E310: 9.92%
A311: ĐUÔI CHI TIẾT | B311: Đuôi 5 | C311: 70 lần | D311: 4 lần | E311: 5.71%
A312: ĐUÔI CHI TIẾT | B312: Đuôi 6 | C312: 29 lần | D312: 0 lần | E312: 0.0%
A313: ĐUÔI CHI TIẾT | B313: Đuôi 7 | C313: 111 lần | D313: 13 lần | E313: 11.71%
A314: ĐUÔI CHI TIẾT | B314: Đuôi 8 | C314: 119 lần | D314: 11 lần | E314: 9.24%
A315: ĐUÔI CHI TIẾT | B315: Đuôi 9 | C315: 74 lần | D315: 7 lần | E315: 9.46%

Sheet Lich_Su_Nuoi_Khung_3Ngay
A1: STT | B1: Ngày Bắt Đầu Khung | C1: N1 (Gốc 60 số) | D1: N2 (Siêu Lọc 28 số) | E1: N3 (Siêu Lọc 28 số) | F1: Tỷ Lệ Trúng N2/N3 (Khi N1 Trượt) | G1: Song Thủ Lô Rơi (N2/N3) | H1: Kết Quả Khung 3 Ngày | I1: Dàn N1 (60 Số) | J1: Dàn Siêu Lọc N2 (28 Số) | K1: Dàn Siêu Lọc N3 (28 Số)
A2: TỔNG KẾT KHUNG 3 NGÀY | B2: Tổng Khung: 287 Khung | C2: Trúng N1: 136 Khung | D2: Trúng N2: 40 Khung | E2: Trúng N3: 28 Khung | F2: Trúng N2/N3 Siêu Lọc: 68 Khung (45.03%) | G2: Trúng STL Rơi: 20 Khung (6.97%) | H2: TỔNG TRÚNG: 204 Khung (71.08%) | I2: --- | J2: --- | K2: ---
A3: 1 | B3: Thứ năm ngày 01-01-2026 | C3: 48 (Trúng) | D3: 49 (Không) | E3: 97 (Không) | F3: --- | G3: 25, 69 (TRƯỢT ❌) | H3: TRÚNG N1 🎯 | I3: 00, 02, 05, 07, 11, 14, 16, 19, 20, 23, 25, 28, 32, 34, 37, 39, 41, 43, 46, 48, 50, 52, 55, 57, 61, 64, 66, 69, 70, 73, 75, 78, 82, 84, 87, 89, 91, 93, 96, 98 (40 số) | J3: 50, 52, 55, 57, 61, 64, 66, 69, 70, 73, 75, 78, 82, 84, 87, 89, 91, 93, 96, 98 (20 số) | K3: 50, 52, 55, 57, 61, 64, 66, 69, 70, 73, 75, 78, 82, 84, 87, 89, 91, 93, 96, 98 (20 số)
A4: 2 | B4: Thứ sáu ngày 02-01-2026 | C4: 49 (Không) | D4: 97 (Trúng) | E4: 05 (Không) | F4: --- | G4: 24, 29 (TRƯỢT ❌) | H4: TRÚNG N2 (Siêu Lọc 🎯) | I4: 01, 06, 10, 15, 24, 29, 33, 38, 42, 47, 51, 56, 60, 65, 74, 79, 83, 88, 92, 97 (20 số) | J4: 51, 56, 60, 65, 74, 79, 83, 88, 92, 97 (10 số) | K4: 51, 56, 60, 65, 74, 79, 83, 88, 92, 97 (10 số)
A5: 3 | B5: Thứ bảy ngày 03-01-2026 | C5: 97 (Trúng) | D5: 05 (Trúng) | E5: 47 (Trúng) | F5: --- | G5: 33, 46 (TRƯỢT ❌) | H5: TRÚNG N1 🎯 | I5: 00, 01, 05, 06, 10, 14, 15, 19, 23, 24, 28, 29, 32, 33, 37, 38, 41, 42, 46, 47, 50, 51, 55, 56, 60, 64, 65, 69, 73, 74, 78, 79, 82, 83, 87, 88, 91, 92, 96, 97 (40 số) | J5: 00, 01, 05, 06, 10, 14, 15, 19, 23, 24, 28, 29, 32, 33, 37, 38, 41, 42, 46, 47 (20 số) | K5: 00, 01, 05, 06, 10, 14, 15, 19, 23, 24, 28, 29, 32, 33, 37, 38, 41, 42, 46, 47 (20 số)
A6: 4 | B6: Chủ nhật ngày 04-01-2026 | C6: 05 (Không) | D6: 47 (Không) | E6: 89 (Trúng) | F6: --- | G6: 25, 34 (TRƯỢT ❌) | H6: TRÚNG N3 (Siêu Lọc 🎯) | I6: 02, 04, 07, 09, 11, 13, 16, 18, 20, 22, 25, 27, 31, 34, 36, 39, 40, 43, 45, 48, 52, 54, 57, 59, 61, 63, 66, 68, 70, 72, 75, 77, 81, 84, 86, 89, 90, 93, 95, 98 (40 số) | J6: 52, 54, 57, 59, 61, 63, 66, 68, 70, 72, 75, 77, 81, 84, 86, 89, 90, 93, 95, 98 (20 số) | K6: 52, 54, 57, 59, 61, 63, 66, 68, 70, 72, 75, 77, 81, 84, 86, 89, 90, 93, 95, 98 (20 số)
A7: 5 | B7: Thứ hai ngày 05-01-2026 | C7: 47 (Trúng) | D7: 89 (Trúng) | E7: 62 (Không) | F7: --- | G7: 43, 47 (TRÚNG 🎯) | H7: TRÚNG N1 🎯 | I7: 01, 02, 06, 07, 10, 11, 15, 16, 20, 24, 25, 29, 33, 34, 38, 39, 42, 43, 47, 48, 51, 52, 56, 57, 60, 61, 65, 66, 70, 74, 75, 79, 83, 84, 88, 89, 92, 93, 97, 98 (40 số) | J7: 51, 52, 56, 57, 60, 61, 65, 66, 70, 74, 75, 79, 83, 84, 88, 89, 92, 93, 97, 98 (20 số) | K7: 51, 52, 56, 57, 60, 61, 65, 66, 70, 74, 75, 79, 83, 84, 88, 89, 92, 93, 97, 98 (20 số)
A8: 6 | B8: Thứ ba ngày 06-01-2026 | C8: 89 (Không) | D8: 62 (Không) | E8: 23 (Trúng) | F8: --- | G8: 10, 47 (TRƯỢT ❌) | H8: TRÚNG N3 (Siêu Lọc 🎯) | I8: 00, 01, 05, 06, 10, 14, 15, 19, 23, 24, 28, 29, 32, 33, 37, 38, 41, 42, 46, 47, 50, 51, 55, 56, 60, 64, 65, 69, 73, 74, 78, 79, 82, 83, 87, 88, 91, 92, 96, 97 (40 số) | J8: 00, 01, 05, 06, 10, 14, 15, 19, 23, 24, 28, 29, 32, 33, 37, 38, 41, 42, 46, 47 (20 số) | K8: 00, 01, 05, 06, 10, 14, 15, 19, 23, 24, 28, 29, 32, 33, 37, 38, 41, 42, 46, 47 (20 số)
A9: 7 | B9: Thứ tư ngày 07-01-2026 | C9: 62 (Không) | D9: 23 (Trúng) | E9: 93 (Không) | F9: --- | G9: 24, 39 (TRƯỢT ❌) | H9: TRÚNG N2 (Siêu Lọc 🎯) | I9: 00, 01, 02, 05, 06, 07, 10, 11, 14, 15, 16, 19, 20, 23, 24, 25, 28, 29, 32, 33, 34, 37, 38, 39, 41, 42, 43, 46, 47, 48, 50, 51, 52, 55, 56, 57, 60, 61, 64, 65, 66, 69, 70, 73, 74, 75, 78, 79, 82, 83, 84, 87, 88, 89, 91, 92, 93, 96, 97, 98 (60 số) | J9: 01, 02, 05, 06, 07, 10, 11, 14, 15, 19, 20, 23, 24, 25, 28, 29, 32, 33, 34, 37, 38, 39, 41, 42, 43, 46, 47, 48 (28 số) | K9: 01, 02, 05, 06, 07, 10, 11, 14, 15, 19, 20, 23, 24, 25, 28, 29, 32, 33, 34, 37, 38, 39, 41, 42, 43, 46, 47, 48 (28 số)
A10: 8 | B10: Thứ năm ngày 08-01-2026 | C10: 23 (Trúng) | D10: 93 (Không) | E10: 38 (Không) | F10: --- | G10: 13, 54 (TRƯỢT ❌) | H10: TRÚNG N1 🎯 | I10: 00, 01, 04, 05, 06, 09, 10, 13, 14, 15, 18, 19, 22, 23, 24, 27, 28, 29, 31, 32, 33, 36, 37, 38, 40, 41, 42, 45, 46, 47, 50, 51, 54, 55, 56, 59, 60, 63, 64, 65, 68, 69, 72, 73, 74, 77, 78, 79, 81, 82, 83, 86, 87, 88, 90, 91, 92, 95, 96, 97 (60 số) | J10: 50, 51, 54, 55, 56, 59, 60, 63, 64, 65, 68, 69, 72, 73, 74, 77, 78, 79, 81, 82, 83, 86, 87, 88, 90, 92, 95, 97 (28 số) | K10: 50, 51, 54, 55, 56, 59, 60, 63, 64, 65, 68, 69, 72, 73, 74, 77, 78, 79, 81, 82, 83, 86, 87, 88, 90, 92, 95, 97 (28 số)
A11: 9 | B11: Thứ sáu ngày 09-01-2026 | C11: 93 (Trúng) | D11: 38 (Trúng) | E11: 94 (Không) | F11: --- | G11: 23, 46 (TRƯỢT ❌) | H11: TRÚNG N1 🎯 | I11: 00, 01, 02, 05, 06, 07, 10, 11, 14, 15, 16, 19, 20, 23, 24, 25, 28, 29, 32, 33, 34, 37, 38, 39, 41, 42, 43, 46, 47, 48, 50, 51, 52, 55, 56, 57, 60, 61, 64, 65, 66, 69, 70, 73, 74, 75, 78, 79, 82, 83, 84, 87, 88, 89, 91, 92, 93, 96, 97, 98 (60 số) | J11: 01, 02, 05, 06, 07, 10, 11, 14, 15, 19, 20, 23, 24, 25, 28, 29, 32, 33, 34, 37, 38, 39, 41, 42, 43, 46, 47, 48 (28 số) | K11: 01, 02, 05, 06, 07, 10, 11, 14, 15, 19, 20, 23, 24, 25, 28, 29, 32, 33, 34, 37, 38, 39, 41, 42, 43, 46, 47, 48 (28 số)
A12: 10 | B12: Thứ bảy ngày 10-01-2026 | C12: 38 (Không) | D12: 94 (Không) | E12: 27 (Không) | F12: --- | G12: 13, 14 (TRƯỢT ❌) | H12: TRƯỢT KHUNG ❌ | I12: 00, 02, 04, 05, 07, 09, 11, 13, 14, 16, 18, 19, 20, 22, 23, 25, 27, 28, 31, 32, 34, 36, 37, 39, 40, 41, 43, 45, 46, 48, 50, 52, 54, 55, 57, 59, 61, 63, 64, 66, 68, 69, 70, 72, 73, 75, 77, 78, 81, 82, 84, 86, 87, 89, 90, 91, 93, 95, 96, 98 (60 số) | J12: 50, 52, 54, 55, 57, 59, 61, 63, 64, 66, 68, 69, 72, 73, 77, 78, 81, 82, 84, 86, 87, 89, 90, 91, 93, 95, 96, 98 (28 số) | K12: 50, 52, 54, 55, 57, 59, 61, 63, 64, 66, 68, 69, 72, 73, 77, 78, 81, 82, 84, 86, 87, 89, 90, 91, 93, 95, 96, 98 (28 số)
A13: 11 | B13: Chủ nhật ngày 11-01-2026 | C13: 94 (Không) | D13: 27 (Trúng) | E13: 17 (Không) | F13: --- | G13: 10, 38 (TRƯỢT ❌) | H13: TRÚNG N2 (Siêu Lọc 🎯) | I13: 01, 02, 04, 06, 07, 09, 10, 11, 13, 15, 16, 18, 20, 22, 24, 25, 27, 29, 31, 33, 34, 36, 38, 39, 40, 42, 43, 45, 47, 48, 51, 52, 54, 56, 57, 59, 60, 61, 63, 65, 66, 68, 70, 72, 74, 75, 77, 79, 81, 83, 84, 86, 88, 89, 90, 92, 93, 95, 97, 98 (60 số) | J13: 01, 02, 04, 06, 07, 09, 10, 13, 15, 18, 20, 22, 24, 25, 27, 29, 31, 33, 34, 36, 38, 39, 40, 42, 43, 45, 47, 48 (28 số) | K13: 01, 02, 04, 06, 07, 09, 10, 13, 15, 18, 20, 22, 24, 25, 27, 29, 31, 33, 34, 36, 38, 39, 40, 42, 43, 45, 47, 48 (28 số)
A14: 12 | B14: Thứ hai ngày 12-01-2026 | C14: 27 (Trúng) | D14: 17 (Không) | E14: 22 (Không) | F14: --- | G14: 20, 31 (TRƯỢT ❌) | H14: TRÚNG N1 🎯 | I14: 02, 04, 07, 09, 11, 13, 16, 18, 20, 22, 25, 27, 31, 34, 36, 39, 40, 43, 45, 48, 52, 54, 57, 59, 61, 63, 66, 68, 70, 72, 75, 77, 81, 84, 86, 89, 90, 93, 95, 98 (40 số) | J14: 52, 54, 57, 59, 61, 63, 66, 68, 70, 72, 75, 77, 81, 84, 86, 89, 90, 93, 95, 98 (20 số) | K14: 52, 54, 57, 59, 61, 63, 66, 68, 70, 72, 75, 77, 81, 84, 86, 89, 90, 93, 95, 98 (20 số)
... A289: 287 | B289: Chủ Nhật ngày 18-10-2026 | C289: 90 (Trúng) | D289: 09 (Trúng) | E289: 63 (Không) | F289: --- | G289: 04, 44 (TRƯỢT ❌) | H289: TRÚNG N1 🎯 | I289: 03, 04, 08, 09, 12, 13, 17, 18, 21, 22, 26, 27, 30, 31, 35, 36, 40, 44, 45, 49, 53, 54, 58, 59, 62, 63, 67, 68, 71, 72, 76, 77, 80, 81, 85, 86, 90, 94, 95, 99 (40 số) | J289: 03, 04, 08, 09, 12, 13, 17, 18, 21, 22, 26, 27, 30, 31, 35, 36, 40, 44, 45, 49 (20 số) | K289: 03, 04, 08, 09, 12, 13, 17, 18, 21, 22, 26, 27, 30, 31, 35, 36, 40, 44, 45, 49 (20 số)

Sheet Top_3D_4D_Manh_Nhat
A1: Thứ Hạng | B1: Loại Số | C1: Số Dự Đoán | D1: Càng Đầu | E1: Gốc 2D / 3D | F1: Điểm Đồng Thuận | G1: Phân Loại | H1: Khuyến Nghị
A2: 🥇 TOP 20 BA CÀNG (3D) MẠNH NHẤT | B2: Ba Càng 3D | C2: --- | D2: --- | E2: --- | F2: --- | G2: MẠNH NHẤT | H2: Bắt nhịp hỏa lực 3D Top 20
A3: Top 01 | B3: Ba Càng (3D) | C3: 042 | D3: Càng 0 | E3: Đề 42 | F3: 60 | G3: MẠNH | H3: Ưu tiên dàn chính hỏa lực
A4: Top 02 | B4: Ba Càng (3D) | C4: 242 | D4: Càng 2 | E4: Đề 42 | F4: 60 | G4: MẠNH | H4: Ưu tiên dàn chính hỏa lực
