Workbook

Sheet DATA_NHAP
A1: =ROW()-1 -> 0 | B1: =45291+A1 -> 45291 | C1: =IF(D1="","",CHOOSE(H1-1,"T2","T3","T4","T5","T6","T7","CN")) -> CN | D1: 91089 | E1: =IF(D1="","",TEXT(D1,"00000")) -> 91089 | F1: =IF(E1="","",RIGHT(E1,2)) -> 89 | G1: =INT((A1-1)/7)+1 -> 0 | H1: =WEEKDAY(B1,2)+1 -> 8 | I1: =IF(D1="","",G1&"|"&H1) -> 0|8 | J1: =IF(E1="","",MID(E1,1,3)) -> 910 | K1: =IF(E1="","",MID(E1,2,3)) -> 108 | L1: =IF(E1="","",MID(E1,3,3)) -> 089 | M1: =IF(E1="","",MID(E1,1,4)) -> 9108 | N1: =IF(E1="","",MID(E1,2,4)) -> 1089
A2: =ROW()-1 -> 1 | B2: =45291+ROW() -> 45293 | C2: =CHOOSE(WEEKDAY(B2,2),"T2","T3","T4","T5","T6","T7","CN") -> T3 | D2: 48877 | E2: =IF(D2="","",TEXT(D2,"00000")) -> 48877 | F2: =IF(E2="","",RIGHT(E2,2)) -> 77 | G2: =INT((ROW()-1)/7)+1 -> 1 | H2: =WEEKDAY(B2,2)+1 -> 3 | I2: =IF(D2="","",G2&"|"&H2) -> 1|3 | J2: =IF(E2="","",MID(E2,1,3)) -> 488 | K2: =IF(E2="","",MID(E2,2,3)) -> 887 | L2: =IF(E2="","",MID(E2,3,3)) -> 877 | M2: =IF(E2="","",MID(E2,1,4)) -> 4887 | N2: =IF(E2="","",MID(E2,2,4)) -> 8877
A3: =ROW()-1 -> 2 | B3: =45291+ROW() -> 45294 | C3: =CHOOSE(WEEKDAY(B3,2),"T2","T3","T4","T5","T6","T7","CN") -> T4 | D3: 73732 | E3: =IF(D3="","",TEXT(D3,"00000")) -> 73732 | F3: =IF(E3="","",RIGHT(E3,2)) -> 32 | G3: =INT((ROW()-1)/7)+1 -> 1 | H3: =WEEKDAY(B3,2)+1 -> 4 | I3: =IF(D3="","",G3&"|"&H3) -> 1|4 | J3: =IF(E3="","",MID(E3,1,3)) -> 737 | K3: =IF(E3="","",MID(E3,2,3)) -> 373 | L3: =IF(E3="","",MID(E3,3,3)) -> 732 | M3: =IF(E3="","",MID(E3,1,4)) -> 7373 | N3: =IF(E3="","",MID(E3,2,4)) -> 3732
A4: =ROW()-1 -> 3 | B4: =45291+ROW() -> 45295 | C4: =CHOOSE(WEEKDAY(B4,2),"T2","T3","T4","T5","T6","T7","CN") -> T5 | D4: 28285 | E4: =IF(D4="","",TEXT(D4,"00000")) -> 28285 | F4: =IF(E4="","",RIGHT(E4,2)) -> 85 | G4: =INT((ROW()-1)/7)+1 -> 1 | H4: =WEEKDAY(B4,2)+1 -> 5 | I4: =IF(D4="","",G4&"|"&H4) -> 1|5 | J4: =IF(E4="","",MID(E4,1,3)) -> 282 | K4: =IF(E4="","",MID(E4,2,3)) -> 828 | L4: =IF(E4="","",MID(E4,3,3)) -> 285 | M4: =IF(E4="","",MID(E4,1,4)) -> 2828 | N4: =IF(E4="","",MID(E4,2,4)) -> 8285
A5: =ROW()-1 -> 4 | B5: =45291+ROW() -> 45296 | C5: =CHOOSE(WEEKDAY(B5,2),"T2","T3","T4","T5","T6","T7","CN") -> T6 | D5: 13113 | E5: =IF(D5="","",TEXT(D5,"00000")) -> 13113 | F5: =IF(E5="","",RIGHT(E5,2)) -> 13 | G5: =INT((ROW()-1)/7)+1 -> 1 | H5: =WEEKDAY(B5,2)+1 -> 6 | I5: =IF(D5="","",G5&"|"&H5) -> 1|6 | J5: =IF(E5="","",MID(E5,1,3)) -> 131 | K5: =IF(E5="","",MID(E5,2,3)) -> 311 | L5: =IF(E5="","",MID(E5,3,3)) -> 113 | M5: =IF(E5="","",MID(E5,1,4)) -> 1311 | N5: =IF(E5="","",MID(E5,2,4)) -> 3113
A6: =ROW()-1 -> 5 | B6: =45291+ROW() -> 45297 | C6: =CHOOSE(WEEKDAY(B6,2),"T2","T3","T4","T5","T6","T7","CN") -> T7 | D6: 68586 | E6: =IF(D6="","",TEXT(D6,"00000")) -> 68586 | F6: =IF(E6="","",RIGHT(E6,2)) -> 86 | G6: =INT((ROW()-1)/7)+1 -> 1 | H6: =WEEKDAY(B6,2)+1 -> 7 | I6: =IF(D6="","",G6&"|"&H6) -> 1|7 | J6: =IF(E6="","",MID(E6,1,3)) -> 685 | K6: =IF(E6="","",MID(E6,2,3)) -> 858 | L6: =IF(E6="","",MID(E6,3,3)) -> 586 | M6: =IF(E6="","",MID(E6,1,4)) -> 6858 | N6: =IF(E6="","",MID(E6,2,4)) -> 8586
A7: =ROW()-1 -> 6 | B7: =45291+ROW() -> 45298 | C7: =CHOOSE(WEEKDAY(B7,2),"T2","T3","T4","T5","T6","T7","CN") -> CN | D7: 91138 | E7: =IF(D7="","",TEXT(D7,"00000")) -> 91138 | F7: =IF(E7="","",RIGHT(E7,2)) -> 38 | G7: =INT((ROW()-1)/7)+1 -> 1 | H7: =WEEKDAY(B7,2)+1 -> 8 | I7: =IF(D7="","",G7&"|"&H7) -> 1|8 | J7: =IF(E7="","",MID(E7,1,3)) -> 911 | K7: =IF(E7="","",MID(E7,2,3)) -> 113 | L7: =IF(E7="","",MID(E7,3,3)) -> 138 | M7: =IF(E7="","",MID(E7,1,4)) -> 9113 | N7: =IF(E7="","",MID(E7,2,4)) -> 1138
A8: =ROW()-1 -> 7 | B8: =45291+ROW() -> 45299 | C8: =CHOOSE(WEEKDAY(B8,2),"T2","T3","T4","T5","T6","T7","CN") -> T2 | D8: 63261 | E8: =IF(D8="","",TEXT(D8,"00000")) -> 63261 | F8: =IF(E8="","",RIGHT(E8,2)) -> 61 | G8: =INT((ROW()-1)/7)+1 -> 2 | H8: =WEEKDAY(B8,2)+1 -> 2 | I8: =IF(D8="","",G8&"|"&H8) -> 2|2 | J8: =IF(E8="","",MID(E8,1,3)) -> 632 | K8: =IF(E8="","",MID(E8,2,3)) -> 326 | L8: =IF(E8="","",MID(E8,3,3)) -> 261 | M8: =IF(E8="","",MID(E8,1,4)) -> 6326 | N8: =IF(E8="","",MID(E8,2,4)) -> 3261
A9: =ROW()-1 -> 8 | B9: =45291+ROW() -> 45300 | C9: =CHOOSE(WEEKDAY(B9,2),"T2","T3","T4","T5","T6","T7","CN") -> T3 | D9: 95539 | E9: =IF(D9="","",TEXT(D9,"00000")) -> 95539 | F9: =IF(E9="","",RIGHT(E9,2)) -> 39 | G9: =INT((ROW()-1)/7)+1 -> 2 | H9: =WEEKDAY(B9,2)+1 -> 3 | I9: =IF(D9="","",G9&"|"&H9) -> 2|3 | J9: =IF(E9="","",MID(E9,1,3)) -> 955 | K9: =IF(E9="","",MID(E9,2,3)) -> 553 | L9: =IF(E9="","",MID(E9,3,3)) -> 539 | M9: =IF(E9="","",MID(E9,1,4)) -> 9553 | N9: =IF(E9="","",MID(E9,2,4)) -> 5539
A10: =ROW()-1 -> 9 | B10: =45291+ROW() -> 45301 | C10: =CHOOSE(WEEKDAY(B10,2),"T2","T3","T4","T5","T6","T7","CN") -> T4 | D10: 76553 | E10: =IF(D10="","",TEXT(D10,"00000")) -> 76553 | F10: =IF(E10="","",RIGHT(E10,2)) -> 53 | G10: =INT((ROW()-1)/7)+1 -> 2 | H10: =WEEKDAY(B10,2)+1 -> 4 | I10: =IF(D10="","",G10&"|"&H10) -> 2|4 | J10: =IF(E10="","",MID(E10,1,3)) -> 765 | K10: =IF(E10="","",MID(E10,2,3)) -> 655 | L10: =IF(E10="","",MID(E10,3,3)) -> 553 | M10: =IF(E10="","",MID(E10,1,4)) -> 7655 | N10: =IF(E10="","",MID(E10,2,4)) -> 6553
A11: =ROW()-1 -> 10 | B11: =45291+ROW() -> 45302 | C11: =CHOOSE(WEEKDAY(B11,2),"T2","T3","T4","T5","T6","T7","CN") -> T5 | D11: 54998 | E11: =IF(D11="","",TEXT(D11,"00000")) -> 54998 | F11: =IF(E11="","",RIGHT(E11,2)) -> 98 | G11: =INT((ROW()-1)/7)+1 -> 2 | H11: =WEEKDAY(B11,2)+1 -> 5 | I11: =IF(D11="","",G11&"|"&H11) -> 2|5 | J11: =IF(E11="","",MID(E11,1,3)) -> 549 | K11: =IF(E11="","",MID(E11,2,3)) -> 499 | L11: =IF(E11="","",MID(E11,3,3)) -> 998 | M11: =IF(E11="","",MID(E11,1,4)) -> 5499 | N11: =IF(E11="","",MID(E11,2,4)) -> 4998
A12: =ROW()-1 -> 11 | B12: =45291+ROW() -> 45303 | C12: =CHOOSE(WEEKDAY(B12,2),"T2","T3","T4","T5","T6","T7","CN") -> T6 | D12: 14609 | E12: =IF(D12="","",TEXT(D12,"00000")) -> 14609 | F12: =IF(E12="","",RIGHT(E12,2)) -> 09 | G12: =INT((ROW()-1)/7)+1 -> 2 | H12: =WEEKDAY(B12,2)+1 -> 6 | I12: =IF(D12="","",G12&"|"&H12) -> 2|6 | J12: =IF(E12="","",MID(E12,1,3)) -> 146 | K12: =IF(E12="","",MID(E12,2,3)) -> 460 | L12: =IF(E12="","",MID(E12,3,3)) -> 609 | M12: =IF(E12="","",MID(E12,1,4)) -> 1460 | N12: =IF(E12="","",MID(E12,2,4)) -> 4609
A13: =ROW()-1 -> 12 | B13: =45291+ROW() -> 45304 | C13: =CHOOSE(WEEKDAY(B13,2),"T2","T3","T4","T5","T6","T7","CN") -> T7 | D13: 70964 | E13: =IF(D13="","",TEXT(D13,"00000")) -> 70964 | F13: =IF(E13="","",RIGHT(E13,2)) -> 64 | G13: =INT((ROW()-1)/7)+1 -> 2 | H13: =WEEKDAY(B13,2)+1 -> 7 | I13: =IF(D13="","",G13&"|"&H13) -> 2|7 | J13: =IF(E13="","",MID(E13,1,3)) -> 709 | K13: =IF(E13="","",MID(E13,2,3)) -> 096 | L13: =IF(E13="","",MID(E13,3,3)) -> 964 | M13: =IF(E13="","",MID(E13,1,4)) -> 7096 | N13: =IF(E13="","",MID(E13,2,4)) -> 0964
... A32: =ROW()-1 -> 31 | B32: =45291+ROW() -> 45323 | C32: =CHOOSE(WEEKDAY(B32,2),"T2","T3","T4","T5","T6","T7","CN") -> T5 | D32: 85852 | E32: =IF(D32="","",TEXT(D32,"00000")) -> 85852 | F32: =IF(E32="","",RIGHT(E32,2)) -> 52 | G32: =INT((ROW()-1)/7)+1 -> 5 | H32: =WEEKDAY(B32,2)+1 -> 5 | I32: =IF(D32="","",G32&"|"&H32) -> 5|5 | J32: =IF(E32="","",MID(E32,1,3)) -> 858 | K32: =IF(E32="","",MID(E32,2,3)) -> 585 | L32: =IF(E32="","",MID(E32,3,3)) -> 852 | M32: =IF(E32="","",MID(E32,1,4)) -> 8585 | N32: =IF(E32="","",MID(E32,2,4)) -> 5852
A33: =ROW()-1 -> 32 | B33: =45291+ROW() -> 45324 | C33: =CHOOSE(WEEKDAY(B33,2),"T2","T3","T4","T5","T6","T7","CN") -> T6 | E33: =IF(D33="","",TEXT(D33,"00000")) | F33: =IF(E33="","",RIGHT(E33,2)) | G33: =INT((ROW()-1)/7)+1 -> 5 | H33: =WEEKDAY(B33,2)+1 -> 6 | I33: =IF(D33="","",G33&"|"&H33) | J33: =IF(E33="","",MID(E33,1,3)) | K33: =IF(E33="","",MID(E33,2,3)) | L33: =IF(E33="","",MID(E33,3,3)) | M33: =IF(E33="","",MID(E33,1,4)) | N33: =IF(E33="","",MID(E33,2,4))
A34: =ROW()-1 -> 33 | B34: =45291+ROW() -> 45325 | C34: =CHOOSE(WEEKDAY(B34,2),"T2","T3","T4","T5","T6","T7","CN") -> T7 | E34: =IF(D34="","",TEXT(D34,"00000")) | F34: =IF(E34="","",RIGHT(E34,2)) | G34: =INT((ROW()-1)/7)+1 -> 5 | H34: =WEEKDAY(B34,2)+1 -> 7 | I34: =IF(D34="","",G34&"|"&H34) | J34: =IF(E34="","",MID(E34,1,3)) | K34: =IF(E34="","",MID(E34,2,3)) | L34: =IF(E34="","",MID(E34,3,3)) | M34: =IF(E34="","",MID(E34,1,4)) | N34: =IF(E34="","",MID(E34,2,4))
A35: =ROW()-1 -> 34 | B35: =45291+ROW() -> 45326 | C35: =CHOOSE(WEEKDAY(B35,2),"T2","T3","T4","T5","T6","T7","CN") -> CN | E35: =IF(D35="","",TEXT(D35,"00000")) | F35: =IF(E35="","",RIGHT(E35,2)) | G35: =INT((ROW()-1)/7)+1 -> 5 | H35: =WEEKDAY(B35,2)+1 -> 8 | I35: =IF(D35="","",G35&"|"&H35) | J35: =IF(E35="","",MID(E35,1,3)) | K35: =IF(E35="","",MID(E35,2,3)) | L35: =IF(E35="","",MID(E35,3,3)) | M35: =IF(E35="","",MID(E35,1,4)) | N35: =IF(E35="","",MID(E35,2,4))
A36: =ROW()-1 -> 35 | B36: =45291+ROW() -> 45327 | C36: =CHOOSE(WEEKDAY(B36,2),"T2","T3","T4","T5","T6","T7","CN") -> T2 | E36: =IF(D36="","",TEXT(D36,"00000")) | F36: =IF(E36="","",RIGHT(E36,2)) | G36: =INT((ROW()-1)/7)+1 -> 6 | H36: =WEEKDAY(B36,2)+1 -> 2 | I36: =IF(D36="","",G36&"|"&H36) | J36: =IF(E36="","",MID(E36,1,3)) | K36: =IF(E36="","",MID(E36,2,3)) | L36: =IF(E36="","",MID(E36,3,3)) | M36: =IF(E36="","",MID(E36,1,4)) | N36: =IF(E36="","",MID(E36,2,4))
A37: =ROW()-1 -> 36 | B37: =45291+ROW() -> 45328 | C37: =CHOOSE(WEEKDAY(B37,2),"T2","T3","T4","T5","T6","T7","CN") -> T3 | D37: 39100 | E37: =IF(D37="","",TEXT(D37,"00000")) -> 39100 | F37: =IF(E37="","",RIGHT(E37,2)) -> 00 | G37: =INT((ROW()-1)/7)+1 -> 6 | H37: =WEEKDAY(B37,2)+1 -> 3 | I37: =IF(D37="","",G37&"|"&H37) -> 6|3 | J37: =IF(E37="","",MID(E37,1,3)) -> 391 | K37: =IF(E37="","",MID(E37,2,3)) -> 910 | L37: =IF(E37="","",MID(E37,3,3)) -> 100 | M37: =IF(E37="","",MID(E37,1,4)) -> 3910 | N37: =IF(E37="","",MID(E37,2,4)) -> 9100
A38: =ROW()-1 -> 37 | B38: =45291+ROW() -> 45329 | C38: =CHOOSE(WEEKDAY(B38,2),"T2","T3","T4","T5","T6","T7","CN") -> T4 | D38: 17670 | E38: =IF(D38="","",TEXT(D38,"00000")) -> 17670 | F38: =IF(E38="","",RIGHT(E38,2)) -> 70 | G38: =INT((ROW()-1)/7)+1 -> 6 | H38: =WEEKDAY(B38,2)+1 -> 4 | I38: =IF(D38="","",G38&"|"&H38) -> 6|4 | J38: =IF(E38="","",MID(E38,1,3)) -> 176 | K38: =IF(E38="","",MID(E38,2,3)) -> 767 | L38: =IF(E38="","",MID(E38,3,3)) -> 670 | M38: =IF(E38="","",MID(E38,1,4)) -> 1767 | N38: =IF(E38="","",MID(E38,2,4)) -> 7670
A39: =ROW()-1 -> 38 | B39: =45291+ROW() -> 45330 | C39: =CHOOSE(WEEKDAY(B39,2),"T2","T3","T4","T5","T6","T7","CN") -> T5 | D39: 48331 | E39: =IF(D39="","",TEXT(D39,"00000")) -> 48331 | F39: =IF(E39="","",RIGHT(E39,2)) -> 31 | G39: =INT((ROW()-1)/7)+1 -> 6 | H39: =WEEKDAY(B39,2)+1 -> 5 | I39: =IF(D39="","",G39&"|"&H39) -> 6|5 | J39: =IF(E39="","",MID(E39,1,3)) -> 483 | K39: =IF(E39="","",MID(E39,2,3)) -> 833 | L39: =IF(E39="","",MID(E39,3,3)) -> 331 | M39: =IF(E39="","",MID(E39,1,4)) -> 4833 | N39: =IF(E39="","",MID(E39,2,4)) -> 8331
A40: =ROW()-1 -> 39 | B40: =45291+ROW() -> 45331 | C40: =CHOOSE(WEEKDAY(B40,2),"T2","T3","T4","T5","T6","T7","CN") -> T6 | E40: =IF(D40="","",TEXT(D40,"00000")) | F40: =IF(E40="","",RIGHT(E40,2)) | G40: =INT((ROW()-1)/7)+1 -> 6 | H40: =WEEKDAY(B40,2)+1 -> 6 | I40: =IF(D40="","",G40&"|"&H40) | J40: =IF(E40="","",MID(E40,1,3)) | K40: =IF(E40="","",MID(E40,2,3)) | L40: =IF(E40="","",MID(E40,3,3)) | M40: =IF(E40="","",MID(E40,1,4)) | N40: =IF(E40="","",MID(E40,2,4))
A41: =ROW()-1 -> 40 | B41: =45291+ROW() -> 45332 | C41: =CHOOSE(WEEKDAY(B41,2),"T2","T3","T4","T5","T6","T7","CN") -> T7 | E41: =IF(D41="","",TEXT(D41,"00000")) | F41: =IF(E41="","",RIGHT(E41,2)) | G41: =INT((ROW()-1)/7)+1 -> 6 | H41: =WEEKDAY(B41,2)+1 -> 7 | I41: =IF(D41="","",G41&"|"&H41) | J41: =IF(E41="","",MID(E41,1,3)) | K41: =IF(E41="","",MID(E41,2,3)) | L41: =IF(E41="","",MID(E41,3,3)) | M41: =IF(E41="","",MID(E41,1,4)) | N41: =IF(E41="","",MID(E41,2,4))
A42: =ROW()-1 -> 41 | B42: =45291+ROW() -> 45333 | C42: =CHOOSE(WEEKDAY(B42,2),"T2","T3","T4","T5","T6","T7","CN") -> CN | E42: =IF(D42="","",TEXT(D42,"00000")) | F42: =IF(E42="","",RIGHT(E42,2)) | G42: =INT((ROW()-1)/7)+1 -> 6 | H42: =WEEKDAY(B42,2)+1 -> 8 | I42: =IF(D42="","",G42&"|"&H42) | J42: =IF(E42="","",MID(E42,1,3)) | K42: =IF(E42="","",MID(E42,2,3)) | L42: =IF(E42="","",MID(E42,3,3)) | M42: =IF(E42="","",MID(E42,1,4)) | N42: =IF(E42="","",MID(E42,2,4))
A43: =ROW()-1 -> 42 | B43: =45291+ROW() -> 45334 | C43: =CHOOSE(WEEKDAY(B43,2),"T2","T3","T4","T5","T6","T7","CN") -> T2 | E43: =IF(D43="","",TEXT(D43,"00000")) | F43: =IF(E43="","",RIGHT(E43,2)) | G43: =INT((ROW()-1)/7)+1 -> 7 | H43: =WEEKDAY(B43,2)+1 -> 2 | I43: =IF(D43="","",G43&"|"&H43) | J43: =IF(E43="","",MID(E43,1,3)) | K43: =IF(E43="","",MID(E43,2,3)) | L43: =IF(E43="","",MID(E43,3,3)) | M43: =IF(E43="","",MID(E43,1,4)) | N43: =IF(E43="","",MID(E43,2,4))
A44: =ROW()-1 -> 43 | B44: =45291+ROW() -> 45335 | C44: =CHOOSE(WEEKDAY(B44,2),"T2","T3","T4","T5","T6","T7","CN") -> T3 | D44: 57406 | E44: =IF(D44="","",TEXT(D44,"00000")) -> 57406 | F44: =IF(E44="","",RIGHT(E44,2)) -> 06 | G44: =INT((ROW()-1)/7)+1 -> 7 | H44: =WEEKDAY(B44,2)+1 -> 3 | I44: =IF(D44="","",G44&"|"&H44) -> 7|3 | J44: =IF(E44="","",MID(E44,1,3)) -> 574 | K44: =IF(E44="","",MID(E44,2,3)) -> 740 | L44: =IF(E44="","",MID(E44,3,3)) -> 406 | M44: =IF(E44="","",MID(E44,1,4)) -> 5740 | N44: =IF(E44="","",MID(E44,2,4)) -> 7406
A45: =ROW()-1 -> 44 | B45: =45291+ROW() -> 45336 | C45: =CHOOSE(WEEKDAY(B45,2),"T2","T3","T4","T5","T6","T7","CN") -> T4 | D45: 99937 | E45: =IF(D45="","",TEXT(D45,"00000")) -> 99937 | F45: =IF(E45="","",RIGHT(E45,2)) -> 37 | G45: =INT((ROW()-1)/7)+1 -> 7 | H45: =WEEKDAY(B45,2)+1 -> 4 | I45: =IF(D45="","",G45&"|"&H45) -> 7|4 | J45: =IF(E45="","",MID(E45,1,3)) -> 999 | K45: =IF(E45="","",MID(E45,2,3)) -> 993 | L45: =IF(E45="","",MID(E45,3,3)) -> 937 | M45: =IF(E45="","",MID(E45,1,4)) -> 9993 | N45: =IF(E45="","",MID(E45,2,4)) -> 9937
A46: =ROW()-1 -> 45 | B46: =45291+ROW() -> 45337 | C46: =CHOOSE(WEEKDAY(B46,2),"T2","T3","T4","T5","T6","T7","CN") -> T5 | D46: 82488 | E46: =IF(D46="","",TEXT(D46,"00000")) -> 82488 | F46: =IF(E46="","",RIGHT(E46,2)) -> 88 | G46: =INT((ROW()-1)/7)+1 -> 7 | H46: =WEEKDAY(B46,2)+1 -> 5 | I46: =IF(D46="","",G46&"|"&H46) -> 7|5 | J46: =IF(E46="","",MID(E46,1,3)) -> 824 | K46: =IF(E46="","",MID(E46,2,3)) -> 248 | L46: =IF(E46="","",MID(E46,3,3)) -> 488 | M46: =IF(E46="","",MID(E46,1,4)) -> 8248 | N46: =IF(E46="","",MID(E46,2,4)) -> 2488
A47: =ROW()-1 -> 46 | B47: =45291+ROW() -> 45338 | C47: =CHOOSE(WEEKDAY(B47,2),"T2","T3","T4","T5","T6","T7","CN") -> T6 | D47: 16053 | E47: =IF(D47="","",TEXT(D47,"00000")) -> 16053 | F47: =IF(E47="","",RIGHT(E47,2)) -> 53 | G47: =INT((ROW()-1)/7)+1 -> 7 | H47: =WEEKDAY(B47,2)+1 -> 6 | I47: =IF(D47="","",G47&"|"&H47) -> 7|6 | J47: =IF(E47="","",MID(E47,1,3)) -> 160 | K47: =IF(E47="","",MID(E47,2,3)) -> 605 | L47: =IF(E47="","",MID(E47,3,3)) -> 053 | M47: =IF(E47="","",MID(E47,1,4)) -> 1605 | N47: =IF(E47="","",MID(E47,2,4)) -> 6053
A48: =ROW()-1 -> 47 | B48: =45291+ROW() -> 45339 | C48: =CHOOSE(WEEKDAY(B48,2),"T2","T3","T4","T5","T6","T7","CN") -> T7 | D48: 57333 | E48: =IF(D48="","",TEXT(D48,"00000")) -> 57333 | F48: =IF(E48="","",RIGHT(E48,2)) -> 33 | G48: =INT((ROW()-1)/7)+1 -> 7 | H48: =WEEKDAY(B48,2)+1 -> 7 | I48: =IF(D48="","",G48&"|"&H48) -> 7|7 | J48: =IF(E48="","",MID(E48,1,3)) -> 573 | K48: =IF(E48="","",MID(E48,2,3)) -> 733 | L48: =IF(E48="","",MID(E48,3,3)) -> 333 | M48: =IF(E48="","",MID(E48,1,4)) -> 5733 | N48: =IF(E48="","",MID(E48,2,4)) -> 7333
A49: =ROW()-1 -> 48 | B49: =45291+ROW() -> 45340 | C49: =CHOOSE(WEEKDAY(B49,2),"T2","T3","T4","T5","T6","T7","CN") -> CN | D49: 15545 | E49: =IF(D49="","",TEXT(D49,"00000")) -> 15545 | F49: =IF(E49="","",RIGHT(E49,2)) -> 45 | G49: =INT((ROW()-1)/7)+1 -> 7 | H49: =WEEKDAY(B49,2)+1 -> 8 | I49: =IF(D49="","",G49&"|"&H49) -> 7|8 | J49: =IF(E49="","",MID(E49,1,3)) -> 155 | K49: =IF(E49="","",MID(E49,2,3)) -> 554 | L49: =IF(E49="","",MID(E49,3,3)) -> 545 | M49: =IF(E49="","",MID(E49,1,4)) -> 1554 | N49: =IF(E49="","",MID(E49,2,4)) -> 5545
A50: =ROW()-1 -> 49 | B50: =45291+ROW() -> 45341 | C50: =CHOOSE(WEEKDAY(B50,2),"T2","T3","T4","T5","T6","T7","CN") -> T2 | D50: 27234 | E50: =IF(D50="","",TEXT(D50,"00000")) -> 27234 | F50: =IF(E50="","",RIGHT(E50,2)) -> 34 | G50: =INT((ROW()-1)/7)+1 -> 8 | H50: =WEEKDAY(B50,2)+1 -> 2 | I50: =IF(D50="","",G50&"|"&H50) -> 8|2 | J50: =IF(E50="","",MID(E50,1,3)) -> 272 | K50: =IF(E50="","",MID(E50,2,3)) -> 723 | L50: =IF(E50="","",MID(E50,3,3)) -> 234 | M50: =IF(E50="","",MID(E50,1,4)) -> 2723 | N50: =IF(E50="","",MID(E50,2,4)) -> 7234
A51: =ROW()-1 -> 50 | B51: =45291+ROW() -> 45342 | C51: =CHOOSE(WEEKDAY(B51,2),"T2","T3","T4","T5","T6","T7","CN") -> T3 | D51: 36209 | E51: =IF(D51="","",TEXT(D51,"00000")) -> 36209 | F51: =IF(E51="","",RIGHT(E51,2)) -> 09 | G51: =INT((ROW()-1)/7)+1 -> 8 | H51: =WEEKDAY(B51,2)+1 -> 3 | I51: =IF(D51="","",G51&"|"&H51) -> 8|3 | J51: =IF(E51="","",MID(E51,1,3)) -> 362 | K51: =IF(E51="","",MID(E51,2,3)) -> 620 | L51: =IF(E51="","",MID(E51,3,3)) -> 209 | M51: =IF(E51="","",MID(E51,1,4)) -> 3620 | N51: =IF(E51="","",MID(E51,2,4)) -> 6209
A52: =ROW()-1 -> 51 | B52: =45291+ROW() -> 45343 | C52: =CHOOSE(WEEKDAY(B52,2),"T2","T3","T4","T5","T6","T7","CN") -> T4 | D52: 77645 | E52: =IF(D52="","",TEXT(D52,"00000")) -> 77645 | F52: =IF(E52="","",RIGHT(E52,2)) -> 45 | G52: =INT((ROW()-1)/7)+1 -> 8 | H52: =WEEKDAY(B52,2)+1 -> 4 | I52: =IF(D52="","",G52&"|"&H52) -> 8|4 | J52: =IF(E52="","",MID(E52,1,3)) -> 776 | K52: =IF(E52="","",MID(E52,2,3)) -> 764 | L52: =IF(E52="","",MID(E52,3,3)) -> 645 | M52: =IF(E52="","",MID(E52,1,4)) -> 7764 | N52: =IF(E52="","",MID(E52,2,4)) -> 7645
A53: =ROW()-1 -> 52 | B53: =45291+ROW() -> 45344 | C53: =CHOOSE(WEEKDAY(B53,2),"T2","T3","T4","T5","T6","T7","CN") -> T5 | D53: 39648 | E53: =IF(D53="","",TEXT(D53,"00000")) -> 39648 | F53: =IF(E53="","",RIGHT(E53,2)) -> 48 | G53: =INT((ROW()-1)/7)+1 -> 8 | H53: =WEEKDAY(B53,2)+1 -> 5 | I53: =IF(D53="","",G53&"|"&H53) -> 8|5 | J53: =IF(E53="","",MID(E53,1,3)) -> 396 | K53: =IF(E53="","",MID(E53,2,3)) -> 964 | L53: =IF(E53="","",MID(E53,3,3)) -> 648 | M53: =IF(E53="","",MID(E53,1,4)) -> 3964 | N53: =IF(E53="","",MID(E53,2,4)) -> 9648
A54: =ROW()-1 -> 53 | B54: =45291+ROW() -> 45345 | C54: =CHOOSE(WEEKDAY(B54,2),"T2","T3","T4","T5","T6","T7","CN") -> T6 | D54: 71961 | E54: =IF(D54="","",TEXT(D54,"00000")) -> 71961 | F54: =IF(E54="","",RIGHT(E54,2)) -> 61 | G54: =INT((ROW()-1)/7)+1 -> 8 | H54: =WEEKDAY(B54,2)+1 -> 6 | I54: =IF(D54="","",G54&"|"&H54) -> 8|6 | J54: =IF(E54="","",MID(E54,1,3)) -> 719 | K54: =IF(E54="","",MID(E54,2,3)) -> 196 | L54: =IF(E54="","",MID(E54,3,3)) -> 961 | M54: =IF(E54="","",MID(E54,1,4)) -> 7196 | N54: =IF(E54="","",MID(E54,2,4)) -> 1961
A55: =ROW()-1 -> 54 | B55: =45291+ROW() -> 45346 | C55: =CHOOSE(WEEKDAY(B55,2),"T2","T3","T4","T5","T6","T7","CN") -> T7 | D55: 77433 | E55: =IF(D55="","",TEXT(D55,"00000")) -> 77433 | F55: =IF(E55="","",RIGHT(E55,2)) -> 33 | G55: =INT((ROW()-1)/7)+1 -> 8 | H55: =WEEKDAY(B55,2)+1 -> 7 | I55: =IF(D55="","",G55&"|"&H55) -> 8|7 | J55: =IF(E55="","",MID(E55,1,3)) -> 774 | K55: =IF(E55="","",MID(E55,2,3)) -> 743 | L55: =IF(E55="","",MID(E55,3,3)) -> 433 | M55: =IF(E55="","",MID(E55,1,4)) -> 7743 | N55: =IF(E55="","",MID(E55,2,4)) -> 7433
... A386: =ROW()-1 -> 385 | B386: =45291+ROW() -> 45677 | C386: =CHOOSE(WEEKDAY(B386,2),"T2","T3","T4","T5","T6","T7","CN") -> T2 | D386: 31409 | E386: =IF(D386="","",TEXT(D386,"00000")) -> 31409 | F386: =IF(E386="","",RIGHT(E386,2)) -> 09 | G386: =INT((ROW()-1)/7)+1 -> 56 | H386: =WEEKDAY(B386,2)+1 -> 2 | I386: =IF(D386="","",G386&"|"&H386) -> 56|2 | J386: =IF(E386="","",MID(E386,1,3)) -> 314 | K386: =IF(E386="","",MID(E386,2,3)) -> 140 | L386: =IF(E386="","",MID(E386,3,3)) -> 409 | M386: =IF(E386="","",MID(E386,1,4)) -> 3140 | N386: =IF(E386="","",MID(E386,2,4)) -> 1409
A387: =ROW()-1 -> 386 | B387: =45291+ROW() -> 45678 | C387: =CHOOSE(WEEKDAY(B387,2),"T2","T3","T4","T5","T6","T7","CN") -> T3 | E387: =IF(D387="","",TEXT(D387,"00000")) | F387: =IF(E387="","",RIGHT(E387,2)) | G387: =INT((ROW()-1)/7)+1 -> 56 | H387: =WEEKDAY(B387,2)+1 -> 3 | I387: =IF(D387="","",G387&"|"&H387) | J387: =IF(E387="","",MID(E387,1,3)) | K387: =IF(E387="","",MID(E387,2,3)) | L387: =IF(E387="","",MID(E387,3,3)) | M387: =IF(E387="","",MID(E387,1,4)) | N387: =IF(E387="","",MID(E387,2,4))
A388: =ROW()-1 -> 387 | B388: =45291+ROW() -> 45679 | C388: =CHOOSE(WEEKDAY(B388,2),"T2","T3","T4","T5","T6","T7","CN") -> T4 | E388: =IF(D388="","",TEXT(D388,"00000")) | F388: =IF(E388="","",RIGHT(E388,2)) | G388: =INT((ROW()-1)/7)+1 -> 56 | H388: =WEEKDAY(B388,2)+1 -> 4 | I388: =IF(D388="","",G388&"|"&H388) | J388: =IF(E388="","",MID(E388,1,3)) | K388: =IF(E388="","",MID(E388,2,3)) | L388: =IF(E388="","",MID(E388,3,3)) | M388: =IF(E388="","",MID(E388,1,4)) | N388: =IF(E388="","",MID(E388,2,4))
...

Sheet LOC_COPY
A1: LOC_COPY - TẠO DÀN 2D NGUỒN THEO NHÓM SỐ + TỔNG + CHẠM
A3: Tuần cần xem | B3: 137 | D3: Tuần lấy vị trí | E3: =B3-1 -> 136
A5: CÀI ĐẶT GHÉP
A6: Nhóm | B6: Số cố định | C6: Tổng bật | D6: Bật | E6: Ghi chú
A7: Nhóm 1 | B7: 23456 | E7: Lấy số có 1 trong 2 chữ số thuộc nhóm và tổng đơn vị thuộc Tổng bật
A8: Nhóm 2 | B8: 56789 | C8: 8913 | D8: X | E8: Tương tự nhóm 1
A9: Chạm chính | B9: 1236 | C9: Chỉ dùng để cộng điểm, không tự sinh thêm số
A10: Top 2D lấy | B10: 12
A12: KẾT QUẢ COPY NHANH
A13: Dàn 2D nguồn | B13: =K119 -> 08 09 17 18 26 27 29 35 36 38 45 47 49 53 54 56 58 62 63 65 67 71 72 74 76 80 81 83 85 90 92 94 99
A14: Dàn 2D nổi bật | B14: =L119 -> 17 18 26 27 29 35 36 38 53 56 62 63 65 67 71 72 76 81 83 92
A15: Số lượng nguồn | B15: =COUNTIF(F20:F119,TRUE()) -> 33
A16: Số lượng nổi bật | B16: =COUNTIF(J20:J119,"<>") -> 100
A19: STT | B19: Số 2D | C19: Tổng | D19: Nhóm 1 | E19: Nhóm 2 | F19: Nguồn | G19: Chạm chính | H19: Điểm 2D | I19: Dàn nguồn | J19: Top nổi bật
A20: 0 | B20: =TEXT(A20,"00") -> 00 | C20: =MOD(VALUE(LEFT(B20,1))+VALUE(RIGHT(B20,1)),10) -> 0 | D20: =AND($D$7="X",OR(ISNUMBER(SEARCH(LEFT(B20,1),$B$7)),ISNUMBER(SEARCH(RIGHT(B20,1),$B$7))),ISNUMBER(SEARCH(TEXT(C20,"0"),$C$7))) -> FALSE | E20: =AND($D$8="X",OR(ISNUMBER(SEARCH(LEFT(B20,1),$B$8)),ISNUMBER(SEARCH(RIGHT(B20,1),$B$8))),ISNUMBER(SEARCH(TEXT(C20,"0"),$C$8))) -> FALSE | F20: =OR(D20,E20) -> FALSE | G20: =OR(ISNUMBER(SEARCH(LEFT(B20,1),$B$9)),ISNUMBER(SEARCH(RIGHT(B20,1),$B$9))) -> FALSE | H20: =--D20+--E20+IF(AND(D20,E20),2,0)+--G20 -> 0 | I20: =IF(F20,B20,"") | J20: =IF(AND(F20,H20>=LARGE($H$20:$H$119,$B$10)),B20,"") | K20: =TRIM(K19&" "&I20) | L20: =TRIM(L19&" "&J20)
A21: 1 | B21: =TEXT(A21,"00") -> 01 | C21: =MOD(VALUE(LEFT(B21,1))+VALUE(RIGHT(B21,1)),10) -> 1 | D21: =AND($D$7="X",OR(ISNUMBER(SEARCH(LEFT(B21,1),$B$7)),ISNUMBER(SEARCH(RIGHT(B21,1),$B$7))),ISNUMBER(SEARCH(TEXT(C21,"0"),$C$7))) -> FALSE | E21: =AND($D$8="X",OR(ISNUMBER(SEARCH(LEFT(B21,1),$B$8)),ISNUMBER(SEARCH(RIGHT(B21,1),$B$8))),ISNUMBER(SEARCH(TEXT(C21,"0"),$C$8))) -> FALSE | F21: =OR(D21,E21) -> FALSE | G21: =OR(ISNUMBER(SEARCH(LEFT(B21,1),$B$9)),ISNUMBER(SEARCH(RIGHT(B21,1),$B$9))) -> TRUE | H21: =--D21+--E21+IF(AND(D21,E21),2,0)+--G21 -> 1 | I21: =IF(F21,B21,"") | J21: =IF(AND(F21,H21>=LARGE($H$20:$H$119,$B$10)),B21,"") | K21: =TRIM(K20&" "&I21) | L21: =TRIM(L20&" "&J21)
A22: 2 | B22: =TEXT(A22,"00") -> 02 | C22: =MOD(VALUE(LEFT(B22,1))+VALUE(RIGHT(B22,1)),10) -> 2 | D22: =AND($D$7="X",OR(ISNUMBER(SEARCH(LEFT(B22,1),$B$7)),ISNUMBER(SEARCH(RIGHT(B22,1),$B$7))),ISNUMBER(SEARCH(TEXT(C22,"0"),$C$7))) -> FALSE | E22: =AND($D$8="X",OR(ISNUMBER(SEARCH(LEFT(B22,1),$B$8)),ISNUMBER(SEARCH(RIGHT(B22,1),$B$8))),ISNUMBER(SEARCH(TEXT(C22,"0"),$C$8))) -> FALSE | F22: =OR(D22,E22) -> FALSE | G22: =OR(ISNUMBER(SEARCH(LEFT(B22,1),$B$9)),ISNUMBER(SEARCH(RIGHT(B22,1),$B$9))) -> TRUE | H22: =--D22+--E22+IF(AND(D22,E22),2,0)+--G22 -> 1 | I22: =IF(F22,B22,"") | J22: =IF(AND(F22,H22>=LARGE($H$20:$H$119,$B$10)),B22,"") | K22: =TRIM(K21&" "&I22) | L22: =TRIM(L21&" "&J22)
A23: 3 | B23: =TEXT(A23,"00") -> 03 | C23: =MOD(VALUE(LEFT(B23,1))+VALUE(RIGHT(B23,1)),10) -> 3 | D23: =AND($D$7="X",OR(ISNUMBER(SEARCH(LEFT(B23,1),$B$7)),ISNUMBER(SEARCH(RIGHT(B23,1),$B$7))),ISNUMBER(SEARCH(TEXT(C23,"0"),$C$7))) -> FALSE | E23: =AND($D$8="X",OR(ISNUMBER(SEARCH(LEFT(B23,1),$B$8)),ISNUMBER(SEARCH(RIGHT(B23,1),$B$8))),ISNUMBER(SEARCH(TEXT(C23,"0"),$C$8))) -> FALSE | F23: =OR(D23,E23) -> FALSE | G23: =OR(ISNUMBER(SEARCH(LEFT(B23,1),$B$9)),ISNUMBER(SEARCH(RIGHT(B23,1),$B$9))) -> TRUE | H23: =--D23+--E23+IF(AND(D23,E23),2,0)+--G23 -> 1 | I23: =IF(F23,B23,"") | J23: =IF(AND(F23,H23>=LARGE($H$20:$H$119,$B$10)),B23,"") | K23: =TRIM(K22&" "&I23) | L23: =TRIM(L22&" "&J23)
A24: 4 | B24: =TEXT(A24,"00") -> 04 | C24: =MOD(VALUE(LEFT(B24,1))+VALUE(RIGHT(B24,1)),10) -> 4 | D24: =AND($D$7="X",OR(ISNUMBER(SEARCH(LEFT(B24,1),$B$7)),ISNUMBER(SEARCH(RIGHT(B24,1),$B$7))),ISNUMBER(SEARCH(TEXT(C24,"0"),$C$7))) -> FALSE | E24: =AND($D$8="X",OR(ISNUMBER(SEARCH(LEFT(B24,1),$B$8)),ISNUMBER(SEARCH(RIGHT(B24,1),$B$8))),ISNUMBER(SEARCH(TEXT(C24,"0"),$C$8))) -> FALSE | F24: =OR(D24,E24) -> FALSE | G24: =OR(ISNUMBER(SEARCH(LEFT(B24,1),$B$9)),ISNUMBER(SEARCH(RIGHT(B24,1),$B$9))) -> FALSE | H24: =--D24+--E24+IF(AND(D24,E24),2,0)+--G24 -> 0 | I24: =IF(F24,B24,"") | J24: =IF(AND(F24,H24>=LARGE($H$20:$H$119,$B$10)),B24,"") | K24: =TRIM(K23&" "&I24) | L24: =TRIM(L23&" "&J24)
A25: 5 | B25: =TEXT(A25,"00") -> 05 | C25: =MOD(VALUE(LEFT(B25,1))+VALUE(RIGHT(B25,1)),10) -> 5 | D25: =AND($D$7="X",OR(ISNUMBER(SEARCH(LEFT(B25,1),$B$7)),ISNUMBER(SEARCH(RIGHT(B25,1),$B$7))),ISNUMBER(SEARCH(TEXT(C25,"0"),$C$7))) -> FALSE | E25: =AND($D$8="X",OR(ISNUMBER(SEARCH(LEFT(B25,1),$B$8)),ISNUMBER(SEARCH(RIGHT(B25,1),$B$8))),ISNUMBER(SEARCH(TEXT(C25,"0"),$C$8))) -> FALSE | F25: =OR(D25,E25) -> FALSE | G25: =OR(ISNUMBER(SEARCH(LEFT(B25,1),$B$9)),ISNUMBER(SEARCH(RIGHT(B25,1),$B$9))) -> FALSE | H25: =--D25+--E25+IF(AND(D25,E25),2,0)+--G25 -> 0 | I25: =IF(F25,B25,"") | J25: =IF(AND(F25,H25>=LARGE($H$20:$H$119,$B$10)),B25,"") | K25: =TRIM(K24&" "&I25) | L25: =TRIM(L24&" "&J25)
A26: 6 | B26: =TEXT(A26,"00") -> 06 | C26: =MOD(VALUE(LEFT(B26,1))+VALUE(RIGHT(B26,1)),10) -> 6 | D26: =AND($D$7="X",OR(ISNUMBER(SEARCH(LEFT(B26,1),$B$7)),ISNUMBER(SEARCH(RIGHT(B26,1),$B$7))),ISNUMBER(SEARCH(TEXT(C26,"0"),$C$7))) -> FALSE | E26: =AND($D$8="X",OR(ISNUMBER(SEARCH(LEFT(B26,1),$B$8)),ISNUMBER(SEARCH(RIGHT(B26,1),$B$8))),ISNUMBER(SEARCH(TEXT(C26,"0"),$C$8))) -> FALSE | F26: =OR(D26,E26) -> FALSE | G26: =OR(ISNUMBER(SEARCH(LEFT(B26,1),$B$9)),ISNUMBER(SEARCH(RIGHT(B26,1),$B$9))) -> TRUE | H26: =--D26+--E26+IF(AND(D26,E26),2,0)+--G26 -> 1 | I26: =IF(F26,B26,"") | J26: =IF(AND(F26,H26>=LARGE($H$20:$H$119,$B$10)),B26,"") | K26: =TRIM(K25&" "&I26) | L26: =TRIM(L25&" "&J26)
A27: 7 | B27: =TEXT(A27,"00") -> 07 | C27: =MOD(VALUE(LEFT(B27,1))+VALUE(RIGHT(B27,1)),10) -> 7 | D27: =AND($D$7="X",OR(ISNUMBER(SEARCH(LEFT(B27,1),$B$7)),ISNUMBER(SEARCH(RIGHT(B27,1),$B$7))),ISNUMBER(SEARCH(TEXT(C27,"0"),$C$7))) -> FALSE | E27: =AND($D$8="X",OR(ISNUMBER(SEARCH(LEFT(B27,1),$B$8)),ISNUMBER(SEARCH(RIGHT(B27,1),$B$8))),ISNUMBER(SEARCH(TEXT(C27,"0"),$C$8))) -> FALSE | F27: =OR(D27,E27) -> FALSE | G27: =OR(ISNUMBER(SEARCH(LEFT(B27,1),$B$9)),ISNUMBER(SEARCH(RIGHT(B27,1),$B$9))) -> FALSE | H27: =--D27+--E27+IF(AND(D27,E27),2,0)+--G27 -> 0 | I27: =IF(F27,B27,"") | J27: =IF(AND(F27,H27>=LARGE($H$20:$H$119,$B$10)),B27,"") | K27: =TRIM(K26&" "&I27) | L27: =TRIM(L26&" "&J27)
A28: 8 | B28: =TEXT(A28,"00") -> 08 | C28: =MOD(VALUE(LEFT(B28,1))+VALUE(RIGHT(B28,1)),10) -> 8 | D28: =AND($D$7="X",OR(ISNUMBER(SEARCH(LEFT(B28,1),$B$7)),ISNUMBER(SEARCH(RIGHT(B28,1),$B$7))),ISNUMBER(SEARCH(TEXT(C28,"0"),$C$7))) -> FALSE | E28: =AND($D$8="X",OR(ISNUMBER(SEARCH(LEFT(B28,1),$B$8)),ISNUMBER(SEARCH(RIGHT(B28,1),$B$8))),ISNUMBER(SEARCH(TEXT(C28,"0"),$C$8))) -> TRUE | F28: =OR(D28,E28) -> TRUE | G28: =OR(ISNUMBER(SEARCH(LEFT(B28,1),$B$9)),ISNUMBER(SEARCH(RIGHT(B28,1),$B$9))) -> FALSE | H28: =--D28+--E28+IF(AND(D28,E28),2,0)+--G28 -> 1 | I28: =IF(F28,B28,"") -> 08 | J28: =IF(AND(F28,H28>=LARGE($H$20:$H$119,$B$10)),B28,"") | K28: =TRIM(K27&" "&I28) -> 08 | L28: =TRIM(L27&" "&J28)
A29: 9 | B29: =TEXT(A29,"00") -> 09 | C29: =MOD(VALUE(LEFT(B29,1))+VALUE(RIGHT(B29,1)),10) -> 9 | D29: =AND($D$7="X",OR(ISNUMBER(SEARCH(LEFT(B29,1),$B$7)),ISNUMBER(SEARCH(RIGHT(B29,1),$B$7))),ISNUMBER(SEARCH(TEXT(C29,"0"),$C$7))) -> FALSE | E29: =AND($D$8="X",OR(ISNUMBER(SEARCH(LEFT(B29,1),$B$8)),ISNUMBER(SEARCH(RIGHT(B29,1),$B$8))),ISNUMBER(SEARCH(TEXT(C29,"0"),$C$8))) -> TRUE | F29: =OR(D29,E29) -> TRUE | G29: =OR(ISNUMBER(SEARCH(LEFT(B29,1),$B$9)),ISNUMBER(SEARCH(RIGHT(B29,1),$B$9))) -> FALSE | H29: =--D29+--E29+IF(AND(D29,E29),2,0)+--G29 -> 1 | I29: =IF(F29,B29,"") -> 09 | J29: =IF(AND(F29,H29>=LARGE($H$20:$H$119,$B$10)),B29,"") | K29: =TRIM(K28&" "&I29) -> 08 09 | L29: =TRIM(L28&" "&J29)
A30: 10 | B30: =TEXT(A30,"00") -> 10 | C30: =MOD(VALUE(LEFT(B30,1))+VALUE(RIGHT(B30,1)),10) -> 1 | D30: =AND($D$7="X",OR(ISNUMBER(SEARCH(LEFT(B30,1),$B$7)),ISNUMBER(SEARCH(RIGHT(B30,1),$B$7))),ISNUMBER(SEARCH(TEXT(C30,"0"),$C$7))) -> FALSE | E30: =AND($D$8="X",OR(ISNUMBER(SEARCH(LEFT(B30,1),$B$8)),ISNUMBER(SEARCH(RIGHT(B30,1),$B$8))),ISNUMBER(SEARCH(TEXT(C30,"0"),$C$8))) -> FALSE | F30: =OR(D30,E30) -> FALSE | G30: =OR(ISNUMBER(SEARCH(LEFT(B30,1),$B$9)),ISNUMBER(SEARCH(RIGHT(B30,1),$B$9))) -> TRUE | H30: =--D30+--E30+IF(AND(D30,E30),2,0)+--G30 -> 1 | I30: =IF(F30,B30,"") | J30: =IF(AND(F30,H30>=LARGE($H$20:$H$119,$B$10)),B30,"") | K30: =TRIM(K29&" "&I30) -> 08 09 | L30: =TRIM(L29&" "&J30)
A31: 11 | B31: =TEXT(A31,"00") -> 11 | C31: =MOD(VALUE(LEFT(B31,1))+VALUE(RIGHT(B31,1)),10) -> 2 | D31: =AND($D$7="X",OR(ISNUMBER(SEARCH(LEFT(B31,1),$B$7)),ISNUMBER(SEARCH(RIGHT(B31,1),$B$7))),ISNUMBER(SEARCH(TEXT(C31,"0"),$C$7))) -> FALSE | E31: =AND($D$8="X",OR(ISNUMBER(SEARCH(LEFT(B31,1),$B$8)),ISNUMBER(SEARCH(RIGHT(B31,1),$B$8))),ISNUMBER(SEARCH(TEXT(C31,"0"),$C$8))) -> FALSE | F31: =OR(D31,E31) -> FALSE | G31: =OR(ISNUMBER(SEARCH(LEFT(B31,1),$B$9)),ISNUMBER(SEARCH(RIGHT(B31,1),$B$9))) -> TRUE | H31: =--D31+--E31+IF(AND(D31,E31),2,0)+--G31 -> 1 | I31: =IF(F31,B31,"") | J31: =IF(AND(F31,H31>=LARGE($H$20:$H$119,$B$10)),B31,"") | K31: =TRIM(K30&" "&I31) -> 08 09 | L31: =TRIM(L30&" "&J31)
... A119: 99 | B119: =TEXT(A119,"00") -> 99 | C119: =MOD(VALUE(LEFT(B119,1))+VALUE(RIGHT(B119,1)),10) -> 8 | D119: =AND($D$7="X",OR(ISNUMBER(SEARCH(LEFT(B119,1),$B$7)),ISNUMBER(SEARCH(RIGHT(B119,1),$B$7))),ISNUMBER(SEARCH(TEXT(C119,"0"),$C$7))) -> FALSE | E119: =AND($D$8="X",OR(ISNUMBER(SEARCH(LEFT(B119,1),$B$8)),ISNUMBER(SEARCH(RIGHT(B119,1),$B$8))),ISNUMBER(SEARCH(TEXT(C119,"0"),$C$8))) -> TRUE | F119: =OR(D119,E119) -> TRUE | G119: =OR(ISNUMBER(SEARCH(LEFT(B119,1),$B$9)),ISNUMBER(SEARCH(RIGHT(B119,1),$B$9))) -> FALSE | H119: =--D119+--E119+IF(AND(D119,E119),2,0)+--G119 -> 1 | I119: =IF(F119,B119,"") -> 99 | J119: =IF(AND(F119,H119>=LARGE($H$20:$H$119,$B$10)),B119,"") | K119: =TRIM(K118&" "&I119) -> 08 09 17 18 26 27 29 35 36 38 45 47 49 53 54 56 58 62 63 65 67 71 72 74 76 80 81 83 85 90 92 94 99 | L119: =TRIM(L118&" "&J119) -> 17 18 26 27 29 35 36 38 53 56 62 63 65 67 71 72 76 81 83 92
D130: 3489

Sheet VI_TRI_GHEP
A1: VI_TRI_GHEP - VỊ TRÍ 3D/4D LẤY TỪ TUẦN TRƯỚC
A2: Tuần cần xem N sẽ lấy vị trí của tuần N-1. Công thức lấy theo DATA_NHAP.
A3: Tuần | B3: 3D-1 T2-P2 | C3: 3D-2 T3-P4 | D3: 3D-3 T4-P5 | E3: 3D-4 T5-P5 | F3: 3D-5 T6-P2 | G3: 3D-6 T7-P2 | H3: 4D-1 T3-P4 | I3: 4D-2 T7-P4 | J3: 4D-3 CN-P2 | K3: 4D-4 CN-P3 | L3: 4D-5 CN-P4
A4: 1 | B4: {=IFERROR(MID(INDEX(DATA_NHAP!$E:$E,MATCH($A4&"|2",DATA_NHAP!$I:$I,0)),2,1),"")} | C4: {=IFERROR(MID(INDEX(DATA_NHAP!$E:$E,MATCH($A4&"|3",DATA_NHAP!$I:$I,0)),4,1),"")} -> 7 | D4: {=IFERROR(MID(INDEX(DATA_NHAP!$E:$E,MATCH($A4&"|4",DATA_NHAP!$I:$I,0)),5,1),"")} -> 2 | E4: {=IFERROR(MID(INDEX(DATA_NHAP!$E:$E,MATCH($A4&"|5",DATA_NHAP!$I:$I,0)),5,1),"")} -> 5 | F4: {=IFERROR(MID(INDEX(DATA_NHAP!$E:$E,MATCH($A4&"|6",DATA_NHAP!$I:$I,0)),2,1),"")} -> 3 | G4: {=IFERROR(MID(INDEX(DATA_NHAP!$E:$E,MATCH($A4&"|7",DATA_NHAP!$I:$I,0)),2,1),"")} -> 8 | H4: {=IFERROR(MID(INDEX(DATA_NHAP!$E:$E,MATCH($A4&"|3",DATA_NHAP!$I:$I,0)),4,1),"")} -> 7 | I4: {=IFERROR(MID(INDEX(DATA_NHAP!$E:$E,MATCH($A4&"|7",DATA_NHAP!$I:$I,0)),4,1),"")} -> 8 | J4: {=IFERROR(MID(INDEX(DATA_NHAP!$E:$E,MATCH($A4&"|8",DATA_NHAP!$I:$I,0)),2,1),"")} -> 1 | K4: {=IFERROR(MID(INDEX(DATA_NHAP!$E:$E,MATCH($A4&"|8",DATA_NHAP!$I:$I,0)),3,1),"")} -> 1 | L4: {=IFERROR(MID(INDEX(DATA_NHAP!$E:$E,MATCH($A4&"|8",DATA_NHAP!$I:$I,0)),4,1),"")} -> 3
A5: 2 | B5: {=IFERROR(MID(INDEX(DATA_NHAP!$E:$E,MATCH($A5&"|2",DATA_NHAP!$I:$I,0)),2,1),"")} -> 3 | C5: {=IFERROR(MID(INDEX(DATA_NHAP!$E:$E,MATCH($A5&"|3",DATA_NHAP!$I:$I,0)),4,1),"")} -> 3 | D5: {=IFERROR(MID(INDEX(DATA_NHAP!$E:$E,MATCH($A5&"|4",DATA_NHAP!$I:$I,0)),5,1),"")} -> 3 | E5: {=IFERROR(MID(INDEX(DATA_NHAP!$E:$E,MATCH($A5&"|5",DATA_NHAP!$I:$I,0)),5,1),"")} -> 8 | F5: {=IFERROR(MID(INDEX(DATA_NHAP!$E:$E,MATCH($A5&"|6",DATA_NHAP!$I:$I,0)),2,1),"")} -> 4 | G5: {=IFERROR(MID(INDEX(DATA_NHAP!$E:$E,MATCH($A5&"|7",DATA_NHAP!$I:$I,0)),2,1),"")} -> 0 | H5: {=IFERROR(MID(INDEX(DATA_NHAP!$E:$E,MATCH($A5&"|3",DATA_NHAP!$I:$I,0)),4,1),"")} -> 3 | I5: {=IFERROR(MID(INDEX(DATA_NHAP!$E:$E,MATCH($A5&"|7",DATA_NHAP!$I:$I,0)),4,1),"")} -> 6 | J5: {=IFERROR(MID(INDEX(DATA_NHAP!$E:$E,MATCH($A5&"|8",DATA_NHAP!$I:$I,0)),2,1),"")} -> 5 | K5: {=IFERROR(MID(INDEX(DATA_NHAP!$E:$E,MATCH($A5&"|8",DATA_NHAP!$I:$I,0)),3,1),"")} -> 8 | L5: {=IFERROR(MID(INDEX(DATA_NHAP!$E:$E,MATCH($A5&"|8",DATA_NHAP!$I:$I,0)),4,1),"")} -> 1
A6: 3 | B6: {=IFERROR(MID(INDEX(DATA_NHAP!$E:$E,MATCH($A6&"|2",DATA_NHAP!$I:$I,0)),2,1),"")} -> 6 | C6: {=IFERROR(MID(INDEX(DATA_NHAP!$E:$E,MATCH($A6&"|3",DATA_NHAP!$I:$I,0)),4,1),"")} -> 4 | D6: {=IFERROR(MID(INDEX(DATA_NHAP!$E:$E,MATCH($A6&"|4",DATA_NHAP!$I:$I,0)),5,1),"")} -> 1 | E6: {=IFERROR(MID(INDEX(DATA_NHAP!$E:$E,MATCH($A6&"|5",DATA_NHAP!$I:$I,0)),5,1),"")} -> 5 | F6: {=IFERROR(MID(INDEX(DATA_NHAP!$E:$E,MATCH($A6&"|6",DATA_NHAP!$I:$I,0)),2,1),"")} -> 0 | G6: {=IFERROR(MID(INDEX(DATA_NHAP!$E:$E,MATCH($A6&"|7",DATA_NHAP!$I:$I,0)),2,1),"")} -> 1 | H6: {=IFERROR(MID(INDEX(DATA_NHAP!$E:$E,MATCH($A6&"|3",DATA_NHAP!$I:$I,0)),4,1),"")} -> 4 | I6: {=IFERROR(MID(INDEX(DATA_NHAP!$E:$E,MATCH($A6&"|7",DATA_NHAP!$I:$I,0)),4,1),"")} -> 7 | J6: {=IFERROR(MID(INDEX(DATA_NHAP!$E:$E,MATCH($A6&"|8",DATA_NHAP!$I:$I,0)),2,1),"")} -> 8 | K6: {=IFERROR(MID(INDEX(DATA_NHAP!$E:$E,MATCH($A6&"|8",DATA_NHAP!$I:$I,0)),3,1),"")} -> 2 | L6: {=IFERROR(MID(INDEX(DATA_NHAP!$E:$E,MATCH($A6&"|8",DATA_NHAP!$I:$I,0)),4,1),"")} -> 7
A7: 4 | B7: {=IFERROR(MID(INDEX(DATA_NHAP!$E:$E,MATCH($A7&"|2",DATA_NHAP!$I:$I,0)),2,1),"")} -> 5 | C7: {=IFERROR(MID(INDEX(DATA_NHAP!$E:$E,MATCH($A7&"|3",DATA_NHAP!$I:$I,0)),4,1),"")} -> 2 | D7: {=IFERROR(MID(INDEX(DATA_NHAP!$E:$E,MATCH($A7&"|4",DATA_NHAP!$I:$I,0)),5,1),"")} -> 6 | E7: {=IFERROR(MID(INDEX(DATA_NHAP!$E:$E,MATCH($A7&"|5",DATA_NHAP!$I:$I,0)),5,1),"")} -> 4 | F7: {=IFERROR(MID(INDEX(DATA_NHAP!$E:$E,MATCH($A7&"|6",DATA_NHAP!$I:$I,0)),2,1),"")} -> 8 | G7: {=IFERROR(MID(INDEX(DATA_NHAP!$E:$E,MATCH($A7&"|7",DATA_NHAP!$I:$I,0)),2,1),"")} -> 3 | H7: {=IFERROR(MID(INDEX(DATA_NHAP!$E:$E,MATCH($A7&"|3",DATA_NHAP!$I:$I,0)),4,1),"")} -> 2 | I7: {=IFERROR(MID(INDEX(DATA_NHAP!$E:$E,MATCH($A7&"|7",DATA_NHAP!$I:$I,0)),4,1),"")} -> 8 | J7: {=IFERROR(MID(INDEX(DATA_NHAP!$E:$E,MATCH($A7&"|8",DATA_NHAP!$I:$I,0)),2,1),"")} -> 3 | K7: {=IFERROR(MID(INDEX(DATA_NHAP!$E:$E,MATCH($A7&"|8",DATA_NHAP!$I:$I,0)),3,1),"")} -> 3 | L7: {=IFERROR(MID(INDEX(DATA_NHAP!$E:$E,MATCH($A7&"|8",DATA_NHAP!$I:$I,0)),4,1),"")} -> 0
A8: 5 | B8: {=IFERROR(MID(INDEX(DATA_NHAP!$E:$E,MATCH($A8&"|2",DATA_NHAP!$I:$I,0)),2,1),"")} -> 9 | C8: {=IFERROR(MID(INDEX(DATA_NHAP!$E:$E,MATCH($A8&"|3",DATA_NHAP!$I:$I,0)),4,1),"")} -> 6 | D8: {=IFERROR(MID(INDEX(DATA_NHAP!$E:$E,MATCH($A8&"|4",DATA_NHAP!$I:$I,0)),5,1),"")} -> 4 | E8: {=IFERROR(MID(INDEX(DATA_NHAP!$E:$E,MATCH($A8&"|5",DATA_NHAP!$I:$I,0)),5,1),"")} -> 2 | F8: {=IFERROR(MID(INDEX(DATA_NHAP!$E:$E,MATCH($A8&"|6",DATA_NHAP!$I:$I,0)),2,1),"")} | G8: {=IFERROR(MID(INDEX(DATA_NHAP!$E:$E,MATCH($A8&"|7",DATA_NHAP!$I:$I,0)),2,1),"")} | H8: {=IFERROR(MID(INDEX(DATA_NHAP!$E:$E,MATCH($A8&"|3",DATA_NHAP!$I:$I,0)),4,1),"")} -> 6 | I8: {=IFERROR(MID(INDEX(DATA_NHAP!$E:$E,MATCH($A8&"|7",DATA_NHAP!$I:$I,0)),4,1),"")} | J8: {=IFERROR(MID(INDEX(DATA_NHAP!$E:$E,MATCH($A8&"|8",DATA_NHAP!$I:$I,0)),2,1),"")} | K8: {=IFERROR(MID(INDEX(DATA_NHAP!$E:$E,MATCH($A8&"|8",DATA_NHAP!$I:$I,0)),3,1),"")} | L8: {=IFERROR(MID(INDEX(DATA_NHAP!$E:$E,MATCH($A8&"|8",DATA_NHAP!$I:$I,0)),4,1),"")}
A9: 6 | B9: {=IFERROR(MID(INDEX(DATA_NHAP!$E:$E,MATCH($A9&"|2",DATA_NHAP!$I:$I,0)),2,1),"")} | C9: {=IFERROR(MID(INDEX(DATA_NHAP!$E:$E,MATCH($A9&"|3",DATA_NHAP!$I:$I,0)),4,1),"")} -> 0 | D9: {=IFERROR(MID(INDEX(DATA_NHAP!$E:$E,MATCH($A9&"|4",DATA_NHAP!$I:$I,0)),5,1),"")} -> 0 | E9: {=IFERROR(MID(INDEX(DATA_NHAP!$E:$E,MATCH($A9&"|5",DATA_NHAP!$I:$I,0)),5,1),"")} -> 1 | F9: {=IFERROR(MID(INDEX(DATA_NHAP!$E:$E,MATCH($A9&"|6",DATA_NHAP!$I:$I,0)),2,1),"")} | G9: {=IFERROR(MID(INDEX(DATA_NHAP!$E:$E,MATCH($A9&"|7",DATA_NHAP!$I:$I,0)),2,1),"")} | H9: {=IFERROR(MID(INDEX(DATA_NHAP!$E:$E,MATCH($A9&"|3",DATA_NHAP!$I:$I,0)),4,1),"")} -> 0 | I9: {=IFERROR(MID(INDEX(DATA_NHAP!$E:$E,MATCH($A9&"|7",DATA_NHAP!$I:$I,0)),4,1),"")} | J9: {=IFERROR(MID(INDEX(DATA_NHAP!$E:$E,MATCH($A9&"|8",DATA_NHAP!$I:$I,0)),2,1),"")} | K9: {=IFERROR(MID(INDEX(DATA_NHAP!$E:$E,MATCH($A9&"|8",DATA_NHAP!$I:$I,0)),3,1),"")} | L9: {=IFERROR(MID(INDEX(DATA_NHAP!$E:$E,MATCH($A9&"|8",DATA_NHAP!$I:$I,0)),4,1),"")}
A10: 7 | B10: {=IFERROR(MID(INDEX(DATA_NHAP!$E:$E,MATCH($A10&"|2",DATA_NHAP!$I:$I,0)),2,1),"")} | C10: {=IFERROR(MID(INDEX(DATA_NHAP!$E:$E,MATCH($A10&"|3",DATA_NHAP!$I:$I,0)),4,1),"")} -> 0 | D10: {=IFERROR(MID(INDEX(DATA_NHAP!$E:$E,MATCH($A10&"|4",DATA_NHAP!$I:$I,0)),5,1),"")} -> 7 | E10: {=IFERROR(MID(INDEX(DATA_NHAP!$E:$E,MATCH($A10&"|5",DATA_NHAP!$I:$I,0)),5,1),"")} -> 8 | F10: {=IFERROR(MID(INDEX(DATA_NHAP!$E:$E,MATCH($A10&"|6",DATA_NHAP!$I:$I,0)),2,1),"")} -> 6 | G10: {=IFERROR(MID(INDEX(DATA_NHAP!$E:$E,MATCH($A10&"|7",DATA_NHAP!$I:$I,0)),2,1),"")} -> 7 | H10: {=IFERROR(MID(INDEX(DATA_NHAP!$E:$E,MATCH($A10&"|3",DATA_NHAP!$I:$I,0)),4,1),"")} -> 0 | I10: {=IFERROR(MID(INDEX(DATA_NHAP!$E:$E,MATCH($A10&"|7",DATA_NHAP!$I:$I,0)),4,1),"")} -> 3 | J10: {=IFERROR(MID(INDEX(DATA_NHAP!$E:$E,MATCH($A10&"|8",DATA_NHAP!$I:$I,0)),2,1),"")} -> 5 | K10: {=IFERROR(MID(INDEX(DATA_NHAP!$E:$E,MATCH($A10&"|8",DATA_NHAP!$I:$I,0)),3,1),"")} -> 5 | L10: {=IFERROR(MID(INDEX(DATA_NHAP!$E:$E,MATCH($A10&"|8",DATA_NHAP!$I:$I,0)),4,1),"")} -> 4
A11: 8 | B11: {=IFERROR(MID(INDEX(DATA_NHAP!$E:$E,MATCH($A11&"|2",DATA_NHAP!$I:$I,0)),2,1),"")} -> 7 | C11: {=IFERROR(MID(INDEX(DATA_NHAP!$E:$E,MATCH($A11&"|3",DATA_NHAP!$I:$I,0)),4,1),"")} -> 0 | D11: {=IFERROR(MID(INDEX(DATA_NHAP!$E:$E,MATCH($A11&"|4",DATA_NHAP!$I:$I,0)),5,1),"")} -> 5 | E11: {=IFERROR(MID(INDEX(DATA_NHAP!$E:$E,MATCH($A11&"|5",DATA_NHAP!$I:$I,0)),5,1),"")} -> 8 | F11: {=IFERROR(MID(INDEX(DATA_NHAP!$E:$E,MATCH($A11&"|6",DATA_NHAP!$I:$I,0)),2,1),"")} -> 1 | G11: {=IFERROR(MID(INDEX(DATA_NHAP!$E:$E,MATCH($A11&"|7",DATA_NHAP!$I:$I,0)),2,1),"")} -> 7 | H11: {=IFERROR(MID(INDEX(DATA_NHAP!$E:$E,MATCH($A11&"|3",DATA_NHAP!$I:$I,0)),4,1),"")} -> 0 | I11: {=IFERROR(MID(INDEX(DATA_NHAP!$E:$E,MATCH($A11&"|7",DATA_NHAP!$I:$I,0)),4,1),"")} -> 3 | J11: {=IFERROR(MID(INDEX(DATA_NHAP!$E:$E,MATCH($A11&"|8",DATA_NHAP!$I:$I,0)),2,1),"")} -> 7 | K11: {=IFERROR(MID(INDEX(DATA_NHAP!$E:$E,MATCH($A11&"|8",DATA_NHAP!$I:$I,0)),3,1),"")} -> 6 | L11: {=IFERROR(MID(INDEX(DATA_NHAP!$E:$E,MATCH($A11&"|8",DATA_NHAP!$I:$I,0)),4,1),"")} -> 3
A12: 9 | B12: {=IFERROR(MID(INDEX(DATA_NHAP!$E:$E,MATCH($A12&"|2",DATA_NHAP!$I:$I,0)),2,1),"")} -> 8 | C12: {=IFERROR(MID(INDEX(DATA_NHAP!$E:$E,MATCH($A12&"|3",DATA_NHAP!$I:$I,0)),4,1),"")} -> 2 | D12: {=IFERROR(MID(INDEX(DATA_NHAP!$E:$E,MATCH($A12&"|4",DATA_NHAP!$I:$I,0)),5,1),"")} -> 9 | E12: {=IFERROR(MID(INDEX(DATA_NHAP!$E:$E,MATCH($A12&"|5",DATA_NHAP!$I:$I,0)),5,1),"")} -> 7 | F12: {=IFERROR(MID(INDEX(DATA_NHAP!$E:$E,MATCH($A12&"|6",DATA_NHAP!$I:$I,0)),2,1),"")} -> 1 | G12: {=IFERROR(MID(INDEX(DATA_NHAP!$E:$E,MATCH($A12&"|7",DATA_NHAP!$I:$I,0)),2,1),"")} -> 7 | H12: {=IFERROR(MID(INDEX(DATA_NHAP!$E:$E,MATCH($A12&"|3",DATA_NHAP!$I:$I,0)),4,1),"")} -> 2 | I12: {=IFERROR(MID(INDEX(DATA_NHAP!$E:$E,MATCH($A12&"|7",DATA_NHAP!$I:$I,0)),4,1),"")} -> 4 | J12: {=IFERROR(MID(INDEX(DATA_NHAP!$E:$E,MATCH($A12&"|8",DATA_NHAP!$I:$I,0)),2,1),"")} -> 8 | K12: {=IFERROR(MID(INDEX(DATA_NHAP!$E:$E,MATCH($A12&"|8",DATA_NHAP!$I:$I,0)),3,1),"")} -> 3 | L12: {=IFERROR(MID(INDEX(DATA_NHAP!$E:$E,MATCH($A12&"|8",DATA_NHAP!$I:$I,0)),4,1),"")} -> 5
A13: 10 | B13: {=IFERROR(MID(INDEX(DATA_NHAP!$E:$E,MATCH($A13&"|2",DATA_NHAP!$I:$I,0)),2,1),"")} -> 8 | C13: {=IFERROR(MID(INDEX(DATA_NHAP!$E:$E,MATCH($A13&"|3",DATA_NHAP!$I:$I,0)),4,1),"")} -> 1 | D13: {=IFERROR(MID(INDEX(DATA_NHAP!$E:$E,MATCH($A13&"|4",DATA_NHAP!$I:$I,0)),5,1),"")} -> 3 | E13: {=IFERROR(MID(INDEX(DATA_NHAP!$E:$E,MATCH($A13&"|5",DATA_NHAP!$I:$I,0)),5,1),"")} -> 9 | F13: {=IFERROR(MID(INDEX(DATA_NHAP!$E:$E,MATCH($A13&"|6",DATA_NHAP!$I:$I,0)),2,1),"")} -> 2 | G13: {=IFERROR(MID(INDEX(DATA_NHAP!$E:$E,MATCH($A13&"|7",DATA_NHAP!$I:$I,0)),2,1),"")} -> 5 | H13: {=IFERROR(MID(INDEX(DATA_NHAP!$E:$E,MATCH($A13&"|3",DATA_NHAP!$I:$I,0)),4,1),"")} -> 1 | I13: {=IFERROR(MID(INDEX(DATA_NHAP!$E:$E,MATCH($A13&"|7",DATA_NHAP!$I:$I,0)),4,1),"")} -> 6 | J13: {=IFERROR(MID(INDEX(DATA_NHAP!$E:$E,MATCH($A13&"|8",DATA_NHAP!$I:$I,0)),2,1),"")} -> 9 | K13: {=IFERROR(MID(INDEX(DATA_NHAP!$E:$E,MATCH($A13&"|8",DATA_NHAP!$I:$I,0)),3,1),"")} -> 3 | L13: {=IFERROR(MID(INDEX(DATA_NHAP!$E:$E,MATCH($A13&"|8",DATA_NHAP!$I:$I,0)),4,1),"")} -> 9
A14: 11 | B14: {=IFERROR(MID(INDEX(DATA_NHAP!$E:$E,MATCH($A14&"|2",DATA_NHAP!$I:$I,0)),2,1),"")} -> 8 | C14: {=IFERROR(MID(INDEX(DATA_NHAP!$E:$E,MATCH($A14&"|3",DATA_NHAP!$I:$I,0)),4,1),"")} -> 3 | D14: {=IFERROR(MID(INDEX(DATA_NHAP!$E:$E,MATCH($A14&"|4",DATA_NHAP!$I:$I,0)),5,1),"")} -> 4 | E14: {=IFERROR(MID(INDEX(DATA_NHAP!$E:$E,MATCH($A14&"|5",DATA_NHAP!$I:$I,0)),5,1),"")} -> 6 | F14: {=IFERROR(MID(INDEX(DATA_NHAP!$E:$E,MATCH($A14&"|6",DATA_NHAP!$I:$I,0)),2,1),"")} -> 5 | G14: {=IFERROR(MID(INDEX(DATA_NHAP!$E:$E,MATCH($A14&"|7",DATA_NHAP!$I:$I,0)),2,1),"")} -> 9 | H14: {=IFERROR(MID(INDEX(DATA_NHAP!$E:$E,MATCH($A14&"|3",DATA_NHAP!$I:$I,0)),4,1),"")} -> 3 | I14: {=IFERROR(MID(INDEX(DATA_NHAP!$E:$E,MATCH($A14&"|7",DATA_NHAP!$I:$I,0)),4,1),"")} -> 8 | J14: {=IFERROR(MID(INDEX(DATA_NHAP!$E:$E,MATCH($A14&"|8",DATA_NHAP!$I:$I,0)),2,1),"")} -> 8 | K14: {=IFERROR(MID(INDEX(DATA_NHAP!$E:$E,MATCH($A14&"|8",DATA_NHAP!$I:$I,0)),3,1),"")} -> 2 | L14: {=IFERROR(MID(INDEX(DATA_NHAP!$E:$E,MATCH($A14&"|8",DATA_NHAP!$I:$I,0)),4,1),"")} -> 7
A15: 12 | B15: {=IFERROR(MID(INDEX(DATA_NHAP!$E:$E,MATCH($A15&"|2",DATA_NHAP!$I:$I,0)),2,1),"")} -> 6 | C15: {=IFERROR(MID(INDEX(DATA_NHAP!$E:$E,MATCH($A15&"|3",DATA_NHAP!$I:$I,0)),4,1),"")} -> 1 | D15: {=IFERROR(MID(INDEX(DATA_NHAP!$E:$E,MATCH($A15&"|4",DATA_NHAP!$I:$I,0)),5,1),"")} -> 5 | E15: {=IFERROR(MID(INDEX(DATA_NHAP!$E:$E,MATCH($A15&"|5",DATA_NHAP!$I:$I,0)),5,1),"")} -> 9 | F15: {=IFERROR(MID(INDEX(DATA_NHAP!$E:$E,MATCH($A15&"|6",DATA_NHAP!$I:$I,0)),2,1),"")} -> 7 | G15: {=IFERROR(MID(INDEX(DATA_NHAP!$E:$E,MATCH($A15&"|7",DATA_NHAP!$I:$I,0)),2,1),"")} -> 2 | H15: {=IFERROR(MID(INDEX(DATA_NHAP!$E:$E,MATCH($A15&"|3",DATA_NHAP!$I:$I,0)),4,1),"")} -> 1 | I15: {=IFERROR(MID(INDEX(DATA_NHAP!$E:$E,MATCH($A15&"|7",DATA_NHAP!$I:$I,0)),4,1),"")} -> 3 | J15: {=IFERROR(MID(INDEX(DATA_NHAP!$E:$E,MATCH($A15&"|8",DATA_NHAP!$I:$I,0)),2,1),"")} -> 6 | K15: {=IFERROR(MID(INDEX(DATA_NHAP!$E:$E,MATCH($A15&"|8",DATA_NHAP!$I:$I,0)),3,1),"")} -> 9 | L15: {=IFERROR(MID(INDEX(DATA_NHAP!$E:$E,MATCH($A15&"|8",DATA_NHAP!$I:$I,0)),4,1),"")} -> 0
... A323: 320 | B323: {=IFERROR(MID(INDEX(DATA_NHAP!$E:$E,MATCH($A323&"|2",DATA_NHAP!$I:$I,0)),2,1),"")} | C323: {=IFERROR(MID(INDEX(DATA_NHAP!$E:$E,MATCH($A323&"|3",DATA_NHAP!$I:$I,0)),4,1),"")} | D323: {=IFERROR(MID(INDEX(DATA_NHAP!$E:$E,MATCH($A323&"|4",DATA_NHAP!$I:$I,0)),5,1),"")} | E323: {=IFERROR(MID(INDEX(DATA_NHAP!$E:$E,MATCH($A323&"|5",DATA_NHAP!$I:$I,0)),5,1),"")} | F323: {=IFERROR(MID(INDEX(DATA_NHAP!$E:$E,MATCH($A323&"|6",DATA_NHAP!$I:$I,0)),2,1),"")} | G323: {=IFERROR(MID(INDEX(DATA_NHAP!$E:$E,MATCH($A323&"|7",DATA_NHAP!$I:$I,0)),2,1),"")} | H323: {=IFERROR(MID(INDEX(DATA_NHAP!$E:$E,MATCH($A323&"|3",DATA_NHAP!$I:$I,0)),4,1),"")} | I323: {=IFERROR(MID(INDEX(DATA_NHAP!$E:$E,MATCH($A323&"|7",DATA_NHAP!$I:$I,0)),4,1),"")} | J323: {=IFERROR(MID(INDEX(DATA_NHAP!$E:$E,MATCH($A323&"|8",DATA_NHAP!$I:$I,0)),2,1),"")} | K323: {=IFERROR(MID(INDEX(DATA_NHAP!$E:$E,MATCH($A323&"|8",DATA_NHAP!$I:$I,0)),3,1),"")} | L323: {=IFERROR(MID(INDEX(DATA_NHAP!$E:$E,MATCH($A323&"|8",DATA_NHAP!$I:$I,0)),4,1),"")}

Sheet DONG_THUAN_GHEP
A1: DONG_THUAN_GHEP - GHÉP 3D/4D THEO VỊ TRÍ TUẦN TRƯỚC
A3: Tuần cần xem | B3: =LOC_COPY!B3 -> 137 | D3: Tuần lấy vị trí | E3: =B3-1 -> 136
A5: Dàn 2D nguồn | B5: =LOC_COPY!B13 -> 08 09 17 18 26 27 29 35 36 38 45 47 49 53 54 56 58 62 63 65 67 71 72 74 76 80 81 83 85 90 92 94 99
A6: Dàn 2D nổi bật | B6: =LOC_COPY!B14 -> 17 18 26 27 29 35 36 38 53 56 62 63 65 67 71 72 76 81 83 92
B8: 3D-1 | C8: 3D-2 | D8: 3D-3 | E8: 3D-4 | F8: 3D-5 | G8: 3D-6 | I8: 4D-1 | J8: 4D-2 | K8: 4D-3 | L8: 4D-4 | M8: 4D-5
B9: {=IFERROR(INDEX(VI_TRI_GHEP!$B:$G,MATCH($E$3,VI_TRI_GHEP!$A:$A,0),1),"")} -> 9 | C9: {=IFERROR(INDEX(VI_TRI_GHEP!$B:$G,MATCH($E$3,VI_TRI_GHEP!$A:$A,0),2),"")} -> 2 | D9: {=IFERROR(INDEX(VI_TRI_GHEP!$B:$G,MATCH($E$3,VI_TRI_GHEP!$A:$A,0),3),"")} | E9: {=IFERROR(INDEX(VI_TRI_GHEP!$B:$G,MATCH($E$3,VI_TRI_GHEP!$A:$A,0),4),"")} | F9: {=IFERROR(INDEX(VI_TRI_GHEP!$B:$G,MATCH($E$3,VI_TRI_GHEP!$A:$A,0),5),"")} | G9: {=IFERROR(INDEX(VI_TRI_GHEP!$B:$G,MATCH($E$3,VI_TRI_GHEP!$A:$A,0),6),"")} | I9: {=IFERROR(INDEX(VI_TRI_GHEP!$H:$L,MATCH($E$3,VI_TRI_GHEP!$A:$A,0),1),"")} -> 2 | J9: {=IFERROR(INDEX(VI_TRI_GHEP!$H:$L,MATCH($E$3,VI_TRI_GHEP!$A:$A,0),2),"")} | K9: {=IFERROR(INDEX(VI_TRI_GHEP!$H:$L,MATCH($E$3,VI_TRI_GHEP!$A:$A,0),3),"")} | L9: {=IFERROR(INDEX(VI_TRI_GHEP!$H:$L,MATCH($E$3,VI_TRI_GHEP!$A:$A,0),4),"")} | M9: {=IFERROR(INDEX(VI_TRI_GHEP!$H:$L,MATCH($E$3,VI_TRI_GHEP!$A:$A,0),5),"")}
A13: 2D | B13: Điểm 2D | C13: 3D-1 | D13: 3D-2 | E13: 3D-3 | F13: 3D-4 | G13: 3D-5 | H13: 3D-6 | I13: Dàn 3D | J13: 4D1-1 | K13: 4D1-2 | L13: 4D1-3 | M13: 4D1-4 | N13: 4D1-5 | O13: 4D1-6 | P13: 4D2-1 | Q13: 4D2-2 | R13: 4D2-3 | S13: 4D2-4 | T13: 4D2-5 | U13: 4D2-6 | V13: 4D3-1 | W13: 4D3-2 | X13: 4D3-3 | Y13: 4D3-4 | Z13: 4D3-5 | AA13: 4D3-6 | AB13: 4D4-1 | AC13: 4D4-2 | AD13: 4D4-3 | AE13: 4D4-4 | AF13: 4D4-5 | AG13: 4D4-6 | AH13: 4D5-1 | AI13: 4D5-2 | AJ13: 4D5-3 | AK13: 4D5-4 | AL13: 4D5-5 | AM13: 4D5-6
A14: =LOC_COPY!I20 | B14: =IF(A14="","",LOC_COPY!H20) | C14: =IF($A14="","",B$9&$A14) | D14: =IF($A14="","",C$9&$A14) | E14: =IF($A14="","",D$9&$A14) | F14: =IF($A14="","",E$9&$A14) | G14: =IF($A14="","",F$9&$A14) | H14: =IF($A14="","",G$9&$A14) | I14: =TRIM(C14&" "&D14&" "&E14&" "&F14&" "&G14&" "&H14) | J14: =IF(C14="","",I$9&C14) | K14: =IF(D14="","",I$9&D14) | L14: =IF(E14="","",I$9&E14) | M14: =IF(F14="","",I$9&F14) | N14: =IF(G14="","",I$9&G14) | O14: =IF(H14="","",I$9&H14) | P14: =IF(C14="","",J$9&C14) | Q14: =IF(D14="","",J$9&D14) | R14: =IF(E14="","",J$9&E14) | S14: =IF(F14="","",J$9&F14) | T14: =IF(G14="","",J$9&G14) | U14: =IF(H14="","",J$9&H14) | V14: =IF(C14="","",K$9&C14) | W14: =IF(D14="","",K$9&D14) | X14: =IF(E14="","",K$9&E14) | Y14: =IF(F14="","",K$9&F14) | Z14: =IF(G14="","",K$9&G14) | AA14: =IF(H14="","",K$9&H14) | AB14: =IF(C14="","",L$9&C14) | AC14: =IF(D14="","",L$9&D14) | AD14: =IF(E14="","",L$9&E14) | AE14: =IF(F14="","",L$9&F14) | AF14: =IF(G14="","",L$9&G14) | AG14: =IF(H14="","",L$9&H14) | AH14: =IF(C14="","",M$9&C14) | AI14: =IF(D14="","",M$9&D14) | AJ14: =IF(E14="","",M$9&E14) | AK14: =IF(F14="","",M$9&F14) | AL14: =IF(G14="","",M$9&G14) | AM14: =IF(H14="","",M$9&H14)
A15: =LOC_COPY!I21 | B15: =IF(A15="","",LOC_COPY!H21) | C15: =IF($A15="","",B$9&$A15) | D15: =IF($A15="","",C$9&$A15) | E15: =IF($A15="","",D$9&$A15) | F15: =IF($A15="","",E$9&$A15) | G15: =IF($A15="","",F$9&$A15) | H15: =IF($A15="","",G$9&$A15) | I15: =TRIM(C15&" "&D15&" "&E15&" "&F15&" "&G15&" "&H15) | J15: =IF(C15="","",I$9&C15) | K15: =IF(D15="","",I$9&D15) | L15: =IF(E15="","",I$9&E15) | M15: =IF(F15="","",I$9&F15) | N15: =IF(G15="","",I$9&G15) | O15: =IF(H15="","",I$9&H15) | P15: =IF(C15="","",J$9&C15) | Q15: =IF(D15="","",J$9&D15) | R15: =IF(E15="","",J$9&E15) | S15: =IF(F15="","",J$9&F15) | T15: =IF(G15="","",J$9&G15) | U15: =IF(H15="","",J$9&H15) | V15: =IF(C15="","",K$9&C15) | W15: =IF(D15="","",K$9&D15) | X15: =IF(E15="","",K$9&E15) | Y15: =IF(F15="","",K$9&F15) | Z15: =IF(G15="","",K$9&G15) | AA15: =IF(H15="","",K$9&H15) | AB15: =IF(C15="","",L$9&C15) | AC15: =IF(D15="","",L$9&D15) | AD15: =IF(E15="","",L$9&E15) | AE15: =IF(F15="","",L$9&F15) | AF15: =IF(G15="","",L$9&G15) | AG15: =IF(H15="","",L$9&H15) | AH15: =IF(C15="","",M$9&C15) | AI15: =IF(D15="","",M$9&D15) | AJ15: =IF(E15="","",M$9&E15) | AK15: =IF(F15="","",M$9&F15) | AL15: =IF(G15="","",M$9&G15) | AM15: =IF(H15="","",M$9&H15)
A16: =LOC_COPY!I22 | B16: =IF(A16="","",LOC_COPY!H22) | C16: =IF($A16="","",B$9&$A16) | D16: =IF($A16="","",C$9&$A16) | E16: =IF($A16="","",D$9&$A16) | F16: =IF($A16="","",E$9&$A16) | G16: =IF($A16="","",F$9&$A16) | H16: =IF($A16="","",G$9&$A16) | I16: =TRIM(C16&" "&D16&" "&E16&" "&F16&" "&G16&" "&H16) | J16: =IF(C16="","",I$9&C16) | K16: =IF(D16="","",I$9&D16) | L16: =IF(E16="","",I$9&E16) | M16: =IF(F16="","",I$9&F16) | N16: =IF(G16="","",I$9&G16) | O16: =IF(H16="","",I$9&H16) | P16: =IF(C16="","",J$9&C16) | Q16: =IF(D16="","",J$9&D16) | R16: =IF(E16="","",J$9&E16) | S16: =IF(F16="","",J$9&F16) | T16: =IF(G16="","",J$9&G16) | U16: =IF(H16="","",J$9&H16) | V16: =IF(C16="","",K$9&C16) | W16: =IF(D16="","",K$9&D16) | X16: =IF(E16="","",K$9&E16) | Y16: =IF(F16="","",K$9&F16) | Z16: =IF(G16="","",K$9&G16) | AA16: =IF(H16="","",K$9&H16) | AB16: =IF(C16="","",L$9&C16) | AC16: =IF(D16="","",L$9&D16) | AD16: =IF(E16="","",L$9&E16) | AE16: =IF(F16="","",L$9&F16) | AF16: =IF(G16="","",L$9&G16) | AG16: =IF(H16="","",L$9&H16) | AH16: =IF(C16="","",M$9&C16) | AI16: =IF(D16="","",M$9&D16) | AJ16: =IF(E16="","",M$9&E16) | AK16: =IF(F16="","",M$9&F16) | AL16: =IF(G16="","",M$9&G16) | AM16: =IF(H16="","",M$9&H16)
A17: =LOC_COPY!I23 | B17: =IF(A17="","",LOC_COPY!H23) | C17: =IF($A17="","",B$9&$A17) | D17: =IF($A17="","",C$9&$A17) | E17: =IF($A17="","",D$9&$A17) | F17: =IF($A17="","",E$9&$A17) | G17: =IF($A17="","",F$9&$A17) | H17: =IF($A17="","",G$9&$A17) | I17: =TRIM(C17&" "&D17&" "&E17&" "&F17&" "&G17&" "&H17) | J17: =IF(C17="","",I$9&C17) | K17: =IF(D17="","",I$9&D17) | L17: =IF(E17="","",I$9&E17) | M17: =IF(F17="","",I$9&F17) | N17: =IF(G17="","",I$9&G17) | O17: =IF(H17="","",I$9&H17) | P17: =IF(C17="","",J$9&C17) | Q17: =IF(D17="","",J$9&D17) | R17: =IF(E17="","",J$9&E17) | S17: =IF(F17="","",J$9&F17) | T17: =IF(G17="","",J$9&G17) | U17: =IF(H17="","",J$9&H17) | V17: =IF(C17="","",K$9&C17) | W17: =IF(D17="","",K$9&D17) | X17: =IF(E17="","",K$9&E17) | Y17: =IF(F17="","",K$9&F17) | Z17: =IF(G17="","",K$9&G17) | AA17: =IF(H17="","",K$9&H17) | AB17: =IF(C17="","",L$9&C17) | AC17: =IF(D17="","",L$9&D17) | AD17: =IF(E17="","",L$9&E17) | AE17: =IF(F17="","",L$9&F17) | AF17: =IF(G17="","",L$9&G17) | AG17: =IF(H17="","",L$9&H17) | AH17: =IF(C17="","",M$9&C17) | AI17: =IF(D17="","",M$9&D17) | AJ17: =IF(E17="","",M$9&E17) | AK17: =IF(F17="","",M$9&F17) | AL17: =IF(G17="","",M$9&G17) | AM17: =IF(H17="","",M$9&H17)
A18: =LOC_COPY!I24 | B18: =IF(A18="","",LOC_COPY!H24) | C18: =IF($A18="","",B$9&$A18) | D18: =IF($A18="","",C$9&$A18) | E18: =IF($A18="","",D$9&$A18) | F18: =IF($A18="","",E$9&$A18) | G18: =IF($A18="","",F$9&$A18) | H18: =IF($A18="","",G$9&$A18) | I18: =TRIM(C18&" "&D18&" "&E18&" "&F18&" "&G18&" "&H18) | J18: =IF(C18="","",I$9&C18) | K18: =IF(D18="","",I$9&D18) | L18: =IF(E18="","",I$9&E18) | M18: =IF(F18="","",I$9&F18) | N18: =IF(G18="","",I$9&G18) | O18: =IF(H18="","",I$9&H18) | P18: =IF(C18="","",J$9&C18) | Q18: =IF(D18="","",J$9&D18) | R18: =IF(E18="","",J$9&E18) | S18: =IF(F18="","",J$9&F18) | T18: =IF(G18="","",J$9&G18) | U18: =IF(H18="","",J$9&H18) | V18: =IF(C18="","",K$9&C18) | W18: =IF(D18="","",K$9&D18) | X18: =IF(E18="","",K$9&E18) | Y18: =IF(F18="","",K$9&F18) | Z18: =IF(G18="","",K$9&G18) | AA18: =IF(H18="","",K$9&H18) | AB18: =IF(C18="","",L$9&C18) | AC18: =IF(D18="","",L$9&D18) | AD18: =IF(E18="","",L$9&E18) | AE18: =IF(F18="","",L$9&F18) | AF18: =IF(G18="","",L$9&G18) | AG18: =IF(H18="","",L$9&H18) | AH18: =IF(C18="","",M$9&C18) | AI18: =IF(D18="","",M$9&D18) | AJ18: =IF(E18="","",M$9&E18) | AK18: =IF(F18="","",M$9&F18) | AL18: =IF(G18="","",M$9&G18) | AM18: =IF(H18="","",M$9&H18)
A19: =LOC_COPY!I25 | B19: =IF(A19="","",LOC_COPY!H25) | C19: =IF($A19="","",B$9&$A19) | D19: =IF($A19="","",C$9&$A19) | E19: =IF($A19="","",D$9&$A19) | F19: =IF($A19="","",E$9&$A19) | G19: =IF($A19="","",F$9&$A19) | H19: =IF($A19="","",G$9&$A19) | I19: =TRIM(C19&" "&D19&" "&E19&" "&F19&" "&G19&" "&H19) | J19: =IF(C19="","",I$9&C19) | K19: =IF(D19="","",I$9&D19) | L19: =IF(E19="","",I$9&E19) | M19: =IF(F19="","",I$9&F19) | N19: =IF(G19="","",I$9&G19) | O19: =IF(H19="","",I$9&H19) | P19: =IF(C19="","",J$9&C19) | Q19: =IF(D19="","",J$9&D19) | R19: =IF(E19="","",J$9&E19) | S19: =IF(F19="","",J$9&F19) | T19: =IF(G19="","",J$9&G19) | U19: =IF(H19="","",J$9&H19) | V19: =IF(C19="","",K$9&C19) | W19: =IF(D19="","",K$9&D19) | X19: =IF(E19="","",K$9&E19) | Y19: =IF(F19="","",K$9&F19) | Z19: =IF(G19="","",K$9&G19) | AA19: =IF(H19="","",K$9&H19) | AB19: =IF(C19="","",L$9&C19) | AC19: =IF(D19="","",L$9&D19) | AD19: =IF(E19="","",L$9&E19) | AE19: =IF(F19="","",L$9&F19) | AF19: =IF(G19="","",L$9&G19) | AG19: =IF(H19="","",L$9&H19) | AH19: =IF(C19="","",M$9&C19) | AI19: =IF(D19="","",M$9&D19) | AJ19: =IF(E19="","",M$9&E19) | AK19: =IF(F19="","",M$9&F19) | AL19: =IF(G19="","",M$9&G19) | AM19: =IF(H19="","",M$9&H19)
A20: =LOC_COPY!I26 | B20: =IF(A20="","",LOC_COPY!H26) | C20: =IF($A20="","",B$9&$A20) | D20: =IF($A20="","",C$9&$A20) | E20: =IF($A20="","",D$9&$A20) | F20: =IF($A20="","",E$9&$A20) | G20: =IF($A20="","",F$9&$A20) | H20: =IF($A20="","",G$9&$A20) | I20: =TRIM(C20&" "&D20&" "&E20&" "&F20&" "&G20&" "&H20) | J20: =IF(C20="","",I$9&C20) | K20: =IF(D20="","",I$9&D20) | L20: =IF(E20="","",I$9&E20) | M20: =IF(F20="","",I$9&F20) | N20: =IF(G20="","",I$9&G20) | O20: =IF(H20="","",I$9&H20) | P20: =IF(C20="","",J$9&C20) | Q20: =IF(D20="","",J$9&D20) | R20: =IF(E20="","",J$9&E20) | S20: =IF(F20="","",J$9&F20) | T20: =IF(G20="","",J$9&G20) | U20: =IF(H20="","",J$9&H20) | V20: =IF(C20="","",K$9&C20) | W20: =IF(D20="","",K$9&D20) | X20: =IF(E20="","",K$9&E20) | Y20: =IF(F20="","",K$9&F20) | Z20: =IF(G20="","",K$9&G20) | AA20: =IF(H20="","",K$9&H20) | AB20: =IF(C20="","",L$9&C20) | AC20: =IF(D20="","",L$9&D20) | AD20: =IF(E20="","",L$9&E20) | AE20: =IF(F20="","",L$9&F20) | AF20: =IF(G20="","",L$9&G20) | AG20: =IF(H20="","",L$9&H20) | AH20: =IF(C20="","",M$9&C20) | AI20: =IF(D20="","",M$9&D20) | AJ20: =IF(E20="","",M$9&E20) | AK20: =IF(F20="","",M$9&F20) | AL20: =IF(G20="","",M$9&G20) | AM20: =IF(H20="","",M$9&H20)
A21: =LOC_COPY!I27 | B21: =IF(A21="","",LOC_COPY!H27) | C21: =IF($A21="","",B$9&$A21) | D21: =IF($A21="","",C$9&$A21) | E21: =IF($A21="","",D$9&$A21) | F21: =IF($A21="","",E$9&$A21) | G21: =IF($A21="","",F$9&$A21) | H21: =IF($A21="","",G$9&$A21) | I21: =TRIM(C21&" "&D21&" "&E21&" "&F21&" "&G21&" "&H21) | J21: =IF(C21="","",I$9&C21) | K21: =IF(D21="","",I$9&D21) | L21: =IF(E21="","",I$9&E21) | M21: =IF(F21="","",I$9&F21) | N21: =IF(G21="","",I$9&G21) | O21: =IF(H21="","",I$9&H21) | P21: =IF(C21="","",J$9&C21) | Q21: =IF(D21="","",J$9&D21) | R21: =IF(E21="","",J$9&E21) | S21: =IF(F21="","",J$9&F21) | T21: =IF(G21="","",J$9&G21) | U21: =IF(H21="","",J$9&H21) | V21: =IF(C21="","",K$9&C21) | W21: =IF(D21="","",K$9&D21) | X21: =IF(E21="","",K$9&E21) | Y21: =IF(F21="","",K$9&F21) | Z21: =IF(G21="","",K$9&G21) | AA21: =IF(H21="","",K$9&H21) | AB21: =IF(C21="","",L$9&C21) | AC21: =IF(D21="","",L$9&D21) | AD21: =IF(E21="","",L$9&E21) | AE21: =IF(F21="","",L$9&F21) | AF21: =IF(G21="","",L$9&G21) | AG21: =IF(H21="","",L$9&H21) | AH21: =IF(C21="","",M$9&C21) | AI21: =IF(D21="","",M$9&D21) | AJ21: =IF(E21="","",M$9&E21) | AK21: =IF(F21="","",M$9&F21) | AL21: =IF(G21="","",M$9&G21) | AM21: =IF(H21="","",M$9&H21)
A22: =LOC_COPY!I28 -> 08 | B22: =IF(A22="","",LOC_COPY!H28) -> 1 | C22: =IF($A22="","",B$9&$A22) -> 908 | D22: =IF($A22="","",C$9&$A22) -> 208 | E22: =IF($A22="","",D$9&$A22) -> 08 | F22: =IF($A22="","",E$9&$A22) -> 08 | G22: =IF($A22="","",F$9&$A22) -> 08 | H22: =IF($A22="","",G$9&$A22) -> 08 | I22: =TRIM(C22&" "&D22&" "&E22&" "&F22&" "&G22&" "&H22) -> 908 208 08 08 08 08 | J22: =IF(C22="","",I$9&C22) -> 2908 | K22: =IF(D22="","",I$9&D22) -> 2208 | L22: =IF(E22="","",I$9&E22) -> 208 | M22: =IF(F22="","",I$9&F22) -> 208 | N22: =IF(G22="","",I$9&G22) -> 208 | O22: =IF(H22="","",I$9&H22) -> 208 | P22: =IF(C22="","",J$9&C22) -> 908 | Q22: =IF(D22="","",J$9&D22) -> 208 | R22: =IF(E22="","",J$9&E22) -> 08 | S22: =IF(F22="","",J$9&F22) -> 08 | T22: =IF(G22="","",J$9&G22) -> 08 | U22: =IF(H22="","",J$9&H22) -> 08 | V22: =IF(C22="","",K$9&C22) -> 908 | W22: =IF(D22="","",K$9&D22) -> 208 | X22: =IF(E22="","",K$9&E22) -> 08 | Y22: =IF(F22="","",K$9&F22) -> 08 | Z22: =IF(G22="","",K$9&G22) -> 08 | AA22: =IF(H22="","",K$9&H22) -> 08 | AB22: =IF(C22="","",L$9&C22) -> 908 | AC22: =IF(D22="","",L$9&D22) -> 208 | AD22: =IF(E22="","",L$9&E22) -> 08 | AE22: =IF(F22="","",L$9&F22) -> 08 | AF22: =IF(G22="","",L$9&G22) -> 08 | AG22: =IF(H22="","",L$9&H22) -> 08 | AH22: =IF(C22="","",M$9&C22) -> 908 | AI22: =IF(D22="","",M$9&D22) -> 208 | AJ22: =IF(E22="","",M$9&E22) -> 08 | AK22: =IF(F22="","",M$9&F22) -> 08 | AL22: =IF(G22="","",M$9&G22) -> 08 | AM22: =IF(H22="","",M$9&H22) -> 08
A23: =LOC_COPY!I29 -> 09 | B23: =IF(A23="","",LOC_COPY!H29) -> 1 | C23: =IF($A23="","",B$9&$A23) -> 909 | D23: =IF($A23="","",C$9&$A23) -> 209 | E23: =IF($A23="","",D$9&$A23) -> 09 | F23: =IF($A23="","",E$9&$A23) -> 09 | G23: =IF($A23="","",F$9&$A23) -> 09 | H23: =IF($A23="","",G$9&$A23) -> 09 | I23: =TRIM(C23&" "&D23&" "&E23&" "&F23&" "&G23&" "&H23) -> 909 209 09 09 09 09 | J23: =IF(C23="","",I$9&C23) -> 2909 | K23: =IF(D23="","",I$9&D23) -> 2209 | L23: =IF(E23="","",I$9&E23) -> 209 | M23: =IF(F23="","",I$9&F23) -> 209 | N23: =IF(G23="","",I$9&G23) -> 209 | O23: =IF(H23="","",I$9&H23) -> 209 | P23: =IF(C23="","",J$9&C23) -> 909 | Q23: =IF(D23="","",J$9&D23) -> 209 | R23: =IF(E23="","",J$9&E23) -> 09 | S23: =IF(F23="","",J$9&F23) -> 09 | T23: =IF(G23="","",J$9&G23) -> 09 | U23: =IF(H23="","",J$9&H23) -> 09 | V23: =IF(C23="","",K$9&C23) -> 909 | W23: =IF(D23="","",K$9&D23) -> 209 | X23: =IF(E23="","",K$9&E23) -> 09 | Y23: =IF(F23="","",K$9&F23) -> 09 | Z23: =IF(G23="","",K$9&G23) -> 09 | AA23: =IF(H23="","",K$9&H23) -> 09 | AB23: =IF(C23="","",L$9&C23) -> 909 | AC23: =IF(D23="","",L$9&D23) -> 209 | AD23: =IF(E23="","",L$9&E23) -> 09 | AE23: =IF(F23="","",L$9&F23) -> 09 | AF23: =IF(G23="","",L$9&G23) -> 09 | AG23: =IF(H23="","",L$9&H23) -> 09 | AH23: =IF(C23="","",M$9&C23) -> 909 | AI23: =IF(D23="","",M$9&D23) -> 209 | AJ23: =IF(E23="","",M$9&E23) -> 09 | AK23: =IF(F23="","",M$9&F23) -> 09 | AL23: =IF(G23="","",M$9&G23) -> 09 | AM23: =IF(H23="","",M$9&H23) -> 09
